<robot
    xmlns:sensor="http://playerstage.sourceforge.net/gazebo/xmlschema/#sensor"
    xmlns:controller="http://playerstage.sourceforge.net/gazebo/xmlschema/#contr
oller"
    xmlns:interface="http://playerstage.sourceforge.net/gazebo/xmlschema/#interf
ace">
    <include filename="$(find prlite_urdf)/prlite_smartarm.xacro" />

    <!-- Properties (Constants) -->
    <property name="M_PI" value="3.14159"/>
    <property name="inch_to_meter" value="0.0254"/>
    <property name="torso_body_z" value="0.001778" />
    <property name="torso_lift_y" value="0.254" />
    <property name="torso_lift_z" value="0.1778" />
    <property name="torso_lift_joint_y" value="0.00635" />
    <property name="torso_y" value="0.2667" />
    <property name="torso_z" value="0.1178" />
    <property name="torso_sz_x" value="0.00635" />
    <property name="torso_sz_y" value="0.508" />
    <property name="torso_sz_z" value="0.3556" />
    <property name="front_shelf_x" value="0.0762" />
    <property name="front_shelf_y" value="0" />
    <property name="front_shelf_z" value="0" />
    <property name="front_shelf_sz_x" value="0.00635" />
    <property name="front_shelf_sz_y" value="0.508" />
    <property name="front_shelf_sz_z" value="0.1524" />
    <property name="shelf_width" value="0.00635" />


 <macro name="prlite_torso" params="">

<!-- * * * Link Definitions * * * -->
<joint name="torso_body_joint" type="fixed">
  <parent link="base_link"/>
  <child link="torso_lift_link"/>
 <origin xyz="${inch_to_meter*10} 0 ${inch_to_meter*6.5}" rpy="0 0 0"/>
</joint>
<link name="torso_lift_link">
  <visual>
    <axis xyz="0 0 0" />
    <origin xyz="${inch_to_meter*0} ${inch_to_meter*0} ${inch_to_meter*-1.5}" rpy="0 0 0"/>
    <geometry><box size="${inch_to_meter*1} ${inch_to_meter*1} ${inch_to_meter*17}"/></geometry>
    <material name="Silver1"><color rgba="0 0.9 0.9 1.0"/></material>
  </visual>
</link>
<joint name="torso_lift_joint" type="prismatic">
  <axis xyz="0 0 1" />
  <limit lower="0.0" upper="${inch_to_meter*12}" effort="10000" velocity=".05"/>
  <origin xyz="-0 0 0" rpy="0 0 0"/>
  <parent link="torso_lift_link"/>
  <child link="torso_link"/>
  <origin xyz="0 ${inch_to_meter*0.5} 0" rpy="0 0 0"/>
</joint>
<link name="torso_link">
  <visual>
    <axis xyz="0 0 0" />
    <origin xyz="${inch_to_meter*(.5)} ${inch_to_meter*0} ${inch_to_meter*0}" rpy="0 0 0"/>
    <geometry><box size="${inch_to_meter*.25} ${inch_to_meter*20} ${inch_to_meter*20}"/></geometry>
    <material name="Silver1"><color rgba="0 0.9 0.9 1.0"/></material>
  </visual>
</link>

<joint name="front_shelf_joint" type="fixed">
  <parent link="torso_lift_link"/>
  <child link="front_shelf_link"/>
  <origin xyz="0 ${shelf_width} 0" rpy="0 0 0"/>
</joint>
<link name="front_shelf_link">
  <visual>
    <origin xyz="${inch_to_meter*3} ${inch_to_meter*0} ${inch_to_meter*-10}" rpy="0 0 0"/>
    <geometry><box size="${inch_to_meter*6} ${inch_to_meter*20} ${inch_to_meter*.25}"/></geometry>
    <material name="Grey1"><color rgba="0 0.9 0.9 1.0"/></material>
  </visual>
</link>
<joint name="left_arm_shelf_joint" type="fixed">
  <parent link="torso_link"/>
  <child link="left_arm_shelf_link"/>
  <origin xyz="${inch_to_meter*0} ${inch_to_meter*7} ${inch_to_meter*-9.75}" rpy="0 0 0"/>
</joint>
<link name="left_arm_shelf_link">
  <visual>
    <origin xyz="${inch_to_meter*3} ${inch_to_meter*0} ${inch_to_meter*0}" rpy="0 0 0"/>
    <geometry><box size="${inch_to_meter*6} ${inch_to_meter*6} ${inch_to_meter*.25}"/></geometry>
    <material name="Silver1"><color rgba="0 0.9 0.9 1.0"/></material>
  </visual>
</link>
<joint name="left_arm_base_link" type="fixed">
  <axis xyz="0 0 1" />
  <parent link="left_arm_shelf_link"/>
  <child link="left_shoulder_pan_link"/>
  <origin xyz="${inch_to_meter*4} ${inch_to_meter*0} ${inch_to_meter*1}" rpy="0 0 0"/>
</joint>

<joint name="right_arm_shelf_joint" type="fixed">
  <parent link="torso_link"/>
  <child link="right_arm_shelf_link"/>
  <origin xyz="${inch_to_meter*0} ${inch_to_meter*-7} ${inch_to_meter*-9.75}" rpy="0 0 0"/>
</joint>

<link name="right_arm_shelf_link">
  <visual>
    <axis xyz="0 0 1" />
    <origin xyz="${inch_to_meter*3} ${inch_to_meter*0} ${inch_to_meter*0}" rpy="0 0 0"/>
    <geometry><box size="${inch_to_meter*6} ${inch_to_meter*6} ${inch_to_meter*.25}"/></geometry>
    <material name="Silver1"><color rgba="0 0.9 0.9 1.0"/></material>
  </visual>
</link>

<joint name="right_arm_base_link" type="fixed">
  <parent link="right_arm_shelf_link"/>
  <child link="right_shoulder_pan_link"/>
  <origin xyz="${inch_to_meter*4} ${inch_to_meter*0} ${inch_to_meter*1}" rpy="0 0 0"/>
</joint>

<!-- hokuyu at 15inches -->
<joint name="hokuyo_torso_joint" type="fixed">
  <parent link="torso_link"/>
  <child link="hokuyo_torso_link"/>
 <origin xyz="${inch_to_meter*2} 0 ${inch_to_meter*2}" rpy="0 0 0"/>
</joint>

<link name="hokuyo_torso_link">
    <origin xyz="${inch_to_meter*0} ${inch_to_meter*0} ${inch_to_meter*0}" rpy="0 0 0"/>
</link>

 </macro>

</robot>
