<?xml version="1.0" ?>
<!-- =================================================================================== -->
<!-- |    This document was autogenerated by xacro from /u/bholmberg/ros_e/gripper_control/urdf/pr2.urdf.xacro | -->
<!-- =================================================================================== -->
<robot name="low_cost_gripper" xmlns:body="http://playerstage.sourceforge.net/gazebo/xmlschema/#body"
                               xmlns:controller="http://playerstage.sourceforge.net/gazebo/xmlschema/#controller"
                               xmlns:geom="http://playerstage.sourceforge.net/gazebo/xmlschema/#geom"
                               xmlns:interface="http://playerstage.sourceforge.net/gazebo/xmlschema/#interface"
                               xmlns:joint="http://playerstage.sourceforge.net/gazebo/xmlschema/#joint"
                               xmlns:sensor="http://playerstage.sourceforge.net/gazebo/xmlschema/#sensor"
                               xmlns:xacro="http://ros.org/wiki/xacro">

  <link name="world" />

  <link name="r_gripper_palm_link">
    <visual>
      <geometry>
        <mesh filename="package://velo_description/meshes/lcg_actuator_palm_mesh_v1-55.STL"  />
      </geometry>
      <origin rpy="0 0 0" xyz="0.0 0.0 0.0"/>
      <material name="r_palm-11_color">
        <color rgba="0.796078 0.823529 0.937255 1"/>
      </material>
    </visual>
    <collision>
      <geometry>
        <mesh filename="package://velo_description/meshes/lcg_actuator_palm_mesh_v1-55.STL"  />
      </geometry>
      <origin rpy="0 0 0" xyz="0.0 0.0 0.0"/>
    </collision>
    <inertial>
      <mass value="0.1"/>
      <inertia ixx="0.001" ixy="0.0" ixz="0.0" iyy="0.01" iyz="0.0" izz="0.01"/>
      <origin rpy="0 0 0" xyz="0.0 0.0 0.0"/>
    </inertial>
  </link>
  <joint name="r_gripper_palm_joint" type="fixed">
    <parent link="world"/>
    <child link="r_gripper_palm_link"/>
    <origin rpy="0 0 0" xyz="0.135 0.0 0.0"/>
  </joint>
  <link name="r_gripper_l_finger_link">
    <visual>
      <geometry>
        <mesh filename="package://velo_description/meshes/lcg_proximal_mesh_v1-55.STL"  />
      </geometry>
      <origin rpy="0 0 0" xyz="0 0 0"/>
      <material name="r_l_finger-11_color">
        <color rgba="0.0 1.0 0.0 1"/>
      </material>
    </visual>
    <collision>
      <geometry>
        <mesh filename="package://velo_description/meshes/lcg_proximal_mesh_v1-55.STL"/>
      </geometry>
      <origin rpy="0 0 0" xyz="0 0 0"/>
    </collision>
    <inertial>
      <mass value="0.1"/>
      <inertia ixx="0.001" ixy="0.0" ixz="0.0" iyy="0.01" iyz="0.0" izz="0.01"/>
      <origin rpy="0 0 0" xyz="0 0.00 0.0"  />
    </inertial>
  </link>
  <joint name="r_gripper_l_finger_joint" type="revolute">
    <parent link="r_gripper_palm_link"/>
    <child link="r_gripper_l_finger_link"  />
    <origin rpy="0 0 -1.57079632679" xyz="0 -0.01750 0.0"/>
    <limit effort="300.0" lower="0" upper="1.42244334038" velocity="10000"/>
    <safety_controller k_position="100" k_velocity="1" soft_lower_limit="0" soft_upper_limit="1.4224433403753787"/>
    <axis xyz="0 0 1"/>
    <dynamics damping="0.01"/>
  </joint>
  <link name="r_gripper_l_finger_tip_link">
    <visual>
      <geometry>
        <mesh filename="package://velo_description/meshes/lcg_distal_mesh_v1-55.STL"  />
      </geometry>
      <origin rpy="0 0 0" xyz="0 0 0"/>
      <material name="r_l_finger_tip-11_color">
        <color rgba="0.796078 0.823529 0.937255 1"/>
      </material>
    </visual>
    <collision>
      <geometry>
        <mesh filename="package://velo_description/meshes/lcg_distal_mesh_v1-55.STL"  />
      </geometry>
      <origin rpy="0 0 0" xyz="0 0 0"/>
    </collision>
    <inertial>
      <mass value="0.1"/>
      <inertia ixx="0.001" ixy="0" ixz="0" iyy="0.001" iyz="0" izz="0.001"/>
      <origin rpy="0 0 0" xyz="0 0.00 0.0"/>
    </inertial>
  </link>
  <joint name="r_gripper_l_finger_tip_joint" type="revolute">
    <parent link="r_gripper_l_finger_link"/>
    <child link="r_gripper_l_finger_tip_link"/>
    <mimic joint="r_gripper_l_finger_joint" multiplier="-1" offset="0"/>
    <origin rpy="0 0 1.57079632679" xyz="0.060 0 0"/>
    <limit effort="300.0" lower="-1.42244334038" upper="1.42244334038" velocity="10000"/>
    <safety_controller k_position="100" k_velocity="1" soft_lower_limit="0" soft_upper_limit="1.4224433403753787"/>
    <axis xyz="0 0 1"/>
    <dynamics damping="0.01"/>
  </joint>
  <link name="r_gripper_r_finger_link">
    <visual>
      <geometry>
        <mesh filename="package://velo_description/meshes/lcg_proximal_mesh_v1-55.STL"/>
      </geometry>
      <origin rpy="0 0 0" xyz="0 0 0"/>
      <material name="r_gripper_r_finger-11_color"  >
        <color rgba="1.0 0.0 0.0 1"/>
      </material>
    </visual>
    <collision>
      <geometry>
        <mesh filename="package://velo_description/meshes/lcg_proximal_mesh_v1-55.STL"  />
      </geometry>
      <origin rpy="0 0 0" xyz="0 0 0"/>
    </collision>
    <inertial>
      <mass value="0.1"/>
      <inertia ixx="0.001" ixy="0" ixz="0" iyy="0.001" iyz="0" izz="0.001"/>
      <origin rpy="0 0 0" xyz="0 0.00 0.0"/>
    </inertial>
  </link>
  <joint name="r_gripper_r_finger_joint" type="revolute">
    <parent link="r_gripper_palm_link"/>
    <child link="r_gripper_r_finger_link"/>
    <mimic joint="r_gripper_l_finger_joint" multiplier="1" offset="0"/>
    <origin rpy="0 3.14159265359 -1.57079632679" xyz="0 0.0175 0"/>
    <limit effort="300.0" lower="-1.42244334038" upper="1.42244334038" velocity="10000"/>
    <safety_controller k_position="100" k_velocity="1" soft_lower_limit="0" soft_upper_limit="1.4224433403753787"/>
    <axis xyz="0 0 1"/>
    <dynamics damping="0.01"/>
  </joint>
  <link name="r_gripper_r_finger_tip_link">
    <visual>
      <geometry>
        <mesh filename="package://velo_description/meshes/lcg_distal_mesh_v1-55.STL"/>
      </geometry>
      <origin rpy="0 0 0" xyz="0 0 0"/>
      <material name="r_r_finger_tip-11_color"  >
        <color rgba="0.796078 0.823529 0.937255 1"/>
      </material>
    </visual>
    <collision>
      <geometry>
        <mesh filename="package://velo_description/meshes/lcg_distal_mesh_v1-55.STL"  />
      </geometry>
      <origin rpy="0 0 0" xyz="0 0 0"/>
    </collision>
    <inertial>
      <mass value="0.1"/>
      <inertia ixx="0.001" ixy="0" ixz="0" iyy="0.001" iyz="0" izz="0.001"/>
      <origin rpy="0 0 0" xyz="0 0.00 0.0"/>
    </inertial>
  </link>
  <joint name="r_gripper_r_finger_tip_joint" type="revolute">
    <parent link="r_gripper_r_finger_link"/>
    <child link="r_gripper_r_finger_tip_link"/>
    <mimic joint="r_gripper_l_finger_joint" multiplier="-1" offset="0"/>
    <origin rpy="0 0 1.57079632679" xyz="0.060 0 0"/>
    <limit effort="300.0" lower="-1.42244334038" upper="1.42244334038" velocity="10000"/>
    <safety_controller k_position="100" k_velocity="1" soft_lower_limit="0" soft_upper_limit="1.4224433403753787"/>
    <axis xyz="0 0 1"/>
    <dynamics damping="0.01"/>
  </joint>
  <link name="r_gripper_l_finger_tip_frame"/>
  <link name="r_gripper_tool_frame">
    <!--<visual>
        <geometry>
          <sphere radius="0.003"/>
        </geometry>
        <origin rpy="0 0 0" xyz="0 0 0"/>
        <material name="${side}_tool_frame-11_color"  >
          <color rgba="0.796078 0.823529 0.937255 1"/>
        </material>
      </visual>-->
    <inertial>
      <mass value="0.1"/>
      <inertia ixx="0.001" ixy="0" ixz="0" iyy="0.001" iyz="0" izz="0.001"/>
      <origin rpy="0 0 0" xyz="0 0.00 0.0"/>
    </inertial>
  </link>
  <joint name="r_gripper_tool_joint" type="fixed">
    <parent link="r_gripper_palm_link"  />
    <child link="r_gripper_tool_frame"/>
    <origin rpy="0 0 0" xyz="0.0 0.0 0.1"/>
  </joint>
  <link name="r_gripper_motor_slider_link">
    <inertial>
      <mass value="0.01"/>
      <origin rpy="0 0 0" xyz="0 0 0"/>
      <inertia ixx="0.001" ixy="0.0" ixz="0.0" iyy="0.001" iyz="0.0" izz="0.001"/>
    </inertial>
    <!-- for debugging only -->
    <!--<visual>
        <origin xyz="0 0 0" rpy="0 0 0" />
        <geometry>
          <box size="0.05 0.01 0.05" />
        </geometry>
      </visual>
      <collision>
        <origin xyz="0 0 0" rpy="0 0 0" />
        <geometry>
          <box size="0.05 0.01 0.05" />
        </geometry>
      </collision>-->
  </link>

  <joint name="r_gripper_motor_slider_joint" type="prismatic"  >
    <origin rpy="0 0 1.57079632679" xyz="0 0 0.1117955"/>
    <axis xyz="1 0 0"/>
    <parent link="r_gripper_palm_link"/>
    <child link="r_gripper_motor_slider_link"  />
    <limit effort="1000.0" lower="-0.135" upper="0.135" velocity="0.2"  />
  </joint>
  <link name="r_gripper_motor_screw_link">
    <inertial>
      <mass value="0.01"/>
      <origin rpy="0 0 0" xyz="0 0 0"/>
      <inertia ixx="0.0001" ixy="0.0" ixz="0.0" iyy="0.0001" iyz="0.0" izz="0.0001"/>
    </inertial>
    <!-- for debugging only -->
    <!--      <visual>
        <origin xyz="0 0 0" rpy="0 0 0" />
        <geometry>
          <box size="0.05 0.01 0.05" />
        </geometry>
      </visual>
      <collision>
        <origin xyz="0 0 0" rpy="0 0 0" />
        <geometry>
          <box size="0.05 0.01 0.05" />
        </geometry>
      </collision> -->
  </link>

  <joint name="r_gripper_motor_screw_joint" type="continuous"  >
    <origin rpy="0 0 0" xyz="0.0 0 0"/>
    <axis xyz="0 1 0"/>
    <parent link="r_gripper_motor_slider_link"/>
    <child link="r_gripper_motor_screw_link"  />
    <dynamics damping="0.0001"/>
  </joint>
  <joint name="r_gripper_joint" type="prismatic">
    <parent link="r_gripper_r_finger_tip_link"/>
    <child link="r_gripper_l_finger_tip_frame"/>
    <axis xyz="0 1 0"/>
    <dynamics damping="10.0"/>
    <limit effort="333.3" lower="-99999.9" upper="99999.9" velocity="9.9"/>
  </joint>

  <transmission name="r_gripper_trans" type="velo_controller/VeloTransmission"  >
    <!-- CHANGE ACTUATOR NAME ON NEXT LINE -->
    <actuator name="r_velo_gripper_motor"/>
    <gap_joint name="r_gripper_joint"
               gear_efficiency="1.0"
               gear_reduction="15.0"
               j0x="-0.035"
               j0y="0.0"
               j1_radius="0.0032"
               j1x="-0.06"
               j1y="0.0"
               l0="0.035"
               l1="0.06"
               l2="0.05"
               p0_radius="0.004"
               p0x="-0.025"
               p0y="0.002"
               p1x="-0.045"
               p1y="0.004"
               p2x="-0.0084"
               p2y="0.0023"
               p3x="-0.044"
               p3y="-0.005"
               screw_efficiency="1.0"
               screw_lead="0.00325"
               theta_closed="101.5"
               theta_open="20.0"
               thickness="0.0069"
               l2g_coeffs_0="-0.00065535931852"
               l2g_coeffs_1="10.019957576"
               l2g_coeffs_2="799.03010689"
               l2g_coeffs_3="-70983.900184"
               l2g_coeffs_4="1729405.0628"
               g2l_coeffs_0=".00005429877018"
               g2l_coeffs_1="0.097594704184"
               g2l_coeffs_2="-0.46537557155"
               g2l_coeffs_3="3.3776098694"
               g2l_coeffs_4="-6.6643179571"
               g2ed_coeffs_0="0.013021055202"
               g2ed_coeffs_1="-0.020767789082"
               g2ed_coeffs_2="-0.41359925158"
               g2ed_coeffs_3="4.8190129478"
               g2ed_coeffs_4="-26.74286852"
               />
    <!-- if a gazebo joint exists as [l|r]_gripper_joint, use this tag to have
           gripper transmission apply torque directly to prismatic joint
           this should be the default behavior in diamondback, deprecating this flag -->
    <use_simulated_gripper_joint/>
    <!-- set passive joint angles so things look nice in rviz -->
    <passive_joint name="r_gripper_l_finger_joint"  />
    <passive_joint name="r_gripper_r_finger_joint"/>
    <passive_joint name="r_gripper_r_finger_tip_joint"/>
    <passive_joint name="r_gripper_l_finger_tip_joint"  />
    <!-- screw joint to capture gripper "dynamics" -->
    <simulated_actuated_joint name="r_gripper_motor_screw_joint" passive_actuated_joint="r_gripper_motor_slider_joint" simulated_reduction="20.0"/>
  </transmission>

</robot>
