<?xml version="1.0"?>

<robot
    xmlns:sensor="http://playerstage.sourceforge.net/gazebo/xmlschema/#sensor"
    xmlns:controller="http://playerstage.sourceforge.net/gazebo/xmlschema/#controller"
    xmlns:interface="http://playerstage.sourceforge.net/gazebo/xmlschema/#interface">
    
    <!--macro name="smart_arm" params="parent *origin side"-->
    <macro name="smart_arm" params="parent side">
        <!-- ****** JOINT DEFINITIONS ****** -->
        
        <!-- Arm's base joint -->
        <!-- joint name="${side}_arm_base_joint" type="fixed">
            <-insert_block name="origin" /> 
            <parent link="${parent}"/>
            <child link="${side}_arm_base_link"/>
        </joint -->

        <joint name="${side}_shoulder_pan_joint" type="revolute" >
            <origin xyz="${inch_to_meter*0} 0 ${inch_to_meter*0}" rpy="0 0 0" />
            <!-- parent link="${side}_arm_base_link" /-->
            <parent link="${parent}" />
            <child link="${side}_shoulder_link"/>
            
            <axis xyz="0 0 1"/>
            <limit  lower="-1.22" upper="1.22" effort="300" velocity="1.17" />
            <safety_controller k_position="100" k_velocity="15.0" soft_lower_limit="${-1.22+0.1}" soft_upper_limit="${1.22-0.1}" />
            <dynamics damping="50" friction="1"/>
        </joint>

        <joint name="${side}_shoulder_caster_joint" type="fixed">
          <axis xyz="0 0 0" />
          <parent link="${side}_shoulder_link"/>
          <child link="${side}_shoulder_caster_link"/>
          <origin xyz="${inch_to_meter*-2} ${inch_to_meter*0} ${inch_to_meter*7.3575}" rpy="0 0 0"/>
        </joint>

        <joint name="${side}_lin_act_cyl_joint" type="revolute">
          <!-- shoulder pan cylindar to lin act joint -->
          <origin xyz="${inch_to_meter*(1.5)} ${inch_to_meter*0} ${inch_to_meter*7.3575}" rpy="0 0 0"/>
<!--
          <origin xyz="${inch_to_meter*(.5)} ${inch_to_meter*0} ${inch_to_meter*7.3575}" rpy="0 0 0"/>
-->
          <parent link="${side}_shoulder_caster_link"/>
          <child link="${side}_lower_linear_actuator_link"/>
          <axis xyz="0 -1 0"/>
          <limit  lower="-1.04719755" upper="1.972222" effort="300" velocity="1.17" />
          <!-- mimic joint="${side}_shoulder_tilt_joint" multiplier="-1" offset="0" -->
      </joint>


       <joint name="${side}_linear_actuator_joint" type="prismatic">
          <!-- linact down: 9.9 inches, up 13.9 inches -->
          <axis xyz="0 0 1" />
          <limit lower="${inch_to_meter*0}" upper="${inch_to_meter*-4}" effort="10000" velocity=".025"/>
          <origin xyz="0.0 0.0 0.0" rpy="0 0 0"/>
          <parent link="${side}_lower_linear_actuator_link"/>
          <child link="${side}_upper_linear_actuator_link"/>
        </joint>
        
        <joint name="${side}_shoulder_tilt_joint" type="revolute">
            <origin xyz="${inch_to_meter*2} 0 ${0}" rpy="0 0 0" />
            <parent link="${side}_shoulder_link"/>
            <child link="${side}_upper_arm_link" />
            
            <axis xyz="0 -1 0"/>
<!--
            <limit  lower="-1.04" upper="1.95" effort="300" velocity="1.17" />
-->
            <limit  lower=".15" upper="1" effort="300" velocity="1.17" />
            <safety_controller k_position="100" k_velocity="15.0" soft_lower_limit="${-1.04719755+0.1}" soft_upper_limit="${1.972222-0.1}" />
            <dynamics damping="50" friction="1"/>
        </joint>
 

<joint name="${side}_upper_arm_hinge_joint" type="revolute"> 
    <origin xyz="${inch_to_meter*14} ${inch_to_meter*0} ${inch_to_meter*.25}" rpy="0.0 0 0.0"/>
    <parent link="${side}_upper_arm_link"/>
    <child link="${side}_upper_arm_hinge_link"/>    
    <axis xyz="0 -1 0"/>
    <limit  lower="-1" upper="-.15" effort="300" velocity="1.17" />
    <mimic joint="${side}_shoulder_tilt_joint" multiplier="-1" offset="0"/> 
</joint>

        <joint name="${side}_elbow_pan_joint" type="fixed" >
            <origin xyz="${inch_to_meter*0} 0 ${inch_to_meter*1}" rpy="0 0 0" />
            <parent link="${side}_upper_arm_hinge_link" />
            <child link="${side}_elbow_pan_link"/>

            <axis xyz="0 0 1"/>
            <limit  lower="-1.22" upper="1.22" effort="300" velocity="1.17" />
            <safety_controller k_position="100" k_velocity="15.0" soft_lower_limit="${-1.22+0.1}" soft_upper_limit="${1.22-0.1}" />
            <dynamics damping="50" friction="1"/>
        </joint>

        <joint name="${side}_elbow_joint" type="revolute" >
            <origin xyz="-0.0075 0 -0.025" rpy="0 0 0" />
            <!-- parent link="${side}_arm_base_link" /-->
            <parent link="${side}_elbow_pan_link" />
            <child link="${side}_elbow_flex_link"/>
            
            <axis xyz="0 0 1"/>
            <limit  lower="-1.22" upper="1.22" effort="300" velocity="1.17" />
            <safety_controller k_position="100" k_velocity="15.0" soft_lower_limit="${-1.22+0.1}" soft_upper_limit="${1.22-0.1}" />
            <dynamics damping="50" friction="1"/>
        </joint>
        
        <joint name="${side}_elbow_flex_joint" type="revolute">
            <origin xyz="${0.105 - 0.01 - 0.03085/2} 0 ${0.01 + 0.05 - 0.031/2}" rpy="0 0 0" />
            <parent link="${side}_elbow_flex_link"/>
            <child link="${side}_forearm_link" />
            
            <axis xyz="0 -1 0"/>
            <limit  lower="-1.04719755" upper="1.972222" effort="300" velocity="1.17" />
            <safety_controller k_position="100" k_velocity="15.0" soft_lower_limit="${-1.04719755+0.1}" soft_upper_limit="${1.972222-0.1}" />
            <dynamics damping="50" friction="1"/>
        </joint>
        
        <joint name="${side}_wrist_flex_joint" type="revolute">
            <origin xyz="${0.04 - 0.01 + 0.0015 + 0.105 + 0.055 - 0.01} 0 0" rpy="0 0 0" />
            <parent link="${side}_forearm_link"/>
            <child link="${side}_wrist_flex_link" />
            
            <axis xyz="0 -1 0"/>
            <!-- From -113 to 108 degrees -->
            <limit  lower="-1.972222" upper="1.8849556" effort="300" velocity="1.17" />
            <dynamics damping="50" friction="1"/>
            <safety_controller k_position="100" k_velocity="15.0" soft_lower_limit="${-1.972222+0.1}" soft_upper_limit="${1.8849556-0.1}" />
        </joint>
        
        <joint name="${side}_wrist_roll_joint" type="revolute">
            <origin xyz="${0.08 - 0.01} 0 ${0.05 - 0.0115 - 0.0155}" rpy="0 0 0" />
            <parent link="${side}_wrist_flex_link"/>
            <child link="${side}_wrist_roll_link" />
            
            <axis xyz="-1 0 0"/>
            <!-- From -150 to 150 degrees -->
            <limit  lower="-2.6179939" upper="2.6179939" effort="300" velocity="1.17" />
            <dynamics damping="50" friction="1"/>
            <safety_controller k_position="100" k_velocity="15.0" soft_lower_limit="${-2.6179939+0.1}" soft_upper_limit="${2.6179939-0.1}" />
        </joint>
        
        <joint name="${side}_gripper_right_joint" type="revolute">
            <origin xyz="${0.0015 + 0.05 - 0.01} ${-0.035/2} 0" rpy="0 0 0" />
            <parent link="${side}_wrist_roll_link"/>
            <child link="${side}_gripper_right_link" />
            
            <axis xyz="0 0 1"/>
            <!-- From 14 to -45 degrees -->
            <limit  lower="-0.838576116" upper="0.245436912" effort="300" velocity="1.17" />
            <dynamics damping="50" friction="1"/>
            <safety_controller k_position="100" k_velocity="15.0" soft_lower_limit="${-0.838576116+0.1}" soft_upper_limit="${0.245436912-0.1}" />
        </joint>
        
        <!-- Gripper left joint -->
        <joint name="${side}_gripper_left_joint" type="revolute">
            <origin xyz="${0.0015 + 0.05 - 0.01} ${0.035/2} 0" rpy="0 0 0" />
            <parent link="${side}_wrist_roll_link"/>
            <child link="${side}_gripper_left_link" />
            
            <axis xyz="0 0 1"/>
            <!-- From -14 to 45 degrees -->
            <limit  lower="-0.240323643" upper="0.843689385" effort="300" velocity="1.17" />
            <dynamics damping="50" friction="1"/>
            <safety_controller k_position="100" k_velocity="15.0" soft_lower_limit="${-0.240323643+0.1}" soft_upper_limit="${0.843689385-0.1}" />
        </joint>
        
        <!-- ****** LINK DEFINITIONS ****** -->
<link name="${side}_shoulder_pan_link">
   <inertial>
        <mass value="0.405" />
        <origin xyz="0.02988871 0 0.02056699" rpy="0 0 0" />
        <inertia ixx="1.0" ixy="0.0" ixz="0.0"
                 iyy="1.0" iyz="0.0"
                 izz="1.0" />
    </inertial>
  <visual>
    <origin xyz="${inch_to_meter*0} ${inch_to_meter*0} ${inch_to_meter*0}" rpy="0 0 0"/>
    <geometry><box size="${inch_to_meter*4} ${inch_to_meter*4} ${inch_to_meter*.25}"/></geometry>
    <material name="Silver1"><color rgba="0 0.9 0.9 1.0"/></material>
  </visual>
</link>

        
<link name="${side}_shoulder_link">
   <inertial>
	<mass value="0.405" />
	<origin xyz="0.02988871 0 0.02056699" rpy="0 0 0" />
	<inertia ixx="1.0" ixy="0.0" ixz="0.0"
		 iyy="1.0" iyz="0.0"
		 izz="1.0" />
    </inertial>
  <visual>
    <origin xyz="${inch_to_meter*0} ${inch_to_meter*0} ${inch_to_meter*0}" rpy="0 0 0"/>
    <geometry><box size="${inch_to_meter*4} ${inch_to_meter*4} ${inch_to_meter*.25}"/></geometry>
    <material name="Silver1"><color rgba="0 0.9 0.9 1.0"/></material>
  </visual>
</link>

<link name="${side}_shoulder_caster_link">
  <!-- 14.715 inches from linact to caster -->
  <visual>
    <origin xyz="0 0 0" rpy="0 0 0"/>
    <geometry><box size="${inch_to_meter*0.25} ${inch_to_meter * 4} ${inch_to_meter*-14.715}"/></geometry>
    <material name="Green"><color rgba="0 0.9 0.9 1.0"/></material>
  </visual>
</link>

<link name="${side}_lower_linear_actuator_link">
  <visual>
    <axis xyz="0 0 0" />
    <origin xyz="${inch_to_meter*(0)} ${inch_to_meter*0} ${inch_to_meter*-4.95}" rpy="0 0 0"/>
    <geometry><box size="${inch_to_meter*1.4} ${inch_to_meter*1.2} ${inch_to_meter*-9.9}"/></geometry>
    <material name="Silver1"><color rgba="0 0.9 0.9 1.0"/></material>
  </visual>
</link>

<link name="${side}_upper_linear_actuator_link" >
  <!-- (4.3 - .315) inches where lin act attaches to arm -->
  <visual>
    <!-- origin xyz="${inch_to_meter*0} ${inch_to_meter*0} ${inch_to_meter*0}" rpy="0 0 0"-->
    <!-- geometry><box size="${inch_to_meter*0} ${inch_to_meter*0} ${inch_to_meter*0}"/></geometry -->
    <origin xyz="${inch_to_meter*(0)} ${inch_to_meter*0} ${inch_to_meter*-5.95}" rpy="0 0 0"/>
    <geometry><box size="${inch_to_meter*.8} ${inch_to_meter*.8} ${inch_to_meter*-9.9}"/></geometry>
    <material name="Green"><color rgba="0 0.9 0.9 1.0"/></material>
  </visual>
</link>

<link name="${side}_upper_arm_link" >
  <visual>
    <origin xyz="${inch_to_meter*7} ${inch_to_meter*0} ${inch_to_meter*0}" rpy="0 0 0"/>
    <geometry><box size="${inch_to_meter*14} ${inch_to_meter*4} ${inch_to_meter*.25}"/></geometry>
    <material name="Silver1"><color rgba="0 0.9 0.9 1.0"/></material>
  </visual>
</link>

<link name="${side}_upper_arm_hinge_link" >
  <visual>
    <origin xyz="${inch_to_meter*0} ${inch_to_meter*0} ${inch_to_meter*0}" rpy="0 0 0"/>
    <geometry><box size="${inch_to_meter*0} ${inch_to_meter*0} ${inch_to_meter*0}"/></geometry>
    <material name="Silver1"><color rgba="0 0.9 0.9 1.0"/></material>
  </visual>
</link>

        <link name="${side}_elbow_pan_link">
            <inertial>
                <mass value="0.125" />
                <origin xyz="0 0 0.00893364" rpy="0 0 0" />
                <inertia ixx="1.0" ixy="0.0" ixz="0.0"
                         iyy="1.0" iyz="0.0" 
                         izz="1.0" />
            </inertial>
            
            <visual>
                <origin xyz="0.0 0.0 0.0" rpy="0 0 0" />
                <geometry>
                    <mesh filename="package://pr2lite_urdf/config/meshes/arm_base.stl"/>
                </geometry>
            </visual>
            
<!--
            <collision>
                <origin xyz="0.0 0.0 0.0" rpy="0 0 0" />
                <geometry>
                    <mesh filename="package://pr2lite_urdf/config/meshes/arm_base_convex.stlb"/>
                </geometry>
            </collision>
-->
        </link>
        
        <link name="${side}_elbow_flex_link">
            <inertial>
                <mass value="0.405" />
                <origin xyz="0.02988871 0 0.02056699" rpy="0 0 0" />
                <inertia ixx="1.0" ixy="0.0" ixz="0.0"
                         iyy="1.0" iyz="0.0" 
                         izz="1.0" />
            </inertial>
            
            <visual>
                <origin xyz="0.0 0.0 0.005" rpy="0 0 0" />
                <geometry>
                    <mesh filename="package://pr2lite_urdf/config/meshes/arm_shoulder_pan.stl"/>
                </geometry>
            </visual>
            
<!--
            <collision>
                <origin xyz="0.0 0.0 0.0" rpy="0 0 0" />
                <geometry>
                    <mesh filename="package://pr2lite_urdf/config/meshes/arm_shoulder_pan_convex.stlb"/>
                </geometry>
            </collision>
-->
        </link>
        
        <link name="${side}_forearm_link">
            <inertial>
                <mass value="0.18" />
                <origin xyz="0.13999458 0 0.00064711" rpy="0 0 0" />
                <inertia ixx="1.0" ixy="0.0" ixz="0.0"
                         iyy="1.0" iyz="0.0" 
                         izz="1.0" />
            </inertial>
            
            <visual>
                <origin xyz="0.0 0.0 0.0" rpy="0 0 0" />
                <geometry>
                    <mesh filename="package://pr2lite_urdf/config/meshes/arm_shoulder_tilt.stl"/>
                </geometry>
            </visual>
            
<!--
            <collision>
                <origin xyz="0.0 0.0 0.0" rpy="0 0 0" />
                <geometry>
                    <mesh filename="package://pr2lite_urdf/config/meshes/arm_shoulder_tilt_convex.stlb"/>
                </geometry>
            </collision>
-->
        </link>
        
        <link name="${side}_wrist_flex_link">
            <inertial>
                <mass value="0.12" />
                <origin xyz="0.04463361 0 0.00720194" rpy="0 0 0" />
                <inertia ixx="1.0" ixy="0.0" ixz="0.0"
                         iyy="1.0" iyz="0.0" 
                         izz="1.0" />
            </inertial>
            
            <visual>
                <origin xyz="0.0 0.0 0.0" rpy="0 0 0" />
                <geometry>
                    <mesh filename="package://pr2lite_urdf/config/meshes/arm_elbow_tilt.stl"/>
                </geometry>
            </visual>
            
<!--
            <collision>
                <origin xyz="0.0 0.0 0.0" rpy="0 0 0" />
                <geometry>
                    <mesh filename="package://pr2lite_urdf/config/meshes/arm_elbow_tilt_convex.stlb"/>
                </geometry>
            </collision>
-->
        </link>
        
        <link name="${side}_wrist_roll_link">
            <inertial>
                <mass value="0.13" />
                <origin xyz="0.02539960 0 0" rpy="0 0 0" />
                <inertia ixx="1.0" ixy="0.0" ixz="0.0"
                         iyy="1.0" iyz="0.0" 
                         izz="1.0" />
            </inertial>
            
            <visual>
                <origin xyz="0.0 0.0 0.0" rpy="0 0 0" />
                <geometry>
                    <mesh filename="package://pr2lite_urdf/config/meshes/arm_wrist_rotate.stl"/>
                </geometry>
            </visual>
            
<!--
            <collision>
                <origin xyz="0.0 0.0 0.0" rpy="0 0 0" />
                <geometry>
                    <mesh filename="package://pr2lite_urdf/config/meshes/arm_wrist_rotate_convex.stlb"/>
                </geometry>
            </collision>
-->
        </link>
        
        <link name="${side}_gripper_right_link">
            <inertial>
                <mass value="0.0225" />
                <origin xyz="0.03058625 -0.01804371 -0.00941599" rpy="0 0 0" />
                <inertia ixx="1.0" ixy="0.0" ixz="0.0"
                         iyy="1.0" iyz="0.0" 
                         izz="1.0" />
            </inertial>
            
            <visual>
                <origin xyz="0.0 0.0 0.0" rpy="0 0 0" />
                <geometry>
                    <mesh filename="package://pr2lite_urdf/config/meshes/arm_right_finger.stl"/>
                </geometry>
            </visual>
            
<!--
            <collision>
                <origin xyz="0.0 0.0 0.0" rpy="0 0 0" />
                <geometry>
                    <mesh filename="package://pr2lite_urdf/config/meshes/arm_right_finger_convex.stlb"/>
                </geometry>
            </collision>
-->
        </link>
        
        <link name="${side}_gripper_left_link">
            <inertial>
                <mass value="0.0225" />
                <origin xyz="0.03058625 0.01804371 -0.00941599" rpy="0 0 0" />
                <inertia ixx="1.0" ixy="0.0" ixz="0.0"
                         iyy="1.0" iyz="0.0" 
                         izz="1.0" />
            </inertial>
            
            <visual>
                <origin xyz="0.0 0.0 0.0" rpy="0 0 0" />
                <geometry>
                    <mesh filename="package://pr2lite_urdf/config/meshes/arm_left_finger.stl"/>
                </geometry>
            </visual>
            
<!--
            <collision>
                <origin xyz="0.0 0.0 0.0" rpy="0 0 0" />
                <geometry>
                    <mesh filename="package://pr2lite_urdf/config/meshes/arm_left_finger_convex.stlb"/>
                </geometry>
            </collision>
-->
        </link>
        
        <!-- ****** TRANSMISSION DEFINITIONS ****** -->
        
        <transmission type="pr2_mechanism_model/SimpleTransmission" name="${side}_shoulder_pan_trans">
            <actuator name="${side}_shoulder_pan_motor" />
            <joint name="${side}_shoulder_pan_joint" />
            <mechanicalReduction>1.0</mechanicalReduction>
        </transmission>
        
        <transmission type="pr2_mechanism_model/SimpleTransmission" name="${side}_elbow_flex_trans">
            <actuator name="${side}_elbow_flex_motor" />
            <joint name="${side}_elbow_flex_joint" />
            <mechanicalReduction>1.0</mechanicalReduction>
        </transmission>
        
        <transmission type="pr2_mechanism_model/SimpleTransmission" name="${side}_wrist_flex_trans">
            <actuator name="${side}_wrist_flex_motor" />
            <joint name="${side}_wrist_flex_joint" />
            <mechanicalReduction>1.0</mechanicalReduction>
        </transmission>
        
        <transmission type="pr2_mechanism_model/SimpleTransmission" name="${side}_wrist_roll_trans">
            <actuator name="${side}_wrist_roll_motor" />
            <joint name="${side}_wrist_roll_joint" />
            <mechanicalReduction>1.0</mechanicalReduction>
        </transmission>
        
        <transmission type="pr2_mechanism_model/SimpleTransmission" name="${side}_gripper_right_trans">
            <actuator name="${side}_gripper_right_motor" />
            <joint name="${side}_gripper_right_joint" />
            <mechanicalReduction>1.0</mechanicalReduction>
        </transmission>
        
        <transmission type="pr2_mechanism_model/SimpleTransmission" name="${side}_gripper_left_trans">
            <actuator name="${side}_gripper_left_motor" />
            <joint name="${side}_gripper_left_joint" />
            <mechanicalReduction>1.0</mechanicalReduction>
        </transmission>
        
        <!-- ****** MATERIAL DEFINITIONS ****** -->
        
        <gazebo reference="${side}_arm_base_link">
            <material>SmartArm/GunMetalBrushedAluminum</material>
            <turnGravityOff>true</turnGravityOff>
        </gazebo>
        
        <gazebo reference="${side}_arm_shoulder_pan_link">
            <material>SmartArm/GunMetalBrushedAluminum</material>
            <turnGravityOff>true</turnGravityOff>
        </gazebo>
        
        <gazebo reference="${side}_elbow_flex_link">
            <material>SmartArm/GunMetalBrushedAluminum</material>
            <turnGravityOff>true</turnGravityOff>
        </gazebo>
        
        <gazebo reference="${side}_wrist_flex_link">
            <material>SmartArm/GunMetalBrushedAluminum</material>
            <turnGravityOff>true</turnGravityOff>
        </gazebo>
        
        <gazebo reference="${side}_wrist_roll_link">
            <material>SmartArm/GunMetalBrushedAluminum</material>
            <turnGravityOff>true</turnGravityOff>
        </gazebo>
        
        <gazebo reference="${side}_gripper_right_link">
            <material>SmartArm/GunMetalBrushedAluminum</material>
            <turnGravityOff>true</turnGravityOff>
            <mu1 value="500.0" />
            <mu2 value="500.0" />
            <kp value="1000000.0" />
            <kd value="1.0" />
        </gazebo>
        
        <gazebo reference="${side}_gripper_left_link">
            <material>SmartArm/GunMetalBrushedAluminum</material>
            <turnGravityOff>true</turnGravityOff>
            <mu1 value="500.0" />
            <mu2 value="500.0" />
            <kp value="1000000.0" />
            <kd value="1.0" />
        </gazebo>
        
        <gazebo reference="${side}_shoulder_pan_joint">
            <stopKd value="1.0" />
            <stopKp value="1000000.0" />
            <fudgeFactor value="0.5" />
        </gazebo>
        
        <gazebo reference="${side}_elbow_flex_joint">
            <stopKd value="1.0" />
            <stopKp value="1000000.0" />
            <fudgeFactor value="0.5" />
        </gazebo>
        
        <gazebo reference="${side}_wrist_flex_joint">
            <stopKd value="1.0" />
            <stopKp value="1000000.0" />
            <fudgeFactor value="0.5" />
        </gazebo>
        
        <gazebo reference="${side}_wrist_roll_joint">
            <stopKd value="1.0" />
            <stopKp value="1000000.0" />
            <fudgeFactor value="0.5" />
        </gazebo>
        
        <gazebo reference="${side}_gripper_right_joint">
            <stopKd value="1.0" />
            <stopKp value="1000000.0" />
            <fudgeFactor value="1.0" />
        </gazebo>
        
        <gazebo reference="${side}_gripper_left_joint">
            <stopKd value="1.0" />
            <stopKp value="1000000.0" />
            <fudgeFactor value="1.0" />
        </gazebo>

<!--
    <transmission type="pr2_mechanism_model/Pr2LiteShoulderTransmission" name="${side}_pr2lite_shoulder_trans" >
      <actuator       name="${side}_linear_actuator_joint" />
      <gap_joint      name="${side}_shoulder_tilt_joint"
                      />
-->
      <!-- if a gazebo joint exists as [l|r]_gripper_joint, use this tag to have
           gripper transmission apply torque directly to prismatic joint
           this should be the default behavior in diamondback, deprecating this flag -->
<!--
      <use_simulated_gripper_joint/>
-->
      <!-- set passive joint angles so things look nice in rviz -->
<!--
      <passive_joint  name="${side}_shoulder_tilt_joint"     />
      <passive_joint  name="${side}_lin_act_cyl_joint"     />
      <passive_joint  name="${side}_upper_arm_hinge_joint" />
-->
      <!-- screw joint to capture gripper "dynamics" -->
<!--
      <simulated_actuated_joint name="${side}_linear_actuator_joint"
                                passive_actuated_joint="${side}_gripper_motor_slider_joint"
                                simulated_reduction="1"   />
    </transmission>
-->
    </macro>
</robot>
