<?xml version="1.0" ?>
<!-- =================================================================================== -->
<!-- |    This document was autogenerated by xacro from pr2lite_base.xacro             | -->
<!-- |    EDITING THIS FILE BY HAND IS NOT RECOMMENDED                                 | -->
<!-- =================================================================================== -->
<robot name="pr2lite" xmlns:body="http://playerstage.sourceforge.net/gazebo/xmlschema/#body" xmlns:controller="http://playerstage.sourceforge.net/gazebo/xmlschema/#controller" xmlns:interface="http://playerstage.sourceforge.net/gazebo/xmlschema/#interface" xmlns:joint="http://playerstage.sourceforge.net/gazebo/xmlschema/#slider" xmlns:sensor="http://playerstage.sourceforge.net/gazebo/xmlschema/#sensor" xmlns:xacro="http://www.ros.org/wiki/xacro">
  <!-- Included URDF Files -->
  <material name="Black">
    <color rgba="0.0 0.0 0.0 1.0"/>
  </material>
  <material name="Blue">
    <color rgba="0.0 0.0 0.8 1.0"/>
  </material>
  <material name="Green">
    <color rgba="0.0 0.8 0.0 1.0"/>
  </material>
  <material name="Grey">
    <color rgba="0.7 0.7 0.7 1.0"/>
  </material>
  <material name="Grey2">
    <color rgba="0.9 0.9 0.9 1.0"/>
  </material>
  <material name="Red">
    <color rgba="0.8 0.0 0.0 1.0"/>
  </material>
  <material name="White">
    <color rgba="1.0 1.0 1.0 1.0"/>
  </material>
  <material name="GunMetalBrushedAluminum">
    <texture filename="package://smart_arm_description/Media/materials/textures/gun_metal_brushed_aluminum.jpg"/>
  </material>
  <!--
    <include filename="$(find pr2lite_urdf)/config/pr2lite_torso.xacro" />
-->
  <!-- Properties (Constants) -->
  <!-- property name="base_size_z" value="0.4318" -->
  <!-- base_size_z/2 + caster_width -->
  <!-- -base_size_z/2  -->
  <!-- -base_size_y/2  -->
  <!-- -inner_torso_bottom_size_x/2 -->
  <!-- base_footprint is a fictitious link(frame) that is on the ground right below base_link origin,
             navigation stack depends on this frame -->
  <link name="base_footprint">
    <inertial>
      <mass value="0.0001"/>
      <origin xyz="0.0 0.0 0.0"/>
      <inertia ixx="0.0001" ixy="0.0" ixz="0.0" iyy="0.0001" iyz="0.0" izz="0.0001"/>
    </inertial>
    <visual>
      <origin rpy="0 0 0" xyz="0.0 0.0 0.21844"/>
      <!--
-->
      <geometry>
        <box size="0.001 0.001 0.001"/>
      </geometry>
      <material name="Green"/>
    </visual>
    <collision>
      <origin rpy="0 0 0" xyz="0.0 0.0 0.21844"/>
      <!--
-->
      <geometry>
        <box size="0.001 0.001 0.001"/>
      </geometry>
    </collision>
  </link>
  <joint name="base_footprint_joint" type="fixed">
    <!-- NB: While you would think this would make it go up, it is oddly reversed.
                 This moves the joint to 0,0,0 where we want it for rviz, etc. -->
    <origin rpy="0 0 0" xyz="0.0 0.0 0.21844"/>
    <!--
-->
    <parent link="base_footprint"/>
    <child link="base_link"/>
  </joint>
  <!-- Links and Joints (i.e., the robot) -->
  <link name="base_link">
    <inertial>
      <mass value="20"/>
      <!-- origin xyz="${z2} ${y2} ${-base_size_z/2}" / -->
      <origin xyz="0.0 0.0 0.0"/>
      <inertia ixx="1.0" ixy="0.0" ixz="0.0" iyy="1.0" iyz="0.0" izz="1.0"/>
    </inertial>
    <visual>
      <origin rpy="0 0 0" xyz="0.0 0.0 0.21844"/>
      <geometry>
        <box size="0.4953 0.508 0.0127"/>
      </geometry>
      <material name="Blue"/>
    </visual>
    <collision>
      <origin rpy="0 0 0" xyz="0.0 0.0 0.0"/>
      <geometry>
        <box size="0.4953 0.508 0.0127"/>
      </geometry>
    </collision>
  </link>
  <joint name="base_inner_torso_joint" type="fixed">
    <origin rpy="0 0 0" xyz="0.24765 0.0 0.0"/>
    <parent link="base_link"/>
    <child link="inner_torso_bottom_link"/>
  </joint>
  <link name="inner_torso_bottom_link">
    <inertial>
      <mass value="20"/>
      <origin xyz="-0.1535 0.0 0.0"/>
      <inertia ixx="1.0" ixy="0.0" ixz="0.0" iyy="1.0" iyz="0.0" izz="1.0"/>
    </inertial>
    <visual>
      <origin rpy="0 0 0" xyz="-0.1535 0.0 0.0"/>
      <geometry>
        <box size="0.307 0.48 0.3"/>
      </geometry>
      <material name="Blue"/>
    </visual>
    <collision>
      <origin rpy="0 0 0" xyz="-0.1535 0.0 0.0"/>
      <geometry>
        <box size="0.307 0.48 0.3"/>
      </geometry>
    </collision>
  </link>
  <!-- 6.85in x 19 x 17.9 -->
  <joint name="inner_torso_top_joint" type="fixed">
    <origin rpy="0 0 0" xyz="-0.0685 0.0 0.0"/>
    <parent link="inner_torso_bottom_link"/>
    <child link="inner_torso_top_link"/>
  </joint>
  <link name="inner_torso_top_link">
    <inertial>
      <mass value="20"/>
      <origin xyz="0.0 0.0 0.0"/>
      <inertia ixx="1.0" ixy="0.0" ixz="0.0" iyy="1.0" iyz="0.0" izz="1.0"/>
    </inertial>
    <visual>
      <origin rpy="0 0 0" xyz="0.0 0.0 0.0"/>
      <geometry>
        <box size="0.17 0.48 0.46"/>
      </geometry>
      <material name="Blue"/>
    </visual>
    <collision>
      <origin rpy="0 0 0" xyz="-0.085 0.0 0.0"/>
      <geometry>
        <box size="0.17 0.48 0.46"/>
      </geometry>
    </collision>
  </link>
  <joint name="wheel_linear_actuator_joint" type="prismatic">
    <axis xyz="1 0 0"/>
    <limit effort="10000" lower="0.0" upper="0.1016" velocity=".05"/>
    <origin rpy="0 0 0" xyz="0.0 0.0 0.0"/>
    <parent link="base_link"/>
    <child link="wheel_linear_actuator_link"/>
  </joint>
  <link name="wheel_linear_actuator_link">
    <visual>
      <axis xyz="0 1 0"/>
      <origin rpy="0 1.57 0" xyz="-0.1524 0.0 0.0"/>
      <geometry>
        <box size=".0254 .0254 0.2032"/>
      </geometry>
      <material name="Silver1">
        <color rgba="0.0 0.9 0.9 1.0"/>
      </material>
    </visual>
  </link>
  <joint name="fl_linear_actuatuor_joint" type="fixed">
    <parent link="wheel_linear_actuator_link"/>
    <child link="fl_anchor_rod_link"/>
    <origin rpy="0 0 0" xyz="0.0 0.0 0.0"/>
  </joint>
  <joint name="fr_linear_actuatuor_joint" type="fixed">
    <parent link="wheel_linear_actuator_link"/>
    <child link="fr_anchor_rod_link"/>
    <origin rpy="0 0 0" xyz="0.0 0.0 0.0"/>
  </joint>
  <joint name="bl_linear_actuatuor_joint" type="fixed">
    <parent link="wheel_linear_actuator_link"/>
    <child link="bl_anchor_rod_link"/>
    <origin rpy="0 0 0" xyz="0.0 0.0 0.0"/>
  </joint>
  <joint name="br_linear_actuatuor_joint" type="fixed">
    <parent link="wheel_linear_actuator_link"/>
    <child link="br_anchor_rod_link"/>
    <origin rpy="0 0 0" xyz="0.0 0.0 0.0"/>
  </joint>
  <joint name="fl_base_joint" type="fixed">
    <axis xyz="0 0 1"/>
    <parent link="base_link"/>
    <child link="fl_base_link"/>
    <origin rpy="0 0 0" xyz="0.1651 0.1651 0.00635"/>
  </joint>
  <link name="fl_base_link">
    <visual>
      <origin rpy="0 0 0" xyz="0 0 0"/>
      <geometry>
        <box size=".0201 .0201 .0001"/>
      </geometry>
      <material name="Grey1">
        <color rgba="0 0.9 0.9 1.0"/>
      </material>
    </visual>
  </link>
  <link name="fl_anchor_rod_link">
    <visual>
      <axis xyz="0 0 1"/>
      <origin rpy="0 0 0" xyz="-0.0508 -0.10795 0"/>
      <geometry>
        <box size="0.01905 0.2159 0.00127"/>
      </geometry>
      <material name="Silver1">
        <color rgba="0 0.9 0.9 1.0"/>
      </material>
    </visual>
  </link>
  <joint name="fl_anchor_rod_joint" type="revolute">
    <axis xyz="0 0 1"/>
    <limit effort="10" lower="-3.1416" upper="3.1416" velocity="3"/>
    <parent link="fl_anchor_rod_link"/>
    <child link="fl_push_rod_link"/>
    <origin rpy="0 0 0" xyz="-0.0508 0.2159 0"/>
  </joint>
  <link name="fl_push_rod_link">
    <visual>
      <axis xyz="0 0 1"/>
      <origin rpy="0 0 0" xyz="-0.0889 0 0"/>
      <geometry>
        <box size="0.1778 0.01905 0.00127"/>
      </geometry>
      <material name="Silver1">
        <color rgba="0 0.9 0.9 1.0"/>
      </material>
    </visual>
  </link>
  <joint name="fl_caster_rotation_joint" type="revolute">
    <axis xyz="0 0 1"/>
    <limit effort="10" lower="-3.1416" upper="3.1416" velocity="3"/>
    <parent link="fl_base_link"/>
    <child link="fl_caster_link"/>
    <origin rpy="0 0 0" xyz="0 0 0"/>
  </joint>
  <link name="fl_caster_link">
    <visual>
      <origin rpy="0 0 0" xyz="0 0 0"/>
      <geometry>
        <box size="0.1016 0.1016 0.00635"/>
      </geometry>
      <material name="Grey1">
        <color rgba="0 0.9 0.9 1.0"/>
      </material>
    </visual>
  </link>
  <joint name="fl_caster_motor_joint" type="fixed">
    <axis xyz="0 0 1"/>
    <parent link="fl_caster_link"/>
    <child link="fl_wheel_motor_block_link"/>
    <origin rpy="0 0 0" xyz="0 0 0"/>
  </joint>
  <link name="fl_wheel_motor_block_link">
    <visual>
      <origin rpy="0 0 0" xyz="0 0 -0.0508"/>
      <geometry>
        <box size="0.1016 0.0254 0.1016"/>
      </geometry>
      <material name="Blue1">
        <color rgba="0 0.9 0.9 1.0"/>
      </material>
    </visual>
  </link>
  <joint name="fl_wheel_joint" type="continuous">
    <axis xyz="0 1 0"/>
    <limit effort="100" velocity="100"/>
    <safety_controller k_velocity="10"/>
    <dynamics damping="0.0" friction="0.0"/>
    <origin rpy="0 0 0" xyz="0 0.0254 -0.0889"/>
    <parent link="fl_wheel_motor_block_link"/>
    <child link="fl_wheel_link"/>
  </joint>
  <link name="fl_wheel_link">
    <inertial>
      <mass value="0.1"/>
      <origin xyz=" 0 0 0 "/>
      <inertia ixx="0.012411765597" ixy="0.0" ixz="0.0" iyy="0.015218160428" iyz="0.0" izz="0.011763977943"/>
    </inertial>
    <visual>
      <origin rpy="0 1.570795 1.570795" xyz="0 0.00635 0"/>
      <geometry>
        <cylinder length="0.0127" radius="0.0762"/>
      </geometry>
      <material name="Grey"/>
    </visual>
    <collision>
      <origin rpy="0 1.570795 1.570795" xyz="0 0 0"/>
      <geometry>
        <cylinder length="0.0127" radius="0.0762"/>
      </geometry>
    </collision>
    <gazebo reference="base_link_fl_wheel_link">
      <mu1 value="100.0"/>
      <mu2 value="100.0"/>
      <kp value="1000000.0"/>
      <kd value="1.0"/>
      <material>Erratic/Grey</material>
    </gazebo>
    <gazebo reference="base_link_fl_motor_link">
      <material>Erratic/White</material>
    </gazebo>
    <transmission name="base_link_fl_wheel_trans" type="pr2_mechanism_model/SimpleTransmission">
      <actuator name="base_link_fl_wheel_motor"/>
      <joint name="base_link_fl_wheel_joint"/>
      <mechanicalReduction>1.0</mechanicalReduction>
    </transmission>
  </link>
  <joint name="fr_base_joint" type="fixed">
    <axis xyz="0 0 1"/>
    <parent link="base_link"/>
    <child link="fr_base_link"/>
    <origin rpy="0 0 0" xyz="0.1651 -0.1651 0.00635"/>
  </joint>
  <link name="fr_base_link">
    <visual>
      <origin rpy="0 0 0" xyz="0 0 0"/>
      <geometry>
        <box size=".0201 .0201 .0001"/>
      </geometry>
      <material name="Grey1">
        <color rgba="0 0.9 0.9 1.0"/>
      </material>
    </visual>
  </link>
  <link name="fr_anchor_rod_link">
    <visual>
      <axis xyz="0 0 1"/>
      <origin rpy="0 0 0" xyz="-0.0508 0.05715 0"/>
      <geometry>
        <box size="0.01905 0.1143 0.00127"/>
      </geometry>
      <material name="Silver1">
        <color rgba="0 0.9 0.9 1.0"/>
      </material>
    </visual>
  </link>
  <joint name="fr_anchor_rod_joint" type="revolute">
    <axis xyz="0 0 1"/>
    <limit effort="10" lower="-3.1416" upper="3.1416" velocity="3"/>
    <parent link="fr_anchor_rod_link"/>
    <child link="fr_push_rod_link"/>
    <origin rpy="0 0 0" xyz="-0.0508 -0.2159 0"/>
  </joint>
  <link name="fr_push_rod_link">
    <visual>
      <axis xyz="0 0 1"/>
      <origin rpy="0 0 0" xyz="-0.0889 0 0"/>
      <geometry>
        <box size="0.1778 0.01905 0.00127"/>
      </geometry>
      <material name="Silver1">
        <color rgba="0 0.9 0.9 1.0"/>
      </material>
    </visual>
  </link>
  <joint name="fr_caster_rotation_joint" type="revolute">
    <axis xyz="0 0 1"/>
    <limit effort="10" lower="-3.1416" upper="3.1416" velocity="3"/>
    <parent link="fr_base_link"/>
    <child link="fr_caster_link"/>
    <origin rpy="0 0 0" xyz="0 0 0"/>
  </joint>
  <link name="fr_caster_link">
    <visual>
      <origin rpy="0 0 0" xyz="0 0 0"/>
      <geometry>
        <box size="0.1016 0.1016 0.00635"/>
      </geometry>
      <material name="Grey1">
        <color rgba="0 0.9 0.9 1.0"/>
      </material>
    </visual>
  </link>
  <joint name="fr_caster_motor_joint" type="fixed">
    <axis xyz="0 0 1"/>
    <parent link="fr_caster_link"/>
    <child link="fr_wheel_motor_block_link"/>
    <origin rpy="0 0 0" xyz="0 0 0"/>
  </joint>
  <link name="fr_wheel_motor_block_link">
    <visual>
      <origin rpy="0 0 0" xyz="0 0 -0.0508"/>
      <geometry>
        <box size="0.1016 0.0254 0.1016"/>
      </geometry>
      <material name="Blue1">
        <color rgba="0 0.9 0.9 1.0"/>
      </material>
    </visual>
  </link>
  <joint name="fr_wheel_joint" type="continuous">
    <axis xyz="0 1 0"/>
    <limit effort="100" velocity="100"/>
    <safety_controller k_velocity="10"/>
    <dynamics damping="0.0" friction="0.0"/>
    <origin rpy="0 0 0" xyz="0 -0.0254 -0.0889"/>
    <parent link="fr_wheel_motor_block_link"/>
    <child link="fr_wheel_link"/>
  </joint>
  <link name="fr_wheel_link">
    <inertial>
      <mass value="0.1"/>
      <origin xyz=" 0 0 0 "/>
      <inertia ixx="0.012411765597" ixy="0.0" ixz="0.0" iyy="0.015218160428" iyz="0.0" izz="0.011763977943"/>
    </inertial>
    <visual>
      <origin rpy="0 1.570795 1.570795" xyz="0 -0.00635 0"/>
      <geometry>
        <cylinder length="0.0127" radius="0.0762"/>
      </geometry>
      <material name="Grey"/>
    </visual>
    <collision>
      <origin rpy="0 1.570795 1.570795" xyz="0 0 0"/>
      <geometry>
        <cylinder length="0.0127" radius="0.0762"/>
      </geometry>
    </collision>
    <gazebo reference="base_link_fr_wheel_link">
      <mu1 value="100.0"/>
      <mu2 value="100.0"/>
      <kp value="1000000.0"/>
      <kd value="1.0"/>
      <material>Erratic/Grey</material>
    </gazebo>
    <gazebo reference="base_link_fr_motor_link">
      <material>Erratic/White</material>
    </gazebo>
    <transmission name="base_link_fr_wheel_trans" type="pr2_mechanism_model/SimpleTransmission">
      <actuator name="base_link_fr_wheel_motor"/>
      <joint name="base_link_fr_wheel_joint"/>
      <mechanicalReduction>1.0</mechanicalReduction>
    </transmission>
  </link>
  <joint name="bl_base_joint" type="fixed">
    <axis xyz="0 0 1"/>
    <parent link="base_link"/>
    <child link="bl_base_link"/>
    <origin rpy="0 0 0" xyz="-0.1651 0.1651 0.00635"/>
  </joint>
  <link name="bl_base_link">
    <visual>
      <origin rpy="0 0 0" xyz="0 0 0"/>
      <geometry>
        <box size=".0201 .0201 .0001"/>
      </geometry>
      <material name="Grey1">
        <color rgba="0 0.9 0.9 1.0"/>
      </material>
    </visual>
  </link>
  <link name="bl_anchor_rod_link">
    <visual>
      <axis xyz="0 0 1"/>
      <origin rpy="0 0 0" xyz="-0.0508 -0.05715 0"/>
      <geometry>
        <box size="0.01905 0.1143 0.00127"/>
      </geometry>
      <material name="Silver1">
        <color rgba="0 0.9 0.9 1.0"/>
      </material>
    </visual>
  </link>
  <joint name="bl_anchor_rod_joint" type="revolute">
    <axis xyz="0 0 1"/>
    <limit effort="10" lower="-3.1416" upper="3.1416" velocity="3"/>
    <parent link="bl_anchor_rod_link"/>
    <child link="bl_push_rod_link"/>
    <origin rpy="0 0 0" xyz="-0.0508 0.1143 0"/>
  </joint>
  <link name="bl_push_rod_link">
    <visual>
      <axis xyz="0 0 1"/>
      <origin rpy="0 0 0" xyz="0.0889 0 0"/>
      <geometry>
        <box size="0.1778 0.01905 0.00127"/>
      </geometry>
      <material name="Silver1">
        <color rgba="0 0.9 0.9 1.0"/>
      </material>
    </visual>
  </link>
  <joint name="bl_caster_rotation_joint" type="revolute">
    <axis xyz="0 0 1"/>
    <limit effort="10" lower="-3.1416" upper="3.1416" velocity="3"/>
    <parent link="bl_base_link"/>
    <child link="bl_caster_link"/>
    <origin rpy="0 0 0" xyz="0 0 0"/>
  </joint>
  <link name="bl_caster_link">
    <visual>
      <origin rpy="0 0 0" xyz="0 0 0"/>
      <geometry>
        <box size="0.1016 0.1016 0.00635"/>
      </geometry>
      <material name="Grey1">
        <color rgba="0 0.9 0.9 1.0"/>
      </material>
    </visual>
  </link>
  <joint name="bl_caster_motor_joint" type="fixed">
    <axis xyz="0 0 1"/>
    <parent link="bl_caster_link"/>
    <child link="bl_wheel_motor_block_link"/>
    <origin rpy="0 0 0" xyz="0 0 0"/>
  </joint>
  <link name="bl_wheel_motor_block_link">
    <visual>
      <origin rpy="0 0 0" xyz="0 0 -0.0508"/>
      <geometry>
        <box size="0.1016 0.0254 0.1016"/>
      </geometry>
      <material name="Blue1">
        <color rgba="0 0.9 0.9 1.0"/>
      </material>
    </visual>
  </link>
  <joint name="bl_wheel_joint" type="continuous">
    <axis xyz="0 1 0"/>
    <limit effort="100" velocity="100"/>
    <safety_controller k_velocity="10"/>
    <dynamics damping="0.0" friction="0.0"/>
    <origin rpy="0 0 0" xyz="0 0.0254 -0.0889"/>
    <parent link="bl_wheel_motor_block_link"/>
    <child link="bl_wheel_link"/>
  </joint>
  <link name="bl_wheel_link">
    <inertial>
      <mass value="0.1"/>
      <origin xyz=" 0 0 0 "/>
      <inertia ixx="0.012411765597" ixy="0.0" ixz="0.0" iyy="0.015218160428" iyz="0.0" izz="0.011763977943"/>
    </inertial>
    <visual>
      <origin rpy="0 1.570795 1.570795" xyz="0 0.00635 0"/>
      <geometry>
        <cylinder length="0.0127" radius="0.0762"/>
      </geometry>
      <material name="Grey"/>
    </visual>
    <collision>
      <origin rpy="0 1.570795 1.570795" xyz="0 0 0"/>
      <geometry>
        <cylinder length="0.0127" radius="0.0762"/>
      </geometry>
    </collision>
    <gazebo reference="base_link_bl_wheel_link">
      <mu1 value="100.0"/>
      <mu2 value="100.0"/>
      <kp value="1000000.0"/>
      <kd value="1.0"/>
      <material>Erratic/Grey</material>
    </gazebo>
    <gazebo reference="base_link_bl_motor_link">
      <material>Erratic/White</material>
    </gazebo>
    <transmission name="base_link_bl_wheel_trans" type="pr2_mechanism_model/SimpleTransmission">
      <actuator name="base_link_bl_wheel_motor"/>
      <joint name="base_link_bl_wheel_joint"/>
      <mechanicalReduction>1.0</mechanicalReduction>
    </transmission>
  </link>
  <joint name="br_base_joint" type="fixed">
    <axis xyz="0 0 1"/>
    <parent link="base_link"/>
    <child link="br_base_link"/>
    <origin rpy="0 0 0" xyz="-0.1651 -0.1651 0.00635"/>
  </joint>
  <link name="br_base_link">
    <visual>
      <origin rpy="0 0 0" xyz="0 0 0"/>
      <geometry>
        <box size=".0201 .0201 .0001"/>
      </geometry>
      <material name="Grey1">
        <color rgba="0 0.9 0.9 1.0"/>
      </material>
    </visual>
  </link>
  <link name="br_anchor_rod_link">
    <visual>
      <axis xyz="0 0 1"/>
      <origin rpy="0 0 0" xyz="-0.0508 0.10795 0"/>
      <geometry>
        <box size="0.01905 0.2159 0.00127"/>
      </geometry>
      <material name="Silver1">
        <color rgba="0 0.9 0.9 1.0"/>
      </material>
    </visual>
  </link>
  <joint name="br_anchor_rod_joint" type="revolute">
    <axis xyz="0 0 1"/>
    <limit effort="10" lower="-3.1416" upper="3.1416" velocity="3"/>
    <parent link="br_anchor_rod_link"/>
    <child link="br_push_rod_link"/>
    <origin rpy="0 0 0" xyz="-0.0508 -0.1143 0"/>
  </joint>
  <link name="br_push_rod_link">
    <visual>
      <axis xyz="0 0 1"/>
      <origin rpy="0 0 0" xyz="0.0889 0 0"/>
      <geometry>
        <box size="0.1778 0.01905 0.00127"/>
      </geometry>
      <material name="Silver1">
        <color rgba="0 0.9 0.9 1.0"/>
      </material>
    </visual>
  </link>
  <joint name="br_caster_rotation_joint" type="revolute">
    <axis xyz="0 0 1"/>
    <limit effort="10" lower="-3.1416" upper="3.1416" velocity="3"/>
    <parent link="br_base_link"/>
    <child link="br_caster_link"/>
    <origin rpy="0 0 0" xyz="0 0 0"/>
  </joint>
  <link name="br_caster_link">
    <visual>
      <origin rpy="0 0 0" xyz="0 0 0"/>
      <geometry>
        <box size="0.1016 0.1016 0.00635"/>
      </geometry>
      <material name="Grey1">
        <color rgba="0 0.9 0.9 1.0"/>
      </material>
    </visual>
  </link>
  <joint name="br_caster_motor_joint" type="fixed">
    <axis xyz="0 0 1"/>
    <parent link="br_caster_link"/>
    <child link="br_wheel_motor_block_link"/>
    <origin rpy="0 0 0" xyz="0 0 0"/>
  </joint>
  <link name="br_wheel_motor_block_link">
    <visual>
      <origin rpy="0 0 0" xyz="0 0 -0.0508"/>
      <geometry>
        <box size="0.1016 0.0254 0.1016"/>
      </geometry>
      <material name="Blue1">
        <color rgba="0 0.9 0.9 1.0"/>
      </material>
    </visual>
  </link>
  <joint name="br_wheel_joint" type="continuous">
    <axis xyz="0 1 0"/>
    <limit effort="100" velocity="100"/>
    <safety_controller k_velocity="10"/>
    <dynamics damping="0.0" friction="0.0"/>
    <origin rpy="0 0 0" xyz="0 -0.0254 -0.0889"/>
    <parent link="br_wheel_motor_block_link"/>
    <child link="br_wheel_link"/>
  </joint>
  <link name="br_wheel_link">
    <inertial>
      <mass value="0.1"/>
      <origin xyz=" 0 0 0 "/>
      <inertia ixx="0.012411765597" ixy="0.0" ixz="0.0" iyy="0.015218160428" iyz="0.0" izz="0.011763977943"/>
    </inertial>
    <visual>
      <origin rpy="0 1.570795 1.570795" xyz="0 -0.00635 0"/>
      <geometry>
        <cylinder length="0.0127" radius="0.0762"/>
      </geometry>
      <material name="Grey"/>
    </visual>
    <collision>
      <origin rpy="0 1.570795 1.570795" xyz="0 0 0"/>
      <geometry>
        <cylinder length="0.0127" radius="0.0762"/>
      </geometry>
    </collision>
    <gazebo reference="base_link_br_wheel_link">
      <mu1 value="100.0"/>
      <mu2 value="100.0"/>
      <kp value="1000000.0"/>
      <kd value="1.0"/>
      <material>Erratic/Grey</material>
    </gazebo>
    <gazebo reference="base_link_br_motor_link">
      <material>Erratic/White</material>
    </gazebo>
    <transmission name="base_link_br_wheel_trans" type="pr2_mechanism_model/SimpleTransmission">
      <actuator name="base_link_br_wheel_motor"/>
      <joint name="base_link_br_wheel_joint"/>
      <mechanicalReduction>1.0</mechanicalReduction>
    </transmission>
  </link>
  <xacro:prlite_torso>
        </xacro:prlite_torso>
  <!--
        <xacro:smart_arm parent="left_shoulder_pan_link" side="left" >
        </xacro:smart_arm>
        <xacro:smart_arm parent="right_shoulder_pan_link" side="right" >
        </xacro:smart_arm>
        <xacro:hokuyo_urg name="hokuyo" parent="hokuyo_torso_link" >
        </xacro:hokuyo_urg>
-->
</robot>

