<?xml version="1.0" ?>
<!-- =================================================================================== -->
<!-- |    This document was autogenerated by xacro from ../config/pr2lite_base.xacro   | -->
<!-- |    EDITING THIS FILE BY HAND IS NOT RECOMMENDED                                 | -->
<!-- =================================================================================== -->
<!-- How to calibrate ax-12 joint limits:
   1 - search for "revolute" joints (note: linear actuators are "prismatic")
   2 - do a "rostopic list" and look for joints with AX-12 on them.
   3 - do a "rostopic echo </jointname/state"
   4 - turn off CM-5
   5 - move chosen joint to one of the extreme positions
   6 - turn on CM-5
   7 - Control-C the rostopic echo command
   8 - copy the position from the rostopic echo. 
   9 - If negative, change the "lower" value (pos = "upper) in the associated line:
     <limit effort="10" lower="-3.1416" upper="3.1416" velocity="3"/>
   10 - repeat steps 4-9 for other extreme position
   11 - repeat 1-10 until all ax-12 joints complete
   12 - test values using trajectory planning
   13 - when satisfied, make corresponding changes in pr2lite_smart_arm.yaml, 
   14 - make corresponding changes to corresponding urdf .xacro files
-->
<robot name="pr2lite" xmlns:body="http://playerstage.sourceforge.net/gazebo/xmlschema/#body" xmlns:controller="http://playerstage.sourceforge.net/gazebo/xmlschema/#controller" xmlns:interface="http://playerstage.sourceforge.net/gazebo/xmlschema/#interface" xmlns:joint="http://playerstage.sourceforge.net/gazebo/xmlschema/#slider" xmlns:sensor="http://playerstage.sourceforge.net/gazebo/xmlschema/#sensor" xmlns:xacro="http://www.ros.org/wiki/xacro">
  <!-- Included URDF Files -->
  <!-- 
     From Matthew:
      width of outer torso: 0.526999 meters
      height of outer torso: 0.771906 meters
      width of joints of arms: 0.4126992 meters
      joints of arms: 0.05715
    -->

  <!-- 
        <property name="pr2lite_left_calib_cam_x" value="-1.03976" />
        <property name="pr2lite_left_calib_cam_y" value="-0" />
        <property name="pr2lite_left_calib_cam_z" value="1.02602" />
        <property name="pr2lite_left_calib_cam_rr" value="3.14159" />
        <property name="pr2lite_left_calib_cam_rp" value="2.69908e-12" />
        <property name="pr2lite_left_calib_cam_ry" value="3.14159" />
	<property name="pr2lite_left_kinect_frame_name" value="left_arm_shelf_link" />

	<property name="turtlebot_calib_cam_x" value="nan" />
	<property name="turtlebot_calib_cam_y" value="nan" />
	<property name="turtlebot_calib_cam_z" value="nan" />
	<property name="turtlebot_calib_cam_rr" value="-nan" />
	<property name="turtlebot_calib_cam_rp" value="1.5708" />
	<property name="turtlebot_calib_cam_ry" value="0" />
	<property name="turtlebot_kinect_frame_name" value="right_arm_shelf_link" />

	<property name="pr2lite_right_calib_cam_x" value="nan" />
	<property name="pr2lite_right_calib_cam_y" value="nan" />
	<property name="pr2lite_right_calib_cam_z" value="nan" />
	<property name="pr2lite_right_calib_cam_rr" value="-nan" />
	<property name="pr2lite_right_calib_cam_rp" value="1.5708" />
	<property name="pr2lite_right_calib_cam_ry" value="0" />
	<property name="pr2lite_right_kinect_frame_name" value="right_arm_shelf_link" />
    -->


  <material name="Black">
    <color rgba="0.0 0.0 0.0 1.0"/>
  </material>
  <material name="Blue">
    <color rgba="0.0 0.0 0.8 1.0"/>
  </material>
  <material name="Green">
    <color rgba="0.0 0.8 0.0 1.0"/>
  </material>
  <material name="Grey">
    <color rgba="0.7 0.7 0.7 1.0"/>
  </material>
  <material name="Grey2">
    <color rgba="0.9 0.9 0.9 1.0"/>
  </material>
  <material name="Red">
    <color rgba="0.8 0.0 0.0 1.0"/>
  </material>
  <material name="White">
    <color rgba="1.0 1.0 1.0 1.0"/>
  </material>
  <material name="GunMetalBrushedAluminum">
    <texture filename="package://smart_arm_description/Media/materials/textures/gun_metal_brushed_aluminum.jpg"/>
  </material>
  <!--
    <include filename="$(find pr2lite_urdf)/config/pr2lite_torso.xacro" />
-->
  <!-- Properties (Constants) -->
  <!-- base_footprint is a fictitious link(frame) that is on the ground right below base_link origin, navigation stack depends on this frame -->
  <link name="base_footprint">
    <visual>
      <origin rpy="0 0 0" xyz="0.0 0.0 0.00889"/>
      <geometry>
        <box size="0.001 0.001 0.001"/>
      </geometry>
      <material name="Green"/>
    </visual>
    <collision>
      <origin rpy="0 0 0" xyz="0.0 0.0 0.00889"/>
      <geometry>
        <box size="0.001 0.001 0.001"/>
      </geometry>
    </collision>
  </link>
  <joint name="base_footprint_joint" type="fixed">
    <!-- NB: While you would think this would make it go up, it is oddly reversed.
              This moves the joint to 0,0,0 where we want it for rviz, etc. -->
    <origin rpy="0 0 0" xyz="0.0 0.0 0.26289"/>
    <parent link="base_footprint"/>
    <child link="base_link"/>
  </joint>
  <!-- Links and Joints (i.e., the robot) -->
  <link name="base_link">
    <inertial>
      <mass value="20"/>
      <origin xyz="0 0 0.04064"/>
      <inertia ixx="1.0" ixy="0.0" ixz="0.0" iyy="1.0" iyz="0.0" izz="1.0"/>
    </inertial>
    <visual>
      <origin rpy="0 0 0" xyz="0 0 0.00889"/>
      <geometry>
        <box size="0.508 0.508 0.0127"/>
      </geometry>
      <material name="Blue"/>
    </visual>
    <collision>
      <origin rpy="0 0 0" xyz="0 0 0.00889"/>
      <geometry>
        <box size="0.508 0.508 0.0127"/>
      </geometry>
    </collision>
  </link>
  <joint name="base_inner_torso_joint" type="fixed">
    <origin xyz="-0.1005 0.0 0.1627"/>
    <parent link="base_link"/>
    <child link="inner_torso_bottom_link"/>
  </joint>
  <link name="inner_torso_bottom_link">
    <inertial>
      <mass value="0"/>
      <origin xyz="0.0 0.0 0.0"/>
      <inertia ixx="1.0" ixy="0.0" ixz="0.0" iyy="1.0" iyz="0.0" izz="1.0"/>
    </inertial>
    <visual>
      <origin rpy="0 0 0" xyz="0.0 0.0 0.0"/>
      <geometry>
        <box size="0.307 0.48 0.3"/>
      </geometry>
      <material name="Blue"/>
    </visual>
    <collision>
      <origin rpy="0 0 0" xyz="-0.1535 0.0 0.0"/>
      <geometry>
        <box size="0.307 0.48 0.3"/>
      </geometry>
    </collision>
  </link>
  <!-- 6.85in x 19 x 17.9 -->
  <joint name="inner_torso_top_joint" type="fixed">
    <origin rpy="0 0 0" xyz="-0.0685 0.0 0.0"/>
    <parent link="inner_torso_bottom_link"/>
    <child link="inner_torso_top_link"/>
  </joint>
  <link name="inner_torso_top_link">
    <inertial>
      <mass value="0"/>
      <origin xyz="0.0 0.0 0.0"/>
      <inertia ixx="1.0" ixy="0.0" ixz="0.0" iyy="1.0" iyz="0.0" izz="1.0"/>
    </inertial>
    <visual>
      <origin rpy="0 0 0" xyz="0.0 0.0 0.3"/>
      <geometry>
        <box size="0.17 0.4953 0.46"/>
      </geometry>
      <material name="Blue"/>
    </visual>
    <collision>
      <origin rpy="0 0 0" xyz="-0.085 0.0 0.3"/>
      <geometry>
        <box size="0.17 0.4953 0.46"/>
      </geometry>
    </collision>
  </link>
  <joint name="torso_body_joint" type="fixed">
    <parent link="inner_torso_bottom_link"/>
    <child link="torso_lift_link"/>
    <origin rpy="0 0 0" xyz="0.156845 0 0.1651"/>
  </joint>
  <link name="torso_lift_link">
    <inertial>
      <mass value="0"/>
      <origin xyz="0.0 0.0 0.0"/>
      <inertia ixx="1.0" ixy="0.0" ixz="0.0" iyy="1.0" iyz="0.0" izz="1.0"/>
    </inertial>
    <visual>
      <axis xyz="0 0 0"/>
      <origin rpy="0 0 0" xyz="0.0 0.0 -0.0381"/>
      <geometry>
        <box size="0.0254 0.0254 0.4318"/>
      </geometry>
      <material name="Silver1">
        <color rgba="0 0.9 0.9 1.0"/>
      </material>
    </visual>
  </link>
  <joint name="torso_lift_joint" type="prismatic">
    <axis xyz="0 0 1"/>
    <limit effort="10000" lower="0.0" upper="0.3048" velocity=".05"/>
    <origin rpy="0 0 0" xyz="-0 0 0"/>
    <parent link="torso_lift_link"/>
    <child link="torso_link"/>
    <origin rpy="0 0 0" xyz="0 0.0127 0"/>
  </joint>
  <link name="torso_link">
    <inertial>
      <mass value="0"/>
      <origin xyz="0.0 0.0 0.0"/>
      <inertia ixx="1.0" ixy="0.0" ixz="0.0" iyy="1.0" iyz="0.0" izz="1.0"/>
    </inertial>
    <visual>
      <axis xyz="0 0 0"/>
      <origin rpy="0 0 0" xyz="0.0127 0.0 0.0635"/>
      <geometry>
        <box size="0.00635 .1587 0.619506"/>
      </geometry>
      <material name="Silver1">
        <color rgba="0 0.9 0.9 1.0"/>
      </material>
    </visual>
  </link>
  <joint name="torso_body_joint2" type="fixed">
    <parent link="torso_link"/>
    <child link="bottom_outer_torso_link"/>
    <origin rpy="0 0 0" xyz="0 0 -0.0975"/>
  </joint>
  <link name="bottom_outer_torso_link">
    <inertial>
      <mass value="0"/>
      <origin xyz="0.0 0.0 0.0"/>
      <inertia ixx="1.0" ixy="0.0" ixz="0.0" iyy="1.0" iyz="0.0" izz="1.0"/>
    </inertial>
    <visual>
      <axis xyz="0 0 0"/>
      <origin rpy="0 0 0" xyz="0.0127 0.0 0.0"/>
      <geometry>
        <box size="0.00635 0.52705 0.32385"/>
      </geometry>
      <material name="Silver1">
        <color rgba="0 0.9 0.9 1.0"/>
      </material>
    </visual>
  </link>
  <joint name="top_shelf_joint" type="fixed">
    <parent link="bottom_outer_torso_link"/>
    <child link="top_shelf_link"/>
    <origin rpy="0 0 0" xyz="0.0127 0.00 0.1619250"/>
  </joint>
  <link name="top_shelf_link">
    <inertial>
      <mass value="0"/>
      <origin xyz="0.0127 0.0 0.0"/>
      <inertia ixx="1.0" ixy="0.0" ixz="0.0" iyy="1.0" iyz="0.0" izz="1.0"/>
    </inertial>
    <visual>
      <origin rpy="0 0 0" xyz="0.0 0.0 0.217"/>
      <geometry>
<!-- ARD
      <origin rpy="0 0 0" xyz="-0.0635 0.0 0.38735"/>
      <origin rpy="0 0 0" xyz="-0.0635 0.0 0.406"/>
      <origin rpy="0 0 0" xyz="-0.0635 0.0 0.38735"/>
        <box size="0.1524 0.508 0.00635"/>
.434
-->
        <box size="0.00635 0.1524 0.434"/>
      </geometry>
      <material name="Grey1">
        <color rgba="0 0.9 0.9 1.0"/>
      </material>
    </visual>
  </link>
  <!-- PR2LITE HEAD starts here -->
  <joint name="neck_joint" type="fixed">
    <parent link="top_shelf_link"/>
    <child link="neck_link"/>
    <origin rpy="0 0 0" xyz="-0.073025 0.0 0.434"/>
<!-- ARD
    <origin rpy="0 0 0" xyz="-0.073025 0.0 0.38735"/>
    <origin rpy="0 0 0" xyz="-0.073025 0.0 0.406"/>
    <origin rpy="0 0 0" xyz="-0.073025 0.0 0.38735"/>
.0127 + .08255=.09525

-->
  </joint>
  <link name="neck_link">
    <inertial>
      <mass value="0"/>
      <origin xyz="0.0 0.0 0.0"/>
      <inertia ixx="1.0" ixy="0.0" ixz="0.0" iyy="1.0" iyz="0.0" izz="1.0"/>
    </inertial>
    <visual>
      <origin rpy="0 0 0" xyz="0.0 0.0 0.09525 "/>
      <geometry>
        <box size="-0.00635 0.14605 0.1651"/>
      </geometry>
      <material name="Brown">
        <color rgba="0 0.9 0.9 1.0"/>
      </material>
    </visual>
  </link>
  <joint name="top_neck_joint" type="fixed">
    <parent link="neck_link"/>
    <child link="top_neck_link"/>
    <origin rpy="0 0 0" xyz="0.0 0.0 0.17145"/>
<!-- 0.00635 + .1651 -->
  </joint>
  <link name="top_neck_link">
    <inertial>
      <mass value="0"/>
      <origin xyz="0.0 0.0 0.0"/>
      <inertia ixx="1.0" ixy="0.0" ixz="0.0" iyy="1.0" iyz="0.0" izz="1.0"/>
    </inertial>
    <visual>
      <origin rpy="0 0 0" xyz="0.0508 0.0 0.003175"/>
      <geometry>
        <box size="0.1016 0.14605 0.00635"/>
      </geometry>
      <material name="Silver1">
        <color rgba="0 0.9 0.9 1.0"/>
      </material>
    </visual>
  </link>
  <!-- 4x 13.14 -->
  <joint name="head_pan_joint" type="revolute">
    <limit effort="10" lower="-2.618" upper="2.618" velocity="3"/>
    <parent link="top_neck_link"/>
    <child link="head_pan_link"/>
    <origin rpy="0 0 0" xyz="0.0508 0.0 0.009525"/>
    <axis xyz="0 0 1"/>
  </joint>
  <link name="head_pan_link">
    <inertial>
      <mass value="0"/>
      <origin xyz="0.0 0.0 0.0"/>
      <inertia ixx="1.0" ixy="0.0" ixz="0.0" iyy="1.0" iyz="0.0" izz="1.0"/>
    </inertial>
    <visual>
      <origin rpy="0 0 0" xyz="0.0 0.0 0.0127"/>
      <geometry>
        <box size="0.1016 0.333756 0.00635"/>
<!-- ARD: add caster width
        <box size="0.1016 0.333756 0.0127"/>
-->
      </geometry>
      <material name="Silver1">
        <color rgba="0 0.9 0.9 1.0"/>
      </material>
    </visual>
  </link>
  <joint name="head_side_joint" type="fixed">
    <parent link="head_pan_link"/>
    <child link="head_side_link"/>
    <origin rpy="0 0 0" xyz="0.0 0.163703 0.0788035"/>
<!-- ARD:
    <origin rpy="0 0 0" xyz="0.0 0.163703 0.0635"/>
-->
  </joint>
  <link name="head_side_link">
    <inertial>
      <mass value="0"/>
      <origin xyz="0.0 0.0 0.0"/>
      <inertia ixx="1.0" ixy="0.0" ixz="0.0" iyy="1.0" iyz="0.0" izz="1.0"/>
    </inertial>
    <visual>
<!-- ARD:
      <origin rpy="0 0 0" xyz="0.0 -0.003175 0.0"/>
-->
      <origin rpy="0 0 0" xyz="0.0 0.0 0.0"/>
      <geometry>
        <box size="0.1016 0.00635 0.127"/>
      </geometry>
      <material name="Silver1">
        <color rgba="0 0.9 0.9 1.0"/>
      </material>
    </visual>
  </link>
  <joint name="head_tilt_joint" type="revolute">
    <limit effort="10" lower="-2.618" upper="2.618" velocity="3"/>
    <parent link="head_side_link"/>
    <child link="head_tilt_link"/>
    <origin rpy="0 0 0" xyz="0.0 -0.00635 0.0127"/>
    <axis xyz="0 1 0"/>
  </joint>
  <link name="head_tilt_link">
    <inertial>
      <mass value="0"/>
      <origin xyz="0.0 0.0 0.0"/>
      <inertia ixx="1.0" ixy="0.0" ixz="0.0" iyy="1.0" iyz="0.0" izz="1.0"/>
    </inertial>
    <visual>
      <origin rpy="0 0 0" xyz="0.0 -0.003175 0.0"/>
      <geometry>
        <box size="0.1016 -0.00635 0.1016"/>
      </geometry>
      <material name="green">
        <color rgba="0 0.9 0.9 1.0"/>
      </material>
    </visual>
  </link>
  <joint name="kinect_side_joint" type="fixed">
    <parent link="head_tilt_link"/>
    <child link="kinect_base_link"/>
<!--
    <origin rpy="0 0 0" xyz="-0.0 0.0 -0.054991"/>
-->
    <origin rpy="0 0 0" xyz="-0.0 0.0 -0.0396875"/>
  </joint>
  <link name="kinect_base_link">
    <inertial>
      <mass value="0"/>
      <origin xyz="0.0 0.0 0.0"/>
      <inertia ixx="1.0" ixy="0.0" ixz="0.0" iyy="1.0" iyz="0.0" izz="1.0"/>
    </inertial>
    <visual>
      <origin rpy="0 0 0" xyz="0.0 -0.14605 0.0"/>
      <geometry>
        <box size="0.1016 0.2921 -0.00635"/>
      </geometry>
      <material name="Green">
        <color rgba="0 0.9 0.9 1.0"/>
      </material>
    </visual>
  </link>
  <!-- KINECT STANDOFF -->
  <joint name="standoff1_kinect_joint" type="fixed">
    <origin rpy="0 0 0" xyz="0.0174625 -0.04445 0.0"/>
    <parent link="kinect_base_link"/>
    <child link="standoff1_kinect_link"/>
  </joint>
  <link name="standoff1_kinect_link">
    <inertial>
      <mass value="0.001"/>
      <origin xyz="0 0 0"/>
      <inertia ixx="0.0001" ixy="0.0" ixz="0.0" iyy="0.0001" iyz="0.0" izz="0.0001"/>
    </inertial>
    <visual>
      <origin rpy="0 0 0" xyz=" 0 0 0 "/>
      <geometry>
        <mesh filename="package://pr2lite_urdf/config/meshes/68-04556-RA_Kinect_Standoff_Assy.3ds" scale="0.001 0.001 0.001"/>
      </geometry>
    </visual>
    <collision>
      <origin rpy="0 0 0" xyz="0.0 0.0 0.0"/>
      <geometry>
        <cylinder length="0.008585" radius="0.001111"/>
      </geometry>
    </collision>
  </link>
  <joint name="standoff2_kinect_joint" type="fixed">
    <origin rpy="0 0 0" xyz="0.0174625 -0.2413 0.0"/>
    <parent link="kinect_base_link"/>
    <child link="standoff2_kinect_link"/>
  </joint>
  <link name="standoff2_kinect_link">
    <inertial>
      <mass value="0.001"/>
      <origin xyz="0 0 0"/>
      <inertia ixx="0.0001" ixy="0.0" ixz="0.0" iyy="0.0001" iyz="0.0" izz="0.0001"/>
    </inertial>
    <visual>
      <origin rpy="0 0 0" xyz=" 0 0 0 "/>
      <geometry>
        <mesh filename="package://pr2lite_urdf/config/meshes/68-04556-RA_Kinect_Standoff_Assy.3ds" scale="0.001 0.001 0.001"/>
      </geometry>
    </visual>
    <collision>
      <origin rpy="0 0 0" xyz="0.0 0.0 0.0"/>
      <geometry>
        <cylinder length="0.008585" radius="0.001111"/>
      </geometry>
    </collision>
  </link>
  <!-- KINECT SENSOR -->
  <joint name="base_kinect_joint" type="fixed">
    <!--
      <origin xyz="-0.0844382 0 0.1047496" rpy="0 0 0" />
    <origin xyz="${inch_to_meter*11/16} ${inch_to_meter*(-11.5/2)} ${0.1047496}" rpy="0 0 0"/>
-->
    <origin rpy="0 0 0" xyz="0.034925 -0.14605 0.1047496"/>
    <parent link="kinect_base_link"/>
    <child link="kinect_link"/>
  </joint>
  <link name="kinect_link">
    <inertial>
      <mass value="12"/>
      <origin xyz="0 0 0"/>
      <inertia ixx="1.0" ixy="0.0" ixz="0.0" iyy="1.0" iyz="0.0" izz="1.0"/>
    </inertial>
    <visual>
      <origin rpy="0 0 0" xyz=" 0 0 0 "/>
      <geometry>
        <mesh filename="package://pr2lite_urdf/config/meshes/68-04546_Kinect_Sensor.3ds" scale="0.001 0.001 0.001"/>
      </geometry>
    </visual>
    <collision>
      <origin rpy="0 0 0" xyz="0.0 0.0 0.0"/>
      <geometry>
        <mesh filename="package://pr2lite_urdf/config/meshes/68-04546_Kinect_Sensor.3ds"/>
      </geometry>
    </collision>
  </link>
  <joint name="kinect_depth_joint" type="fixed">
<!--

    kinect_frames.launch : -0.025 and -0.045
    current turtlebot xacro : 0.018 and -0.005
    the yujin lads xacro : 0.0125 and -0.0125

    <origin rpy="0 0 0" xyz="0 0.018 0"/>
see "https://github.com/turtlebot/turtlebot/issues/9"
-->
    <origin rpy="0 0 0" xyz="0 -0.025 0"/>
    <parent link="kinect_link"/>
    <child link="kinect_depth_frame"/>
  </joint>
  <link name="kinect_depth_frame">
    <inertial>
      <mass value="0.0001"/>
      <origin xyz="0 0 0"/>
      <inertia ixx="0.0001" ixy="0.0" ixz="0.0" iyy="0.0001" iyz="0.0" izz="0.0001"/>
    </inertial>
  </link>
  <joint name="kinect_depth_optical_joint" type="fixed">
    <origin rpy="-1.570795 0 -1.570795" xyz="0 0 0"/>
    <parent link="kinect_depth_frame"/>
    <child link="kinect_depth_optical_frame"/>
  </joint>
  <link name="kinect_depth_optical_frame">
    <inertial>
      <mass value="0.0001"/>
      <origin xyz="0 0 0"/>
      <inertia ixx="0.0001" ixy="0.0" ixz="0.0" iyy="0.0001" iyz="0.0" izz="0.0001"/>
    </inertial>
  </link>
  <joint name="kinect_rgb_joint" type="fixed">
    <origin rpy="0 0 0" xyz="0 -0.045 0"/>
<!--
    <origin rpy="0 0 0" xyz="0 -0.005 0"/>
    <origin rpy="0 0 0" xyz="0 -0.0125 0"/>
-->
    <parent link="kinect_link"/>
    <child link="kinect_rgb_frame"/>
  </joint>
  <link name="kinect_rgb_frame">
    <inertial>
      <mass value="0.0001"/>
      <origin xyz="0 0 0"/>
      <inertia ixx="0.0001" ixy="0.0" ixz="0.0" iyy="0.0001" iyz="0.0" izz="0.0001"/>
    </inertial>
  </link>
  <joint name="kinect_rgb_optical_joint" type="fixed">
    <origin rpy="-1.570795 0 -1.570795" xyz="0 0 0"/>
    <parent link="kinect_rgb_frame"/>
    <child link="kinect_rgb_optical_frame"/>
  </joint>
  <link name="kinect_rgb_optical_frame">
    <inertial>
      <mass value="0.0001"/>
      <origin xyz="0 0 0"/>
      <inertia ixx="0.0001" ixy="0.0" ixz="0.0" iyy="0.0001" iyz="0.0" izz="0.0001"/>
    </inertial>
  </link>
  <!--
standoffs from side 1.858 from front 0.775
hokuyo side bar dimensions: 2.594 jutting out 1"high
hokuyo side bar location: 1.875 + .5 (center) from bottom, 1.274 (+eight inch)  from side
hokuyo rotate .5 from front, .5 from top
hokuyo gap .368 
hokuyo body rotate 1.024 from front, 1.017 from bottom
hokuyo side bar dimensions: 
-->
  <joint name="lidar_bar_joint" type="fixed">
    <parent link="neck_link"/>
    <child link="lidar_bar_link"/>
    <origin rpy="0 0 0" xyz="0.0 0.0355092 0.060198"/>
  </joint>
  <link name="lidar_bar_link">
    <inertial>
      <mass value="0"/>
      <origin xyz="0.0 0.0 0.0"/>
      <inertia ixx="1.0" ixy="0.0" ixz="0.0" iyy="1.0" iyz="0.0" izz="1.0"/>
    </inertial>
    <visual>
      <origin rpy="0 0 0" xyz="0.0329438 0.0 0.0"/>
      <geometry>
        <box size="0.0658876 0.00635 0.0254"/>
      </geometry>
      <material name="Silver1">
        <color rgba="0 0.9 0.9 1.0"/>
      </material>
    </visual>
  </link>
  <joint name="lidar_tilt_joint" type="revolute">
    <limit effort="10" lower="-2.618" upper="2.618" velocity="3"/>
    <parent link="lidar_bar_link"/>
    <child link="lidar_tilt_link"/>
    <origin rpy="0 0 0" xyz="0.0531876 -0.00635 0.0"/>
    <axis xyz="0 -1 0"/>
  </joint>
  <link name="lidar_tilt_link">
    <inertial>
      <mass value="0"/>
      <origin xyz="0.0 0.0 0.0"/>
      <inertia ixx="1.0" ixy="0.0" ixz="0.0" iyy="1.0" iyz="0.0" izz="1.0"/>
    </inertial>
    <visual>
      <origin rpy="0 0 0" xyz="0.0 0.0 0.0"/>
      <geometry>
        <box size="0.0508 -0.00635 0.0508"/>
      </geometry>
      <material name="Green">
        <color rgba="0 0.9 0.9 1.0"/>
      </material>
    </visual>
  </link>
  <joint name="lidar_base_joint" type="fixed">
    <parent link="lidar_tilt_link"/>
    <child link="lidar_base_link"/>
    <origin rpy="0 0 0" xyz="0.0 -0.0254 -0.0254"/>
  </joint>
  <link name="lidar_base_link">
    <inertial>
      <mass value="0"/>
      <origin xyz="0.0 0.0 0.0"/>
      <inertia ixx="1.0" ixy="0.0" ixz="0.0" iyy="1.0" iyz="0.0" izz="1.0"/>
    </inertial>
    <visual>
      <origin rpy="0 0 0" xyz="0.0 0.0 0.0"/>
      <geometry>
        <box size="0.0508 0.0508 0.00635"/>
      </geometry>
      <material name="Green">
        <color rgba="0 0.9 0.9 1.0"/>
      </material>
    </visual>
  </link>
  <joint name="hokuyo_tilt_mount_joint" type="fixed">
    <!-- insert_block name="origin" /-->
    <parent link="lidar_base_link"/>
    <child link="hokuyo_tilt_mount_link"/>
  </joint>
  <link name="hokuyo_tilt_mount_link">
    <inertial>
      <mass value="0.160"/>
      <origin rpy="0 0 0" xyz="0.0 0.0 0.0"/>
      <inertia ixx="1.0" ixy="0.0" ixz="0.0" iyy="1.0" iyz="0.0" izz="1.0"/>
    </inertial>
    <visual>
      <origin rpy="1.570795 0 1.570795" xyz="0.0 0.0 0.0"/>
      <geometry>
        <mesh filename="package://hokuyo_urg_description/meshes/hokuyo_urg.stl"/>
      </geometry>
    </visual>
    <collision>
      <origin rpy="1.570795 0 1.570795" xyz="0.0 0.0 0.0"/>
      <geometry>
        <mesh filename="package://hokuyo_urg_description/meshes/collada/hokuyo_urg.dae"/>
      </geometry>
    </collision>
  </link>
  <joint name="hokuyo_tilt_joint" type="fixed">
    <origin rpy="0 0 0" xyz="0 0 0.06"/>
    <parent link="hokuyo_tilt_mount_link"/>
    <child link="hokuyo_tilt_link"/>
  </joint>
  <link name="hokuyo_tilt_link" type="laser">
    <inertial>
      <mass value="0.001"/>
      <origin rpy="0 0 0" xyz="0 0 0"/>
      <inertia ixx="0.0001" ixy="0" ixz="0" iyy="0.000001" iyz="0" izz="0.0001"/>
    </inertial>
    <visual name="laser_visual">
      <origin rpy="0 0 0" xyz="0 0 0"/>
      <geometry name="laser_visual_geom">
        <box size="0.001 0.001 0.001"/>
      </geometry>
      <material name="Red"/>
    </visual>
    <collision name="laser_collision">
      <origin rpy="0 0 0" xyz="0 0 0"/>
      <geometry name="laser_collision_geom">
        <box size=".001 .001 .001"/>
      </geometry>
    </collision>
  </link>
  <gazebo reference="hokuyo_tilt_mount_link">
    <material value="Erratic/Black"/>
  </gazebo>
  <gazebo reference="hokuyo_tilt_link">
    <material value="Erratic/Black"/>
  </gazebo>
  <gazebo reference="hokuyo_tilt_link">
    <sensor:ray name="laser">
      <rayCount>683</rayCount>
      <rangeCount>683</rangeCount>
      <laserCount>1</laserCount>
      <origin>0.0 0.0 0.0</origin>
      <displayRays>false</displayRays>
      <minAngle>-90</minAngle>
      <maxAngle> 90</maxAngle>
      <minRange>0.06</minRange>
      <maxRange>4.0</maxRange>
      <resRange>0.001</resRange>
      <updateRate>10.0</updateRate>
      <controller:gazebo_ros_laser name="gazebo_ros_hokuyo_tilt_laser_controller" plugin="libgazebo_ros_laser.so">
        <gaussianNoise>0.005</gaussianNoise>
        <alwaysOn>true</alwaysOn>
        <updateRate>10.0</updateRate>
        <topicName>hokuyo_tilt/scan</topicName>
        <frameName>hokuyo_tilt_link</frameName>
        <interface:laser name="gazebo_ros_hokuyo_tilt_laser_iface"/>
      </controller:gazebo_ros_laser>
    </sensor:ray>
  </gazebo>
  <!--
-->
  <!-- PR2LITE HEAD ends here -->
  <joint name="left_arm_shelf_joint" type="fixed">
    <parent link="top_shelf_link"/>
    <child link="left_arm_shelf_link"/>
    <origin rpy="0 0 0" xyz="-0.0 0.1778 0.434"/>
<!-- ARD
    <origin rpy="0 0 0" xyz="0.0 0.1778 0.376174"/>
-->
  </joint>
  <link name="left_arm_shelf_link">
    <inertial>
      <mass value="0"/>
      <origin xyz="0.0 0.0 0.0"/>
      <inertia ixx="1.0" ixy="0.0" ixz="0.0" iyy="1.0" iyz="0.0" izz="1.0"/>
    </inertial>
    <visual>
      <axis xyz="0 0 -1"/>
      <origin rpy="0 0 0" xyz="-0.0762 -0.05505 0.00635"/>
      <geometry>
        <box size="0.1524 0.2625 0.0127"/>
      </geometry>
      <material name="Silver1">
        <color rgba="0 0.9 0.9 1.0"/>
      </material>
    </visual>
  </link>
  <!--
-->
  <joint name="left_shoulder_pan_joint" type="revolute">
    <axis xyz="0 0 1"/>
    <parent link="left_arm_shelf_link"/>
    <child link="left_shoulder_pan_link"/>
    <origin rpy="0 3.14 3.14" xyz="-0.0635 0.0 -0.00635"/>
    <limit effort="300" lower="-2.618" upper="2.618" velocity=".1"/>
    <dynamics damping="50" friction="1"/>
  </joint>
  <joint name="right_arm_shelf_joint" type="fixed">
    <parent link="top_shelf_link"/>
    <child link="right_arm_shelf_link"/>
    <origin rpy="0 0 0" xyz="-0.0 -0.1778 0.434"/>
<!--
    <origin rpy="0 0 0" xyz="0.0 -0.1778 0.376174"/>
-->
  </joint>
  <link name="right_arm_shelf_link">
    <inertial>
      <mass value="0"/>
      <origin xyz="0.0 0.0 0.0"/>
      <inertia ixx="1.0" ixy="0.0" ixz="0.0" iyy="1.0" iyz="0.0" izz="1.0"/>
    </inertial>
    <visual>
      <axis xyz="0 0 -1"/>
      <origin rpy="0 0 0" xyz="-0.0762 0.05505 0.00635"/>
      <geometry>
<!--
      <origin rpy="0 0 0" xyz="-0.0635 0.05505 0.0"/>
        <box size="0.1524 0.1524 0.00635"/>
525 / 2 = 2625
-->
        <box size="0.1524 0.2625 0.0127"/>
      </geometry>
      <material name="Silver1">
        <color rgba="0 0.9 0.9 1.0"/>
      </material>
    </visual>
  </link>
  <!--
-->
  <joint name="right_shoulder_pan_joint" type="revolute">
    <parent link="right_arm_shelf_link"/>
    <child link="right_shoulder_pan_link"/>
    <origin rpy="0 3.14 3.14" xyz="-0.0635 0.0 -0.00635"/>
    <axis xyz="0 0 1"/>
    <limit effort="300" lower="-2.618" upper="2.618" velocity=".1"/>
    <dynamics damping="50" friction="1"/>
  </joint>
  <joint name="wheel_linear_actuator_joint" type="prismatic">
    <axis xyz="1 0 0"/>
    <limit effort="10000" lower="0.0" upper="0.1016" velocity=".05"/>
    <origin rpy="0 0 0" xyz="0.0 0.0 0.0"/>
    <parent link="base_link"/>
    <child link="wheel_linear_actuator_link"/>
  </joint>
  <link name="wheel_linear_actuator_link">
    <inertial>
      <mass value="0"/>
      <origin xyz="0.0 0.0 0.0"/>
      <inertia ixx="1.0" ixy="0.0" ixz="0.0" iyy="1.0" iyz="0.0" izz="1.0"/>
    </inertial>
    <visual>
      <axis xyz="0 1 0"/>
      <origin rpy="0 1.57 0" xyz="-0.1524 0.0 0.0"/>
      <geometry>
        <box size=".0254 .0254 0.2032"/>
      </geometry>
      <material name="Silver1">
        <color rgba="0.0 0.9 0.9 1.0"/>
      </material>
    </visual>
  </link>
  <joint name="fl_linear_actuatuor_joint" type="fixed">
    <parent link="wheel_linear_actuator_link"/>
    <child link="fl_anchor_rod_link"/>
    <origin rpy="0 0 0" xyz="0.0 0.0 0.0"/>
  </joint>
  <joint name="fr_linear_actuatuor_joint" type="fixed">
    <parent link="wheel_linear_actuator_link"/>
    <child link="fr_anchor_rod_link"/>
    <origin rpy="0 0 0" xyz="0.0 0.0 0.0"/>
  </joint>
  <joint name="bl_linear_actuatuor_joint" type="fixed">
    <parent link="wheel_linear_actuator_link"/>
    <child link="bl_anchor_rod_link"/>
    <origin rpy="0 0 0" xyz="0.0 0.0 0.0"/>
  </joint>
  <joint name="br_linear_actuatuor_joint" type="fixed">
    <parent link="wheel_linear_actuator_link"/>
    <child link="br_anchor_rod_link"/>
    <origin rpy="0 0 0" xyz="0.0 0.0 0.0"/>
  </joint>
  <joint name="fl_base_joint" type="fixed">
    <axis xyz="0 0 1"/>
    <parent link="base_link"/>
    <child link="fl_base_link"/>
    <origin rpy="0 0 0" xyz="0.1651 0.1651 -0.00635"/>
  </joint>
  <link name="fl_base_link">
    <visual>
      <origin rpy="0 0 0" xyz="0 0 0"/>
      <geometry>
        <box size=".0201 .0201 .0001"/>
      </geometry>
      <material name="Grey1">
        <color rgba="0 0.9 0.9 1.0"/>
      </material>
    </visual>
  </link>
  <link name="fl_anchor_rod_link">
    <visual>
      <axis xyz="0 0 1"/>
      <origin rpy="0 0 0" xyz="-0.0508 -0.10795 0"/>
      <geometry>
        <box size="0.01905 0.2159 0.00127"/>
      </geometry>
      <material name="Silver1">
        <color rgba="0 0.9 0.9 1.0"/>
      </material>
    </visual>
  </link>
  <joint name="fl_anchor_rod_joint" type="revolute">
    <axis xyz="0 0 1"/>
    <limit effort="10" lower="-3.1416" upper="3.1416" velocity="3"/>
    <parent link="fl_anchor_rod_link"/>
    <child link="fl_push_rod_link"/>
    <origin rpy="0 0 0" xyz="-0.0508 0.2159 0"/>
  </joint>
  <link name="fl_push_rod_link">
    <visual>
      <axis xyz="0 0 1"/>
      <origin rpy="0 0 0" xyz="-0.0889 0 0"/>
      <geometry>
        <box size="0.1778 0.01905 0.00127"/>
      </geometry>
      <material name="Silver1">
        <color rgba="0 0.9 0.9 1.0"/>
      </material>
    </visual>
  </link>
  <joint name="fl_caster_rotation_joint" type="revolute">
    <axis xyz="0 0 1"/>
    <limit effort="10" lower="-3.1416" upper="3.1416" velocity="3"/>
    <parent link="fl_base_link"/>
    <child link="fl_caster_link"/>
    <origin rpy="0 0 0" xyz="0 0 0"/>
  </joint>
  <link name="fl_caster_link">
    <visual>
      <origin rpy="0 0 0" xyz="0 0 0"/>
      <geometry>
        <box size="0.1016 0.1016 0.00635"/>
      </geometry>
      <material name="Grey1">
        <color rgba="0 0.9 0.9 1.0"/>
      </material>
    </visual>
  </link>
  <joint name="fl_caster_motor_joint" type="fixed">
    <axis xyz="0 0 1"/>
    <parent link="fl_caster_link"/>
    <child link="fl_wheel_motor_block_link"/>
    <origin rpy="0 0 0" xyz="0 0 0"/>
  </joint>
  <link name="fl_wheel_motor_block_link">
    <visual>
  <!--
      <origin rpy="0 0 0" xyz="0 0 -0.0508"/>
-->
      <origin rpy="0 0 0" xyz="0 0 -0.0762"/>
      <geometry>
        <box size="0.1016 0.0254 0.1524"/>
      </geometry>
      <material name="Blue1">
        <color rgba="0 0.9 0.9 1.0"/>
      </material>
    </visual>
  </link>
  <joint name="fl_wheel_joint" type="continuous">
    <axis xyz="0 1 0"/>
    <limit effort="100" velocity="100"/>
<!--
    <safety_controller k_velocity="10"/>
-->
    <dynamics damping="0.0" friction="0.0"/>
<!--
    <origin rpy="0 0 0" xyz="0 0.0254 -0.0889"/>
-->
    <origin rpy="0 0 0" xyz="0 0.0254 -0.1397"/>
    <parent link="fl_wheel_motor_block_link"/>
    <child link="fl_wheel_link"/>
  </joint>
  <link name="fl_wheel_link">
    <inertial>
      <mass value="0.1"/>
      <origin xyz=" 0 0 0 "/>
      <inertia ixx="0.012411765597" ixy="0.0" ixz="0.0" iyy="0.015218160428" iyz="0.0" izz="0.011763977943"/>
    </inertial>
    <visual>
      <origin rpy="0 1.570795 1.570795" xyz="0 0.00635 0"/>
      <geometry>
        <cylinder length="0.0127" radius="0.0762"/>
      </geometry>
      <material name="Grey"/>
    </visual>
    <collision>
      <origin rpy="0 1.570795 1.570795" xyz="0 0 0"/>
      <geometry>
        <cylinder length="0.0127" radius="0.0762"/>
      </geometry>
    </collision>
    <gazebo reference="base_link_fl_wheel_link">
      <mu1 value="100.0"/>
      <mu2 value="100.0"/>
      <kp value="1000000.0"/>
      <kd value="1.0"/>
      <material>Erratic/Grey</material>
    </gazebo>
    <gazebo reference="base_link_fl_motor_link">
      <material>Erratic/White</material>
    </gazebo>
    <transmission name="base_link_fl_wheel_trans" type="pr2_mechanism_model/SimpleTransmission">
      <actuator name="base_link_fl_wheel_motor"/>
      <joint name="base_link_fl_wheel_joint"/>
      <mechanicalReduction>1.0</mechanicalReduction>
    </transmission>
  </link>
  <joint name="fr_base_joint" type="fixed">
    <axis xyz="0 0 1"/>
    <parent link="base_link"/>
    <child link="fr_base_link"/>
    <origin rpy="0 0 0" xyz="0.1651 -0.1651 -0.00635"/>
  </joint>
  <link name="fr_base_link">
    <visual>
      <origin rpy="0 0 0" xyz="0 0 0"/>
      <geometry>
        <box size=".0201 .0201 .0001"/>
      </geometry>
      <material name="Grey1">
        <color rgba="0 0.9 0.9 1.0"/>
      </material>
    </visual>
  </link>
  <link name="fr_anchor_rod_link">
    <visual>
      <axis xyz="0 0 1"/>
      <origin rpy="0 0 0" xyz="-0.0508 0.05715 0"/>
      <geometry>
        <box size="0.01905 0.1143 0.00127"/>
      </geometry>
      <material name="Silver1">
        <color rgba="0 0.9 0.9 1.0"/>
      </material>
    </visual>
  </link>
  <joint name="fr_anchor_rod_joint" type="revolute">
    <axis xyz="0 0 1"/>
    <limit effort="10" lower="-3.1416" upper="3.1416" velocity="3"/>
    <parent link="fr_anchor_rod_link"/>
    <child link="fr_push_rod_link"/>
    <origin rpy="0 0 0" xyz="-0.0508 -0.2159 0"/>
  </joint>
  <link name="fr_push_rod_link">
    <visual>
      <axis xyz="0 0 1"/>
      <origin rpy="0 0 0" xyz="-0.0889 0 0"/>
      <geometry>
        <box size="0.1778 0.01905 0.00127"/>
      </geometry>
      <material name="Silver1">
        <color rgba="0 0.9 0.9 1.0"/>
      </material>
    </visual>
  </link>
  <joint name="fr_caster_rotation_joint" type="revolute">
    <axis xyz="0 0 1"/>
    <limit effort="10" lower="-3.1416" upper="3.1416" velocity="3"/>
    <parent link="fr_base_link"/>
    <child link="fr_caster_link"/>
    <origin rpy="0 0 0" xyz="0 0 0"/>
  </joint>
  <link name="fr_caster_link">
    <visual>
      <origin rpy="0 0 0" xyz="0 0 0"/>
      <geometry>
        <box size="0.1016 0.1016 0.00635"/>
      </geometry>
      <material name="Grey1">
        <color rgba="0 0.9 0.9 1.0"/>
      </material>
    </visual>
  </link>
  <joint name="fr_caster_motor_joint" type="fixed">
    <axis xyz="0 0 1"/>
    <parent link="fr_caster_link"/>
    <child link="fr_wheel_motor_block_link"/>
    <origin rpy="0 0 0" xyz="0 0 0"/>
  </joint>
  <link name="fr_wheel_motor_block_link">
    <visual>
<!--
      <origin rpy="0 0 0" xyz="0 0 -0.0508"/>
-->
      <origin rpy="0 0 0" xyz="0 0 -0.0762"/>
      <geometry>
<!--
        <box size="0.1016 0.0254 0.1016"/>
-->
        <box size="0.1016 0.0254 0.1524"/>
      </geometry>
      <material name="Blue1">
        <color rgba="0 0.9 0.9 1.0"/>
      </material>
    </visual>
  </link>
  <joint name="fr_wheel_joint" type="continuous">
    <axis xyz="0 1 0"/>
    <limit effort="100" velocity="100"/>
<!--
    <safety_controller k_velocity="10"/>
-->
    <dynamics damping="0.0" friction="0.0"/>
<!--
    <origin rpy="0 0 0" xyz="0 -0.0254 -0.0889"/>
-->
    <origin rpy="0 0 0" xyz="0 -0.0254 -0.1397"/>
    <parent link="fr_wheel_motor_block_link"/>
    <child link="fr_wheel_link"/>
  </joint>
  <link name="fr_wheel_link">
    <inertial>
      <mass value="0.1"/>
      <origin xyz=" 0 0 0 "/>
      <inertia ixx="0.012411765597" ixy="0.0" ixz="0.0" iyy="0.015218160428" iyz="0.0" izz="0.011763977943"/>
    </inertial>
    <visual>
      <origin rpy="0 1.570795 1.570795" xyz="0 -0.00635 0"/>
      <geometry>
        <cylinder length="0.0127" radius="0.0762"/>
      </geometry>
      <material name="Grey"/>
    </visual>
    <collision>
      <origin rpy="0 1.570795 1.570795" xyz="0 0 0"/>
      <geometry>
        <cylinder length="0.0127" radius="0.0762"/>
      </geometry>
    </collision>
    <gazebo reference="base_link_fr_wheel_link">
      <mu1 value="100.0"/>
      <mu2 value="100.0"/>
      <kp value="1000000.0"/>
      <kd value="1.0"/>
      <material>Erratic/Grey</material>
    </gazebo>
    <gazebo reference="base_link_fr_motor_link">
      <material>Erratic/White</material>
    </gazebo>
    <transmission name="base_link_fr_wheel_trans" type="pr2_mechanism_model/SimpleTransmission">
      <actuator name="base_link_fr_wheel_motor"/>
      <joint name="base_link_fr_wheel_joint"/>
      <mechanicalReduction>1.0</mechanicalReduction>
    </transmission>
  </link>
  <joint name="bl_base_joint" type="fixed">
    <axis xyz="0 0 1"/>
    <parent link="base_link"/>
    <child link="bl_base_link"/>
    <origin rpy="0 0 0" xyz="-0.1651 0.1651 -0.00635"/>
  </joint>
  <link name="bl_base_link">
    <visual>
      <origin rpy="0 0 0" xyz="0 0 0"/>
      <geometry>
        <box size=".0201 .0201 .0001"/>
      </geometry>
      <material name="Grey1">
        <color rgba="0 0.9 0.9 1.0"/>
      </material>
    </visual>
  </link>
  <link name="bl_anchor_rod_link">
    <visual>
      <axis xyz="0 0 1"/>
      <origin rpy="0 0 0" xyz="-0.0508 -0.05715 0"/>
      <geometry>
        <box size="0.01905 0.1143 0.00127"/>
      </geometry>
      <material name="Silver1">
        <color rgba="0 0.9 0.9 1.0"/>
      </material>
    </visual>
  </link>
  <joint name="bl_anchor_rod_joint" type="revolute">
    <axis xyz="0 0 1"/>
    <limit effort="10" lower="-3.1416" upper="3.1416" velocity="3"/>
    <parent link="bl_anchor_rod_link"/>
    <child link="bl_push_rod_link"/>
    <origin rpy="0 0 0" xyz="-0.0508 0.1143 0"/>
  </joint>
  <link name="bl_push_rod_link">
    <visual>
      <axis xyz="0 0 1"/>
      <origin rpy="0 0 0" xyz="0.0889 0 0"/>
      <geometry>
        <box size="0.1778 0.01905 0.00127"/>
      </geometry>
      <material name="Silver1">
        <color rgba="0 0.9 0.9 1.0"/>
      </material>
    </visual>
  </link>
  <joint name="bl_caster_rotation_joint" type="revolute">
    <axis xyz="0 0 1"/>
    <limit effort="10" lower="-3.1416" upper="3.1416" velocity="3"/>
    <parent link="bl_base_link"/>
    <child link="bl_caster_link"/>
    <origin rpy="0 0 0" xyz="0 0 0"/>
  </joint>
  <link name="bl_caster_link">
    <visual>
      <origin rpy="0 0 0" xyz="0 0 0"/>
      <geometry>
        <box size="0.1016 0.1016 0.00635"/>
      </geometry>
      <material name="Grey1">
        <color rgba="0 0.9 0.9 1.0"/>
      </material>
    </visual>
  </link>
  <joint name="bl_caster_motor_joint" type="fixed">
    <axis xyz="0 0 1"/>
    <parent link="bl_caster_link"/>
    <child link="bl_wheel_motor_block_link"/>
    <origin rpy="0 0 0" xyz="0 0 0"/>
  </joint>
  <link name="bl_wheel_motor_block_link">
    <visual>
<!--
      <origin rpy="0 0 0" xyz="0 0 -0.0508"/>
-->
      <origin rpy="0 0 0" xyz="0 0 -0.0762"/>
      <geometry>
<!--
        <box size="0.1016 0.0254 0.1016"/>
-->
        <box size="0.1016 0.0254 0.1524"/>
      </geometry>
      <material name="Blue1">
        <color rgba="0 0.9 0.9 1.0"/>
      </material>
    </visual>
  </link>
  <joint name="bl_wheel_joint" type="continuous">
    <axis xyz="0 1 0"/>
    <limit effort="100" velocity="100"/>
<!--
    <safety_controller k_velocity="10"/>
-->
    <dynamics damping="0.0" friction="0.0"/>
<!--
    <origin rpy="0 0 0" xyz="0 0.0254 -0.0889"/>
-->
    <origin rpy="0 0 0" xyz="0 0.0254 -0.1397"/>
    <parent link="bl_wheel_motor_block_link"/>
    <child link="bl_wheel_link"/>
  </joint>
  <link name="bl_wheel_link">
    <inertial>
      <mass value="0.1"/>
      <origin xyz=" 0 0 0 "/>
      <inertia ixx="0.012411765597" ixy="0.0" ixz="0.0" iyy="0.015218160428" iyz="0.0" izz="0.011763977943"/>
    </inertial>
    <visual>
      <origin rpy="0 1.570795 1.570795" xyz="0 0.00635 0"/>
      <geometry>
        <cylinder length="0.0127" radius="0.0762"/>
      </geometry>
      <material name="Grey"/>
    </visual>
    <collision>
      <origin rpy="0 1.570795 1.570795" xyz="0 0 0"/>
      <geometry>
        <cylinder length="0.0127" radius="0.0762"/>
      </geometry>
    </collision>
    <gazebo reference="base_link_bl_wheel_link">
      <mu1 value="100.0"/>
      <mu2 value="100.0"/>
      <kp value="1000000.0"/>
      <kd value="1.0"/>
      <material>Erratic/Grey</material>
    </gazebo>
    <gazebo reference="base_link_bl_motor_link">
      <material>Erratic/White</material>
    </gazebo>
    <transmission name="base_link_bl_wheel_trans" type="pr2_mechanism_model/SimpleTransmission">
      <actuator name="base_link_bl_wheel_motor"/>
      <joint name="base_link_bl_wheel_joint"/>
      <mechanicalReduction>1.0</mechanicalReduction>
    </transmission>
  </link>
  <joint name="br_base_joint" type="fixed">
    <axis xyz="0 0 1"/>
    <parent link="base_link"/>
    <child link="br_base_link"/>
    <origin rpy="0 0 0" xyz="-0.1651 -0.1651 -0.00635"/>
  </joint>
  <link name="br_base_link">
    <visual>
      <origin rpy="0 0 0" xyz="0 0 0"/>
      <geometry>
        <box size=".0201 .0201 .0001"/>
      </geometry>
      <material name="Grey1">
        <color rgba="0 0.9 0.9 1.0"/>
      </material>
    </visual>
  </link>
  <link name="br_anchor_rod_link">
    <visual>
      <axis xyz="0 0 1"/>
      <origin rpy="0 0 0" xyz="-0.0508 0.10795 0"/>
      <geometry>
        <box size="0.01905 0.2159 0.00127"/>
      </geometry>
      <material name="Silver1">
        <color rgba="0 0.9 0.9 1.0"/>
      </material>
    </visual>
  </link>
  <joint name="br_anchor_rod_joint" type="revolute">
    <axis xyz="0 0 1"/>
    <limit effort="10" lower="-3.1416" upper="3.1416" velocity="3"/>
    <parent link="br_anchor_rod_link"/>
    <child link="br_push_rod_link"/>
    <origin rpy="0 0 0" xyz="-0.0508 -0.1143 0"/>
  </joint>
  <link name="br_push_rod_link">
    <visual>
      <axis xyz="0 0 1"/>
      <origin rpy="0 0 0" xyz="0.0889 0 0"/>
      <geometry>
        <box size="0.1778 0.01905 0.00127"/>
      </geometry>
      <material name="Silver1">
        <color rgba="0 0.9 0.9 1.0"/>
      </material>
    </visual>
  </link>
  <joint name="br_caster_rotation_joint" type="revolute">
    <axis xyz="0 0 1"/>
    <limit effort="10" lower="-3.1416" upper="3.1416" velocity="3"/>
    <parent link="br_base_link"/>
    <child link="br_caster_link"/>
    <origin rpy="0 0 0" xyz="0 0 0"/>
  </joint>
  <link name="br_caster_link">
    <visual>
      <origin rpy="0 0 0" xyz="0 0 0"/>
      <geometry>
        <box size="0.1016 0.1016 0.00635"/>
      </geometry>
      <material name="Grey1">
        <color rgba="0 0.9 0.9 1.0"/>
      </material>
    </visual>
  </link>
  <joint name="br_caster_motor_joint" type="fixed">
    <axis xyz="0 0 1"/>
    <parent link="br_caster_link"/>
    <child link="br_wheel_motor_block_link"/>
    <origin rpy="0 0 0" xyz="0 0 0"/>
  </joint>
  <link name="br_wheel_motor_block_link">
    <visual>
<!--
      <origin rpy="0 0 0" xyz="0 0 -0.0508"/>
-->
      <origin rpy="0 0 0" xyz="0 0 -0.0762"/>
      <geometry>
<!--
        <box size="0.1016 0.0254 0.1016"/>
-->
        <box size="0.1016 0.0254 0.1524"/>
      </geometry>
      <material name="Blue1">
        <color rgba="0 0.9 0.9 1.0"/>
      </material>
    </visual>
  </link>
  <joint name="br_wheel_joint" type="continuous">
    <axis xyz="0 1 0"/>
    <limit effort="100" velocity="100"/>
<!--
    <safety_controller k_velocity="10"/>
-->
    <dynamics damping="0.0" friction="0.0"/>
<!--
    <origin rpy="0 0 0" xyz="0 -0.0254 -0.0889"/>
-->
    <origin rpy="0 0 0" xyz="0 -0.0254 -0.1397"/>
    <parent link="br_wheel_motor_block_link"/>
    <child link="br_wheel_link"/>
  </joint>
  <link name="br_wheel_link">
    <inertial>
      <mass value="0.1"/>
      <origin xyz=" 0 0 0 "/>
      <inertia ixx="0.012411765597" ixy="0.0" ixz="0.0" iyy="0.015218160428" iyz="0.0" izz="0.011763977943"/>
    </inertial>
    <visual>
      <origin rpy="0 1.570795 1.570795" xyz="0 -0.00635 0"/>
      <geometry>
        <cylinder length="0.0127" radius="0.0762"/>
      </geometry>
      <material name="Grey"/>
    </visual>
    <collision>
      <origin rpy="0 1.570795 1.570795" xyz="0 0 0"/>
      <geometry>
        <cylinder length="0.0127" radius="0.0762"/>
      </geometry>
    </collision>
    <gazebo reference="base_link_br_wheel_link">
      <mu1 value="100.0"/>
      <mu2 value="100.0"/>
      <kp value="1000000.0"/>
      <kd value="1.0"/>
      <material>Erratic/Grey</material>
    </gazebo>
    <gazebo reference="base_link_br_motor_link">
      <material>Erratic/White</material>
    </gazebo>
    <transmission name="base_link_br_wheel_trans" type="pr2_mechanism_model/SimpleTransmission">
      <actuator name="base_link_br_wheel_motor"/>
      <joint name="base_link_br_wheel_joint"/>
      <mechanicalReduction>1.0</mechanicalReduction>
    </transmission>
  </link>
  <xacro:pr2lite_torso>
</xacro:pr2lite_torso>
  <!--
-->
  <joint name="left_shoulder_caster_joint" type="fixed">
    <axis xyz="0 0 0"/>
    <parent link="left_shoulder_pan_link"/>
    <child link="left_shoulder_caster_link"/>
    <origin rpy="0 0 0" xyz="-0.0508 0.0 0.1868805"/>
  </joint>
  <joint name="left_lin_act_cyl_joint" type="revolute">
    <!-- shoulder pan cylindar to lin act joint -->
    <origin rpy="0 0 0" xyz="0.0381 0.0 0.1868805"/>
    <!--
          <origin xyz="${inch_to_meter*(.5)} ${inch_to_meter*0} ${inch_to_meter*7.3575}" rpy="0 0 0"/>
-->
    <parent link="left_shoulder_caster_link"/>
    <child link="left_lower_linear_actuator_link"/>
    <axis xyz="0 -1 0"/>
    <limit effort="300" lower="-2.618" upper="2.618" velocity="1.17"/>
    <!-- mimic joint="${side}_shoulder_tilt_joint" multiplier="-1" offset="0" -->
  </joint>
  <joint name="left_linear_actuator_joint" type="prismatic">
    <!-- linact down: 9.9 inches, up 13.9 inches -->
    <axis xyz="0 0 -1"/>
    <limit effort="10000" lower="0.0" upper="-0.1016" velocity=".025"/>
    <origin rpy="0 0 0" xyz="0.0 0.0 0.0"/>
    <parent link="left_lower_linear_actuator_link"/>
    <child link="left_upper_linear_actuator_link"/>
  </joint>
  <joint name="left_shoulder_tilt_joint" type="revolute">
<!--
    <origin rpy="0 0 0" xyz="0.0508 0 0.0"/>
-->
    <origin rpy="0 0 0" xyz="0.057 0 0.0"/>
    <parent link="left_shoulder_pan_link"/>
    <child link="left_upper_arm_link"/>
    <axis xyz="0 -1 0"/>
    <limit effort="300" lower="0.268" upper="1.213" velocity=".23"/>
<!--
    <safety_controller k_position="100" k_velocity="15.0" soft_lower_limit="-0.94719755" soft_upper_limit="1.872222"/>
-->
    <dynamics damping="50" friction="1"/>
  </joint>
<!-- ==========ARD CUT HERE ========== -->
<!--
 <joint name="left_arm_top_bar_joint" type="fixed">
    <origin rpy="0 0 0" xyz="0.0 0 0.003175"/>
    <parent link="left_upper_arm_link"/>
    <child link="left_upper_arm_top_bar_link"/>
    <axis xyz="0 -1 0"/>
  </joint>
  <link name="left_upper_arm_top_bar_link">
    <inertial>
      <mass value="0.405"/>
      <origin rpy="0 0 0" xyz="0.02988871 0 0.02056699"/>
      <inertia ixx="1.0" ixy="0.0" ixz="0.0" iyy="1.0" iyz="0.0" izz="1.0"/>
    </inertial>
    <visual>
      <origin rpy="0 0 0" xyz="0.1778 0.0 -.0254"/>
      <geometry>
        <box size="0.2794 0.0508 0.0508"/>
      </geometry>
      <material name="Silver1">
        <color rgba="0 0.9 0.9 1.0"/>
      </material>
    </visual>
  </link>
-->

  <joint name="left_upper_arm_hinge_joint" type="revolute">
<!-- ARD
    <origin rpy="0.0 0 0.0" xyz="0.3556 0.0 0.00635"/>
-->
    <origin rpy="0.0 0 0.0" xyz="0.41 0.0 0.00635"/>
    <parent link="left_upper_arm_link"/>
    <child link="left_elbow_pan_link"/>
    <axis xyz="0 -1 0"/>
    <limit effort="300" lower="-1.213" upper="-0.268" velocity=".23"/>
    <mimic joint="left_shoulder_tilt_joint" multiplier="-1" offset="0"/>
  </joint>
  <joint name="left_elbow_pan_joint" type="revolute">
    <origin rpy="0 0 0" xyz="-0.0508 0 0.0127"/>
    <parent link="left_elbow_pan_link"/>
    <child link="left_elbow_flex_link"/>
    <axis xyz="0 0 1"/>
    <limit effort="300" lower="-2.618" upper="2.618" velocity=".1"/>
  </joint>
  <joint name="left_elbow_flex_joint" type="revolute">
    <origin rpy="0 0 0" xyz="0.0762 0.0 0.0254"/>
    <parent link="left_elbow_flex_link"/>
    <child link="left_forearm_link"/>
    <axis xyz="0 -1 0"/>
    <limit effort="300" lower="-2.618" upper="2.618" velocity=".1"/>
  </joint>
  <joint name="left_wrist_flex_joint" type="revolute">
<!-- ARD
    <origin rpy="0 0 0" xyz="0.1778 0 0"/>
-->
    <origin rpy="0 0 0" xyz="0.18 0 0"/>
    <parent link="left_forearm_link"/>
    <child link="left_wrist_flex_link"/>
    <axis xyz="0 1 0"/>
    <limit effort="300" lower="-2.618" upper="2.618" velocity=".1"/>
  </joint>
  <joint name="left_wrist_roll_joint" type="revolute">
    <origin rpy="0 0 0" xyz="0.07 0 0.023"/>
    <parent link="left_wrist_flex_link"/>
    <child link="left_wrist_roll_link"/>
    <axis xyz="-1 0 0"/>
    <limit effort="300" lower="-2.618" upper="2.618" velocity=".1"/>
  </joint>
  <joint name="left_gripper_right_joint" type="revolute">
    <origin rpy="0 0 0" xyz="0.0415 -0.0175 0"/>
    <parent link="left_wrist_roll_link"/>
    <child link="left_gripper_right_link"/>
    <axis xyz="0 0 -1"/>
    <limit effort="300" lower="-2.618" upper="2.618" velocity=".1"/>
  </joint>
  <joint name="left_gripper_left_joint" type="revolute">
    <origin rpy="0 0 0" xyz="0.0415 0.0175 0"/>
    <parent link="left_wrist_roll_link"/>
    <child link="left_gripper_left_link"/>
    <axis xyz="0 0 -1"/>
    <limit effort="300" lower="-2.618" upper="2.618" velocity=".1"/>
  </joint>
  <link name="left_elbow_pan_link">
    <inertial>
      <mass value="0.405"/>
      <origin rpy="0 0 0" xyz="0.02988871 0 0.02056699"/>
      <inertia ixx="1.0" ixy="0.0" ixz="0.0" iyy="1.0" iyz="0.0" izz="1.0"/>
    </inertial>
    <visual>
      <origin rpy="0 0 0" xyz="-0.0508 -0.0 0.003175"/>
      <geometry>
        <box size="0.1016 0.1016 0.00635"/>
      </geometry>
      <material name="Green">
        <color rgba="0 0.9 0.9 1.0"/>
      </material>
    </visual>
  </link>
  <link name="left_elbow_flex_link">
    <inertial>
      <mass value="0.405"/>
      <origin rpy="0 0 0" xyz="0.0 0 0.0"/>
      <inertia ixx="1.0" ixy="0.0" ixz="0.0" iyy="1.0" iyz="0.0" izz="1.0"/>
    </inertial>
    <visual>
      <origin rpy="0 0 0" xyz="0.0 0.0 0.0"/>
      <geometry>
        <box size="0.1016 0.1016 0.00635"/>
      </geometry>
      <material name="Green">
        <color rgba="0 0.9 0.9 1.0"/>
      </material>
    </visual>
  </link>
  <link name="left_forearm_link">
    <inertial>
      <mass value="0.405"/>
      <origin rpy="0 0 0" xyz="0.02988871 0 0.02056699"/>
      <inertia ixx="1.0" ixy="0.0" ixz="0.0" iyy="1.0" iyz="0.0" izz="1.0"/>
    </inertial>
    <visual>
      <origin rpy="0 0 0" xyz="0.0889 0.0 0.0"/>
      <geometry>
        <!-- 2", 1", 7" -->
        <box size="0.1524  0.1016 0.0254"/>
      </geometry>
      <material name="Silver1">
        <color rgba="0 0.9 0.9 1.0"/>
      </material>
    </visual>
  </link>
  <link name="left_wrist_flex_link">
    <inertial>
      <mass value="0.12"/>
      <origin rpy="0 0 0" xyz="0.04463361 0 0.00720194"/>
      <inertia ixx="1.0" ixy="0.0" ixz="0.0" iyy="1.0" iyz="0.0" izz="1.0"/>
    </inertial>
    <visual>
      <origin rpy="0 0 0" xyz="0.0 0.0 0.0"/>
      <geometry>
        <mesh filename="package://pr2lite_urdf/config/meshes/arm_elbow_tilt.stl"/>
      </geometry>
      <material name="Green">
        <color rgba="0 0.9 0.9 1.0"/>
      </material>
    </visual>
   </link>
  <link name="left_wrist_roll_link">
    <inertial>
      <mass value="0.13"/>
      <origin rpy="0 0 0" xyz="0.02539960 0 0"/>
      <inertia ixx="1.0" ixy="0.0" ixz="0.0" iyy="1.0" iyz="0.0" izz="1.0"/>
    </inertial>
    <visual>
      <origin rpy="0 0 0" xyz="0.0 0.0 0.0"/>
      <geometry>
        <mesh filename="package://pr2lite_urdf/config/meshes/arm_wrist_rotate.stl"/>
      </geometry>
      <material name="Green">
        <color rgba="0 0.9 0.9 1.0"/>
      </material>
    </visual>
  </link>
  <link name="left_gripper_right_link">
    <inertial>
      <mass value="0.0225"/>
      <origin rpy="0 0 0" xyz="0.03058625 -0.01804371 -0.00941599"/>
      <inertia ixx="1.0" ixy="0.0" ixz="0.0" iyy="1.0" iyz="0.0" izz="1.0"/>
    </inertial>
    <visual>
      <origin rpy="0 0 0" xyz="0.0 0.0 0.0"/>
      <geometry>
        <mesh filename="package://pr2lite_urdf/config/meshes/arm_right_finger.stl"/>
      </geometry>
      <material name="Silver1">
        <color rgba="0 0.9 0.9 1.0"/>
      </material>
    </visual>
   </link>
  <link name="left_gripper_left_link">
    <inertial>
      <mass value="0.0225"/>
      <origin rpy="0 0 0" xyz="0.03058625 0.01804371 -0.00941599"/>
      <inertia ixx="1.0" ixy="0.0" ixz="0.0" iyy="1.0" iyz="0.0" izz="1.0"/>
    </inertial>
    <visual>
      <origin rpy="0 0 0" xyz="0.0 0.0 0.0"/>
      <geometry>
        <mesh filename="package://pr2lite_urdf/config/meshes/arm_left_finger.stl"/>
      </geometry>
      <material name="Silver1">
        <color rgba="0 0.9 0.9 1.0"/>
      </material>
    </visual>
  </link>
<!-- ==========ARD CUT HERE ========== -->
  <link name="left_shoulder_pan_link">
    <inertial>
      <mass value="0.405"/>
      <origin rpy="0 0 0" xyz="0.02988871 0 0.02056699"/>
      <inertia ixx="1.0" ixy="0.0" ixz="0.0" iyy="1.0" iyz="0.0" izz="1.0"/>
    </inertial>
    <visual>
      <origin rpy="0 0 0" xyz="0.0 0.0 0.0"/>
      <geometry>
        <box size="0.1016 0.1016 0.00635"/>
      </geometry>
      <material name="Silver1">
        <color rgba="0 0.9 0.9 1.0"/>
      </material>
    </visual>
  </link>
  <link name="left_shoulder_caster_link">
    <!-- 14.715 inches from linact to caster -->
    <visual>
      <origin rpy="0 0 0" xyz="0 0 0"/>
      <geometry>
        <box size="0.00635 0.1016 -0.373761"/>
      </geometry>
      <material name="Green">
        <color rgba="0 0.9 0.9 1.0"/>
      </material>
    </visual>
  </link>
  <link name="left_lower_linear_actuator_link">
    <visual>
      <axis xyz="0 0 0"/>
      <origin rpy="0 0 0" xyz="0.0 0.0 -0.12573"/>
      <geometry>
        <box size="0.03556 0.03048 -0.25146"/>
      </geometry>
      <material name="Silver1">
        <color rgba="0 0.9 0.9 1.0"/>
      </material>
    </visual>
  </link>
  <link name="left_upper_linear_actuator_link">
    <!-- (4.3 - .315) inches where lin act attaches to arm -->
    <visual>
      <!-- origin xyz="${inch_to_meter*0} ${inch_to_meter*0} ${inch_to_meter*0}" rpy="0 0 0"-->
      <!-- geometry><box size="${inch_to_meter*0} ${inch_to_meter*0} ${inch_to_meter*0}"/></geometry -->
      <origin rpy="0 0 0" xyz="0.0 0.0 -0.15113"/>
      <geometry>
        <box size="0.02032 0.02032 -0.25146"/>
      </geometry>
      <material name="Green">
        <color rgba="0 0.9 0.9 1.0"/>
      </material>
    </visual>
  </link>
  <link name="left_upper_arm_link">
    <visual>
      <origin rpy="0 0 0" xyz="0.205 0.0 0.0"/>
      <geometry>
<!-- ARD
        <origin rpy="0 0 0" xyz="0.1778 0.0 0.0"/>
        <box size="0.3556 0.1016 0.00635"/>
-->
        <box size="0.41 0.1016 0.00635"/>
      </geometry>
      <material name="Silver1">
        <color rgba="0 0.9 0.9 1.0"/>
      </material>
    </visual>
  </link>
  <transmission name="left_shoulder_pan_trans" type="pr2_mechanism_model/SimpleTransmission">
    <actuator name="left_shoulder_pan_motor"/>
    <joint name="left_shoulder_pan_joint"/>
    <mechanicalReduction>1.0</mechanicalReduction>
  </transmission>
  <transmission name="left_elbow_flex_trans" type="pr2_mechanism_model/SimpleTransmission">
    <actuator name="left_elbow_flex_motor"/>
    <joint name="left_elbow_flex_joint"/>
    <mechanicalReduction>1.0</mechanicalReduction>
  </transmission>
  <transmission name="left_wrist_flex_trans" type="pr2_mechanism_model/SimpleTransmission">
    <actuator name="left_wrist_flex_motor"/>
    <joint name="left_wrist_flex_joint"/>
    <mechanicalReduction>1.0</mechanicalReduction>
  </transmission>
  <transmission name="left_wrist_roll_trans" type="pr2_mechanism_model/SimpleTransmission">
    <actuator name="left_wrist_roll_motor"/>
    <joint name="left_wrist_roll_joint"/>
    <mechanicalReduction>1.0</mechanicalReduction>
  </transmission>
  <transmission name="left_gripper_right_trans" type="pr2_mechanism_model/SimpleTransmission">
    <actuator name="left_gripper_right_motor"/>
    <joint name="left_gripper_right_joint"/>
    <mechanicalReduction>1.0</mechanicalReduction>
  </transmission>
  <transmission name="left_gripper_left_trans" type="pr2_mechanism_model/SimpleTransmission">
    <actuator name="left_gripper_left_motor"/>
    <joint name="left_gripper_left_joint"/>
    <mechanicalReduction>1.0</mechanicalReduction>
  </transmission>
  <gazebo reference="left_arm_base_link">
    <material>SmartArm/GunMetalBrushedAluminum</material>
    <turnGravityOff>true</turnGravityOff>
  </gazebo>
  <gazebo reference="left_arm_shoulder_pan_link">
    <material>SmartArm/GunMetalBrushedAluminum</material>
    <turnGravityOff>true</turnGravityOff>
  </gazebo>
  <gazebo reference="left_elbow_flex_link">
    <material>SmartArm/GunMetalBrushedAluminum</material>
    <turnGravityOff>true</turnGravityOff>
  </gazebo>
  <gazebo reference="left_wrist_flex_link">
    <material>SmartArm/GunMetalBrushedAluminum</material>
    <turnGravityOff>true</turnGravityOff>
  </gazebo>
  <gazebo reference="left_wrist_roll_link">
    <material>SmartArm/GunMetalBrushedAluminum</material>
    <turnGravityOff>true</turnGravityOff>
  </gazebo>
  <gazebo reference="left_gripper_right_link">
    <material>SmartArm/GunMetalBrushedAluminum</material>
    <turnGravityOff>true</turnGravityOff>
    <mu1 value="500.0"/>
    <mu2 value="500.0"/>
    <kp value="1000000.0"/>
    <kd value="1.0"/>
  </gazebo>
  <gazebo reference="left_gripper_left_link">
    <material>SmartArm/GunMetalBrushedAluminum</material>
    <turnGravityOff>true</turnGravityOff>
    <mu1 value="500.0"/>
    <mu2 value="500.0"/>
    <kp value="1000000.0"/>
    <kd value="1.0"/>
  </gazebo>
  <gazebo reference="left_shoulder_pan_joint">
    <stopKd value="1.0"/>
    <stopKp value="1000000.0"/>
    <fudgeFactor value="0.5"/>
  </gazebo>
  <gazebo reference="left_elbow_flex_joint">
    <stopKd value="1.0"/>
    <stopKp value="1000000.0"/>
    <fudgeFactor value="0.5"/>
  </gazebo>
  <gazebo reference="left_wrist_flex_joint">
    <stopKd value="1.0"/>
    <stopKp value="1000000.0"/>
    <fudgeFactor value="0.5"/>
  </gazebo>
  <gazebo reference="left_wrist_roll_joint">
    <stopKd value="1.0"/>
    <stopKp value="1000000.0"/>
    <fudgeFactor value="0.5"/>
  </gazebo>
  <gazebo reference="left_gripper_right_joint">
    <stopKd value="1.0"/>
    <stopKp value="1000000.0"/>
    <fudgeFactor value="1.0"/>
  </gazebo>
  <gazebo reference="left_gripper_left_joint">
    <stopKd value="1.0"/>
    <stopKp value="1000000.0"/>
    <fudgeFactor value="1.0"/>
  </gazebo>
  <joint name="right_shoulder_caster_joint" type="fixed">
    <axis xyz="0 0 0"/>
    <parent link="right_shoulder_pan_link"/>
    <child link="right_shoulder_caster_link"/>
    <origin rpy="0 0 0" xyz="-0.0508 0.0 0.1868805"/>
  </joint>
  <joint name="right_lin_act_cyl_joint" type="revolute">
    <!-- shoulder pan cylindar to lin act joint -->
    <origin rpy="0 0 0" xyz="0.0381 0.0 0.1868805"/>
    <!--
          <origin xyz="${inch_to_meter*(.5)} ${inch_to_meter*0} ${inch_to_meter*7.3575}" rpy="0 0 0"/>
-->
    <parent link="right_shoulder_caster_link"/>
    <child link="right_lower_linear_actuator_link"/>
    <axis xyz="0 -1 0"/>
    <limit effort="300" lower="-2.618" upper="2.618" velocity=".1"/>
    <!-- mimic joint="${side}_shoulder_tilt_joint" multiplier="-1" offset="0" -->
  </joint>
  <link name="right_upper_linear_actuator_link">
    <!-- (4.3 - .315) inches where lin act attaches to arm -->
    <visual>
      <!-- origin xyz="${inch_to_meter*0} ${inch_to_meter*0} ${inch_to_meter*0}" rpy="0 0 0"-->
      <!-- geometry><box size="${inch_to_meter*0} ${inch_to_meter*0} ${inch_to_meter*0}"/></geometry -->
      <origin rpy="0 0 0" xyz="0.0 0.0 -0.15113"/>
      <geometry>
        <box size="0.02032 0.02032 -0.25146"/>
      </geometry>
      <material name="Green">
        <color rgba="0 0.9 0.9 1.0"/>
      </material>
    </visual>
  </link>

  <joint name="right_linear_actuator_joint" type="prismatic">
    <!-- linact down: 9.9 inches, up 13.9 inches -->
    <axis xyz="0 0 -1"/>
    <limit effort="10000" lower="0.0" upper="-0.1016" velocity=".025"/>
    <origin rpy="0 0 0" xyz="0.0 0.0 0.0"/>
    <parent link="right_lower_linear_actuator_link"/>
    <child link="right_upper_linear_actuator_link"/>
  </joint>
  <joint name="right_shoulder_tilt_joint" type="revolute">
<!--
    <origin rpy="0 0 0" xyz="0.0508 0 0.0"/>
-->
    <origin rpy="0 0 0" xyz="0.057 0 0.0"/>
    <parent link="right_shoulder_pan_link"/>
    <child link="right_upper_arm_link"/>
    <axis xyz="0 -1 0"/>
    <!--
            <limit  lower="-1.04" upper="1.95" effort="300" velocity=".1" />
-->
    <limit effort="300" lower="0.268" upper="1.213" velocity=".23"/>
<!--
    <safety_controller k_position="100" k_velocity="15.0" soft_lower_limit="-0.94719755" soft_upper_limit="1.872222"/>
-->
    <dynamics damping="50" friction="1"/>
  </joint>
<!-- ==========ARD CUT HERE ========== -->
<!--
 <joint name="right_arm_top_bar_joint" type="fixed">
    <origin rpy="0 0 0" xyz="0.0 0 0.003175"/>
    <parent link="right_upper_arm_link"/>
    <child link="right_upper_arm_top_bar_link"/>
    <axis xyz="0 -1 0"/>
  </joint>
  <link name="right_upper_arm_top_bar_link">
    <inertial>
      <mass value="0.405"/>
      <origin rpy="0 0 0" xyz="0.02988871 0 0.02056699"/>
      <inertia ixx="1.0" ixy="0.0" ixz="0.0" iyy="1.0" iyz="0.0" izz="1.0"/>
    </inertial>
    <visual>
      <origin rpy="0 0 0" xyz="0.1778 0.0 -.0254"/>
      <geometry>
        <box size="0.2921 0.0508 0.0508"/>
      </geometry>
      <material name="Silver1">
        <color rgba="0 0.9 0.9 1.0"/>
      </material>
    </visual>
  </link>
-->
  <joint name="right_upper_arm_hinge_joint" type="revolute">
<!-- ARD
    <origin rpy="0.0 0 0.0" xyz="0.3556 0.0 0.00635"/>
-->
    <origin rpy="0.0 0 0.0" xyz="0.41 0.0 0.00635"/>
    <parent link="right_upper_arm_link"/>
    <child link="right_elbow_pan_link"/>
    <axis xyz="0 -1 0"/>
    <limit effort="300" lower="-1.213" upper="-0.268" velocity=".23"/>
    <mimic joint="right_shoulder_tilt_joint" multiplier="-1" offset="0"/>
  </joint>
  <joint name="right_elbow_pan_joint" type="revolute">
    <origin rpy="0 0 0" xyz="-0.0508 0 0.0127"/>
    <parent link="right_elbow_pan_link"/>
    <child link="right_elbow_flex_link"/>
    <axis xyz="0 0 1"/>
    <limit effort="300" lower="-2.618" upper="2.618" velocity=".1"/>
  </joint>
  <joint name="right_elbow_flex_joint" type="revolute">
    <origin rpy="0 0 0" xyz="0.0762 0.0 0.0254"/>
    <parent link="right_elbow_flex_link"/>
    <child link="right_forearm_link"/>
    <axis xyz="0 -1 0"/>
    <limit effort="300" lower="-2.618" upper="2.618" velocity=".1"/>
  </joint>
  <joint name="right_wrist_flex_joint" type="revolute">
<!--
    <origin rpy="0 0 0" xyz="0.1778 0 0"/>
-->
    <origin rpy="0 0 0" xyz="0.18 0 0"/>
    <parent link="right_forearm_link"/>
    <child link="right_wrist_flex_link"/>
    <axis xyz="0 -1 0"/>
    <limit effort="300" lower="-2.618" upper="2.618" velocity=".1"/>
  </joint>
  <joint name="right_wrist_roll_joint" type="revolute">
    <origin rpy="0 0 0" xyz="0.07 0 0.023"/>
    <parent link="right_wrist_flex_link"/>
    <child link="right_wrist_roll_link"/>
    <axis xyz="-1 0 0"/>
    <limit effort="300" lower="-2.618" upper="2.618" velocity=".1"/>
  </joint>
  <joint name="right_gripper_right_joint" type="revolute">
    <origin rpy="0 0 0" xyz="0.0415 -0.0175 0"/>
    <parent link="right_wrist_roll_link"/>
    <child link="right_gripper_right_link"/>
    <axis xyz="0 0 1"/>
    <limit effort="300" lower="-2.618" upper="2.618" velocity=".1"/>
  </joint>
  <joint name="right_gripper_left_joint" type="revolute">
    <origin rpy="0 0 0" xyz="0.0415 0.0175 0"/>
    <parent link="right_wrist_roll_link"/>
    <child link="right_gripper_left_link"/>
    <axis xyz="0 0 1"/>
    <limit effort="300" lower="-2.618" upper="2.618" velocity=".1"/>
  </joint>
  <link name="right_elbow_pan_link">
    <inertial>
      <mass value="0.405"/>
      <origin rpy="0 0 0" xyz="0.0 0 0.02056699"/>
      <inertia ixx="1.0" ixy="0.0" ixz="0.0" iyy="1.0" iyz="0.0" izz="1.0"/>
    </inertial>
    <visual>
      <origin rpy="0 0 0" xyz="-0.0508 0.0 0.003175"/>
      <geometry>
        <box size="0.1016 0.1016 0.00635"/>
      </geometry>
      <material name="Green">
        <color rgba="0 0.9 0.9 1.0"/>
      </material>
    </visual>
  </link>
  <link name="right_elbow_flex_link">
    <inertial>
      <mass value="0.405"/>
      <origin rpy="0 0 0" xyz="0.0 0 0.0"/>
      <inertia ixx="1.0" ixy="0.0" ixz="0.0" iyy="1.0" iyz="0.0" izz="1.0"/>
    </inertial>
    <visual>
      <origin rpy="0 0 0" xyz="0.0 0.0 0.0"/>
      <geometry>
        <box size="0.1016 0.1016 0.00635"/>
      </geometry>
      <material name="Green">
        <color rgba="0 0.9 0.9 1.0"/>
      </material>
    </visual>
  </link>
  <link name="right_forearm_link">
    <inertial>
      <mass value="0.405"/>
      <origin rpy="0 0 0" xyz="0.02988871 0 0.02056699"/>
      <inertia ixx="1.0" ixy="0.0" ixz="0.0" iyy="1.0" iyz="0.0" izz="1.0"/>
    </inertial>
    <visual>
      <origin rpy="0 0 0" xyz="0.0889 0.0 0.0"/>
      <geometry>
        <!-- 2", 1", 7" -->
        <box size="0.1524  0.1016 0.0254"/>
      </geometry>
      <material name="Silver1">
        <color rgba="0 0.9 0.9 1.0"/>
      </material>
    </visual>
  </link>
  <link name="right_wrist_flex_link">
    <inertial>
      <mass value="0.12"/>
      <origin rpy="0 0 0" xyz="0.04463361 0 0.00720194"/>
      <inertia ixx="1.0" ixy="0.0" ixz="0.0" iyy="1.0" iyz="0.0" izz="1.0"/>
    </inertial>
    <visual>
      <origin rpy="0 0 0" xyz="0.0 0.0 0.0"/>
      <geometry>
        <mesh filename="package://pr2lite_urdf/config/meshes/arm_elbow_tilt.stl"/>
      </geometry>
      <material name="Green">
        <color rgba="0 0.9 0.9 1.0"/>
      </material>
    </visual>
   </link>
  <link name="right_wrist_roll_link">
    <inertial>
      <mass value="0.13"/>
      <origin rpy="0 0 0" xyz="0.02539960 0 0"/>
      <inertia ixx="1.0" ixy="0.0" ixz="0.0" iyy="1.0" iyz="0.0" izz="1.0"/>
    </inertial>
    <visual>
      <origin rpy="0 0 0" xyz="0.0 0.0 0.0"/>
      <geometry>
        <mesh filename="package://pr2lite_urdf/config/meshes/arm_wrist_rotate.stl"/>
      </geometry>
      <material name="Green">
        <color rgba="0 0.9 0.9 1.0"/>
      </material>
    </visual>
  </link>
  <link name="right_gripper_right_link">
    <inertial>
      <mass value="0.0225"/>
      <origin rpy="0 0 0" xyz="0.03058625 -0.01804371 -0.00941599"/>
      <inertia ixx="1.0" ixy="0.0" ixz="0.0" iyy="1.0" iyz="0.0" izz="1.0"/>
    </inertial>
    <visual>
      <origin rpy="0 0 0" xyz="0.0 0.0 0.0"/>
      <geometry>
        <mesh filename="package://pr2lite_urdf/config/meshes/arm_right_finger.stl"/>
      </geometry>
      <material name="Silver1">
        <color rgba="0 0.9 0.9 1.0"/>
      </material>
    </visual>
   </link>
  <link name="right_gripper_left_link">
    <inertial>
      <mass value="0.0225"/>
      <origin rpy="0 0 0" xyz="0.03058625 0.01804371 -0.00941599"/>
      <inertia ixx="1.0" ixy="0.0" ixz="0.0" iyy="1.0" iyz="0.0" izz="1.0"/>
    </inertial>
    <visual>
      <origin rpy="0 0 0" xyz="0.0 0.0 0.0"/>
      <geometry>
        <mesh filename="package://pr2lite_urdf/config/meshes/arm_left_finger.stl"/>
      </geometry>
      <material name="Silver1">
        <color rgba="0 0.9 0.9 1.0"/>
      </material>
    </visual>
  </link>
<!-- ==========ARD CUT HERE ========== -->
  <link name="right_shoulder_pan_link">
    <inertial>
      <mass value="0.405"/>
      <origin rpy="0 0 0" xyz="0.02988871 0 0.02056699"/>
      <inertia ixx="1.0" ixy="0.0" ixz="0.0" iyy="1.0" iyz="0.0" izz="1.0"/>
    </inertial>
    <visual>
      <origin rpy="0 0 0" xyz="0.0 0.0 0.0"/>
      <geometry>
        <box size="0.1016 0.1016 0.00635"/>
      </geometry>
      <material name="Silver1">
        <color rgba="0 0.9 0.9 1.0"/>
      </material>
    </visual>
  </link>
  <link name="right_shoulder_caster_link">
    <!-- 14.715 inches from linact to caster -->
    <visual>
      <origin rpy="0 0 0" xyz="0 0 0"/>
      <geometry>
        <box size="0.00635 0.1016 -0.373761"/>
      </geometry>
      <material name="Green">
        <color rgba="0 0.9 0.9 1.0"/>
      </material>
    </visual>
  </link>
  <link name="right_lower_linear_actuator_link">
    <visual>
      <axis xyz="0 0 0"/>
      <origin rpy="0 0 0" xyz="0.0 0.0 -0.12573"/>
      <geometry>
        <box size="0.03556 0.03048 -0.25146"/>
      </geometry>
      <material name="Silver1">
        <color rgba="0 0.9 0.9 1.0"/>
      </material>
    </visual>
  </link>
  <link name="right_upper_arm_link">
    <visual>
      <origin rpy="0 0 0" xyz="0.205 0.0 0.0"/>
      <geometry>
<!-- ARD
      <origin rpy="0 0 0" xyz="0.1778 0.0 0.0"/>
        <box size="0.3556 0.1016 0.00635"/>
-->
        <box size="0.41 0.1016 0.00635"/>
      </geometry>
      <material name="Silver1">
        <color rgba="0 0.9 0.9 1.0"/>
      </material>
    </visual>
  </link>
  <transmission name="right_shoulder_pan_trans" type="pr2_mechanism_model/SimpleTransmission">
    <actuator name="right_shoulder_pan_motor"/>
    <joint name="right_shoulder_pan_joint"/>
    <mechanicalReduction>1.0</mechanicalReduction>
  </transmission>
  <transmission name="right_elbow_flex_trans" type="pr2_mechanism_model/SimpleTransmission">
    <actuator name="right_elbow_flex_motor"/>
    <joint name="right_elbow_flex_joint"/>
    <mechanicalReduction>1.0</mechanicalReduction>
  </transmission>
  <transmission name="right_wrist_flex_trans" type="pr2_mechanism_model/SimpleTransmission">
    <actuator name="right_wrist_flex_motor"/>
    <joint name="right_wrist_flex_joint"/>
    <mechanicalReduction>1.0</mechanicalReduction>
  </transmission>
  <transmission name="right_wrist_roll_trans" type="pr2_mechanism_model/SimpleTransmission">
    <actuator name="right_wrist_roll_motor"/>
    <joint name="right_wrist_roll_joint"/>
    <mechanicalReduction>1.0</mechanicalReduction>
  </transmission>
  <transmission name="right_gripper_right_trans" type="pr2_mechanism_model/SimpleTransmission">
    <actuator name="right_gripper_right_motor"/>
    <joint name="right_gripper_right_joint"/>
    <mechanicalReduction>1.0</mechanicalReduction>
  </transmission>
  <transmission name="right_gripper_left_trans" type="pr2_mechanism_model/SimpleTransmission">
    <actuator name="right_gripper_left_motor"/>
    <joint name="right_gripper_left_joint"/>
    <mechanicalReduction>1.0</mechanicalReduction>
  </transmission>
  <gazebo reference="right_arm_base_link">
    <material>SmartArm/GunMetalBrushedAluminum</material>
    <turnGravityOff>true</turnGravityOff>
  </gazebo>
  <gazebo reference="right_arm_shoulder_pan_link">
    <material>SmartArm/GunMetalBrushedAluminum</material>
    <turnGravityOff>true</turnGravityOff>
  </gazebo>
  <gazebo reference="right_elbow_flex_link">
    <material>SmartArm/GunMetalBrushedAluminum</material>
    <turnGravityOff>true</turnGravityOff>
  </gazebo>
  <gazebo reference="right_wrist_flex_link">
    <material>SmartArm/GunMetalBrushedAluminum</material>
    <turnGravityOff>true</turnGravityOff>
  </gazebo>
  <gazebo reference="right_wrist_roll_link">
    <material>SmartArm/GunMetalBrushedAluminum</material>
    <turnGravityOff>true</turnGravityOff>
  </gazebo>
  <gazebo reference="right_gripper_right_link">
    <material>SmartArm/GunMetalBrushedAluminum</material>
    <turnGravityOff>true</turnGravityOff>
    <mu1 value="500.0"/>
    <mu2 value="500.0"/>
    <kp value="1000000.0"/>
    <kd value="1.0"/>
  </gazebo>
  <gazebo reference="right_gripper_left_link">
    <material>SmartArm/GunMetalBrushedAluminum</material>
    <turnGravityOff>true</turnGravityOff>
    <mu1 value="500.0"/>
    <mu2 value="500.0"/>
    <kp value="1000000.0"/>
    <kd value="1.0"/>
  </gazebo>
  <gazebo reference="right_shoulder_pan_joint">
    <stopKd value="1.0"/>
    <stopKp value="1000000.0"/>
    <fudgeFactor value="0.5"/>
  </gazebo>
  <gazebo reference="right_elbow_flex_joint">
    <stopKd value="1.0"/>
    <stopKp value="1000000.0"/>
    <fudgeFactor value="0.5"/>
  </gazebo>
  <gazebo reference="right_wrist_flex_joint">
    <stopKd value="1.0"/>
    <stopKp value="1000000.0"/>
    <fudgeFactor value="0.5"/>
  </gazebo>
  <gazebo reference="right_wrist_roll_joint">
    <stopKd value="1.0"/>
    <stopKp value="1000000.0"/>
    <fudgeFactor value="0.5"/>
  </gazebo>
  <gazebo reference="right_gripper_right_joint">
    <stopKd value="1.0"/>
    <stopKp value="1000000.0"/>
    <fudgeFactor value="1.0"/>
  </gazebo>
  <gazebo reference="right_gripper_left_joint">
    <stopKd value="1.0"/>
    <stopKp value="1000000.0"/>
    <fudgeFactor value="1.0"/>
  </gazebo>
  <!-- hokuyu on base -->
  <joint name="hokuyo_torso_joint" type="fixed">
    <parent link="base_link"/>
    <child link="hokuyo_torso_link"/>
    <origin rpy="0 0 0" xyz="0.1586 0 -0.02"/>
  </joint>
  <link name="hokuyo_torso_link">
    <inertial>
      <mass value="0"/>
      <origin xyz="0.0 0.0 0.0"/>
      <inertia ixx="1.0" ixy="0.0" ixz="0.0" iyy="1.0" iyz="0.0" izz="1.0"/>
    </inertial>
    <origin rpy="0 0 0" xyz="0.0 0.0 0.0"/>
  </link>
  <joint name="hokuyo_mount_joint" type="fixed">
    <!-- insert_block name="origin" /-->
    <parent link="hokuyo_torso_link"/>
    <child link="hokuyo_mount_link"/>
  </joint>
  <link name="hokuyo_mount_link">
    <inertial>
      <mass value="0.160"/>
      <origin rpy="0 0 0" xyz="0.0 0.0 0.0"/>
      <inertia ixx="1.0" ixy="0.0" ixz="0.0" iyy="1.0" iyz="0.0" izz="1.0"/>
    </inertial>
    <visual>
      <origin rpy="1.570795 0 1.570795" xyz="0.0 0.0 0.0"/>
      <geometry>
        <mesh filename="package://hokuyo_urg_description/meshes/hokuyo_urg.stl"/>
      </geometry>
    </visual>
    <collision>
      <origin rpy="1.570795 0 1.570795" xyz="0.0 0.0 0.0"/>
      <geometry>
        <mesh filename="package://hokuyo_urg_description/meshes/collada/hokuyo_urg.dae"/>
      </geometry>
    </collision>
  </link>
  <joint name="hokuyo_joint" type="fixed">
    <origin rpy="0 0 0" xyz="0 0 0.06"/>
    <parent link="hokuyo_mount_link"/>
<!--
    <child link="hokuyo_link"/>
-->
    <child link="neato_link"/>
  </joint>
<!--
  <link name="hokuyo_link" type="laser">
-->
  <link name="neato_link" type="laser">
    <inertial>
      <mass value="0.001"/>
      <origin rpy="0 0 0" xyz="0 0 0"/>
      <inertia ixx="0.0001" ixy="0" ixz="0" iyy="0.000001" iyz="0" izz="0.0001"/>
    </inertial>
    <visual name="laser_visual">
      <origin rpy="0 0 0" xyz="0 0 0"/>
      <geometry name="laser_visual_geom">
        <box size="0.001 0.001 0.001"/>
      </geometry>
      <material name="Red"/>
    </visual>
    <collision name="laser_collision">
      <origin rpy="0 0 0" xyz="0 0 0"/>
      <geometry name="laser_collision_geom">
        <box size=".001 .001 .001"/>
      </geometry>
    </collision>
  </link>
  <gazebo reference="hokuyo_mount_link">
    <material value="Erratic/Black"/>
  </gazebo>
<!--
  <gazebo reference="hokuyo_link">
-->
  <gazebo reference="neato_link">
    <material value="Erratic/Black"/>
  </gazebo>
<!--
  <gazebo reference="hokuyo_link">
-->
  <gazebo reference="neato_link">
    <sensor:ray name="laser">
      <rayCount>683</rayCount>
      <rangeCount>683</rangeCount>
      <laserCount>1</laserCount>
      <origin>0.0 0.0 0.0</origin>
      <minAngle>-90</minAngle>
      <maxAngle> 90</maxAngle>
      <minRange>0.06</minRange>
      <maxRange>4.0</maxRange>
      <resRange>0.001</resRange>
      <updateRate>10.0</updateRate>
      <controller:gazebo_ros_laser name="gazebo_ros_hokuyo_laser_controller" plugin="libgazebo_ros_laser.so">
        <gaussianNoise>0.005</gaussianNoise>
        <alwaysOn>true</alwaysOn>
        <updateRate>10.0</updateRate>
        <topicName>hokuyo/scan</topicName>
<!--
        <frameName>hokuyo_link</frameName>
-->
        <frameName>neato_link</frameName>
        <interface:laser name="gazebo_ros_hokuyo_laser_iface"/>
      </controller:gazebo_ros_laser>
    </sensor:ray>
  </gazebo>
</robot>

