<?xml version="1.0" ?>
<!-- =================================================================================== -->
<!-- |    This document was autogenerated by xacro from prlite_base.xacro              | -->
<!-- |    EDITING THIS FILE BY HAND IS NOT RECOMMENDED                                 | -->
<!-- =================================================================================== -->
<robot name="prlite" xmlns:body="http://playerstage.sourceforge.net/gazebo/xmlschema/#body" xmlns:controller="http://playerstage.sourceforge.net/gazebo/xmlschema/#controller" xmlns:interface="http://playerstage.sourceforge.net/gazebo/xmlschema/#interface" xmlns:joint="http://playerstage.sourceforge.net/gazebo/xmlschema/#slider" xmlns:sensor="http://playerstage.sourceforge.net/gazebo/xmlschema/#sensor" xmlns:xacro="http://www.ros.org/wiki/xacro">
  <!-- Included URDF Files -->
  <material name="Black">
    <color rgba="0.0 0.0 0.0 1.0"/>
  </material>
  <material name="Blue">
    <color rgba="0.0 0.0 0.8 1.0"/>
  </material>
  <material name="Green">
    <color rgba="0.0 0.8 0.0 1.0"/>
  </material>
  <material name="Grey">
    <color rgba="0.7 0.7 0.7 1.0"/>
  </material>
  <material name="Grey2">
    <color rgba="0.9 0.9 0.9 1.0"/>
  </material>
  <material name="Red">
    <color rgba="0.8 0.0 0.0 1.0"/>
  </material>
  <material name="White">
    <color rgba="1.0 1.0 1.0 1.0"/>
  </material>
  <material name="GunMetalBrushedAluminum">
    <texture filename="package://smart_arm_description/Media/materials/textures/gun_metal_brushed_aluminum.jpg"/>
  </material>
  <!-- Properties (Constants) -->
  <!-- base_footprint is a fictitious link(frame) that is on the ground right below base_link origin,
             navigation stack depends on this frame -->
  <link name="base_footprint">
    <inertial>
      <mass value="0.0001"/>
      <origin xyz="0 0 0"/>
      <inertia ixx="0.0001" ixy="0.0" ixz="0.0" iyy="0.0001" iyz="0.0" izz="0.0001"/>
    </inertial>
    <visual>
      <origin rpy="0 0 0" xyz="0 0 0.21844"/>
      <geometry>
        <box size="0.001 0.001 0.001"/>
      </geometry>
      <material name="Green"/>
    </visual>
    <collision>
      <origin rpy="0 0 0" xyz="0 0 0.21844"/>
      <geometry>
        <box size="0.001 0.001 0.001"/>
      </geometry>
    </collision>
  </link>
  <joint name="base_footprint_joint" type="fixed">
    <!-- NB: While you would think this would make it go up, it is oddly reversed.
                 This moves the joint to 0,0,0 where we want it for rviz, etc. -->
    <origin rpy="0 0 0" xyz="0 0 0.21844"/>
    <parent link="base_footprint"/>
    <child link="base_link"/>
  </joint>
  <!-- Links and Joints (i.e., the robot) -->
  <link name="base_link">
    <inertial>
      <mass value="20"/>
      <!-- origin xyz="${-base_size_x/2} ${-base_size_y/2} ${-base_size_z/2}" / -->
      <origin xyz="0 0 0"/>
      <inertia ixx="1.0" ixy="0.0" ixz="0.0" iyy="1.0" iyz="0.0" izz="1.0"/>
    </inertial>
    <visual>
      <origin rpy="0 0 0" xyz="0.0 0.0 0.21844"/>
      <geometry>
        <box size="0.4953 0.508 0.4318"/>
      </geometry>
      <material name="Blue"/>
    </visual>
    <collision>
      <origin rpy="0 0 0" xyz="0.0 0.0 0.0"/>
      <geometry>
        <box size="0.4953 0.508 0.4318"/>
      </geometry>
    </collision>
  </link>
  <joint name="wheel_linear_actuator_joint" type="prismatic">
    <axis xyz="1 0 0"/>
    <limit effort="10000" lower="0.0" upper="0.1016" velocity=".05"/>
    <origin rpy="0 0 0" xyz="0 0 0"/>
    <parent link="base_link"/>
    <child link="wheel_linear_actuator_link"/>
  </joint>
  <link name="wheel_linear_actuator_link">
    <visual>
      <axis xyz="0 1 0"/>
      <origin rpy="0 1.57 0" xyz="-0.1524 0 0"/>
      <geometry>
        <box size=".0254 .0254 0.2032"/>
      </geometry>
      <material name="Silver1">
        <color rgba="0 0.9 0.9 1.0"/>
      </material>
    </visual>
  </link>
  <joint name="fl_linear_actuatuor_joint" type="fixed">
    <parent link="wheel_linear_actuator_link"/>
    <child link="fl_anchor_rod_link"/>
    <origin rpy="0 0 0" xyz="0.0 0 0"/>
  </joint>
  <joint name="fr_linear_actuatuor_joint" type="fixed">
    <parent link="wheel_linear_actuator_link"/>
    <child link="fr_anchor_rod_link"/>
    <origin rpy="0 0 0" xyz="0.0 0 0"/>
  </joint>
  <joint name="bl_linear_actuatuor_joint" type="fixed">
    <parent link="wheel_linear_actuator_link"/>
    <child link="bl_anchor_rod_link"/>
    <origin rpy="0 0 0" xyz="0.0 0 0"/>
  </joint>
  <joint name="br_linear_actuatuor_joint" type="fixed">
    <parent link="wheel_linear_actuator_link"/>
    <child link="br_anchor_rod_link"/>
    <origin rpy="0 0 0" xyz="0.0 0 0"/>
  </joint>
  <joint name="fl_base_joint" type="fixed">
    <axis xyz="0 0 1"/>
    <parent link="base_link"/>
    <child link="fl_base_link"/>
    <origin rpy="0 0 0" xyz="0.1651 0.1651 0.00635"/>
  </joint>
  <link name="fl_base_link">
    <visual>
      <origin rpy="0 0 0" xyz="0 0 0"/>
      <geometry>
        <box size=".0201 .0201 .0001"/>
      </geometry>
      <material name="Grey1">
        <color rgba="0 0.9 0.9 1.0"/>
      </material>
    </visual>
  </link>
  <link name="fl_anchor_rod_link">
    <visual>
      <axis xyz="0 0 1"/>
      <origin rpy="0 0 0" xyz="-0.0508 -0.10795 0"/>
      <geometry>
        <box size="0.01905 0.2159 0.00127"/>
      </geometry>
      <material name="Silver1">
        <color rgba="0 0.9 0.9 1.0"/>
      </material>
    </visual>
  </link>
  <joint name="fl_anchor_rod_joint" type="revolute">
    <axis xyz="0 0 1"/>
    <limit effort="10" lower="-3.1416" upper="3.1416" velocity="3"/>
    <parent link="fl_anchor_rod_link"/>
    <child link="fl_push_rod_link"/>
    <origin rpy="0 0 0" xyz="-0.0508 0.2159 0"/>
  </joint>
  <link name="fl_push_rod_link">
    <visual>
      <axis xyz="0 0 1"/>
      <origin rpy="0 0 0" xyz="-0.0889 0 0"/>
      <geometry>
        <box size="0.1778 0.01905 0.00127"/>
      </geometry>
      <material name="Silver1">
        <color rgba="0 0.9 0.9 1.0"/>
      </material>
    </visual>
  </link>
  <joint name="fl_caster_rotation_joint" type="revolute">
    <axis xyz="0 0 1"/>
    <limit effort="10" lower="-3.1416" upper="3.1416" velocity="3"/>
    <parent link="fl_base_link"/>
    <child link="fl_caster_link"/>
    <origin rpy="0 0 0" xyz="0 0 0"/>
  </joint>
  <link name="fl_caster_link">
    <visual>
      <origin rpy="0 0 0" xyz="0 0 0"/>
      <geometry>
        <box size="0.1016 0.1016 0.00635"/>
      </geometry>
      <material name="Grey1">
        <color rgba="0 0.9 0.9 1.0"/>
      </material>
    </visual>
  </link>
  <joint name="fl_caster_motor_joint" type="fixed">
    <axis xyz="0 0 1"/>
    <parent link="fl_caster_link"/>
    <child link="fl_wheel_motor_block_link"/>
    <origin rpy="0 0 0" xyz="0 0 0"/>
  </joint>
  <link name="fl_wheel_motor_block_link">
    <visual>
      <origin rpy="0 0 0" xyz="0 0 -0.0508"/>
      <geometry>
        <box size="0.1016 0.0254 0.1016"/>
      </geometry>
      <material name="Blue1">
        <color rgba="0 0.9 0.9 1.0"/>
      </material>
    </visual>
  </link>
  <joint name="fl_wheel_joint" type="continuous">
    <axis xyz="0 1 0"/>
    <limit effort="100" velocity="100"/>
    <safety_controller k_velocity="10"/>
    <dynamics damping="0.0" friction="0.0"/>
    <origin rpy="0 0 0" xyz="0 0.0254 -0.0889"/>
    <parent link="fl_wheel_motor_block_link"/>
    <child link="fl_wheel_link"/>
  </joint>
  <link name="fl_wheel_link">
    <inertial>
      <mass value="0.1"/>
      <origin xyz=" 0 0 0 "/>
      <inertia ixx="0.012411765597" ixy="0.0" ixz="0.0" iyy="0.015218160428" iyz="0.0" izz="0.011763977943"/>
    </inertial>
    <visual>
      <origin rpy="0 1.570795 1.570795" xyz="0 0.00635 0"/>
      <geometry>
        <cylinder length="0.0127" radius="0.0762"/>
      </geometry>
      <material name="Grey"/>
    </visual>
    <collision>
      <origin rpy="0 1.570795 1.570795" xyz="0 0 0"/>
      <geometry>
        <cylinder length="0.0127" radius="0.0762"/>
      </geometry>
    </collision>
    <gazebo reference="base_link_fl_wheel_link">
      <mu1 value="100.0"/>
      <mu2 value="100.0"/>
      <kp value="1000000.0"/>
      <kd value="1.0"/>
      <material>Erratic/Grey</material>
    </gazebo>
    <gazebo reference="base_link_fl_motor_link">
      <material>Erratic/White</material>
    </gazebo>
    <transmission name="base_link_fl_wheel_trans" type="pr2_mechanism_model/SimpleTransmission">
      <actuator name="base_link_fl_wheel_motor"/>
      <joint name="base_link_fl_wheel_joint"/>
      <mechanicalReduction>1.0</mechanicalReduction>
    </transmission>
  </link>
  <joint name="fr_base_joint" type="fixed">
    <axis xyz="0 0 1"/>
    <parent link="base_link"/>
    <child link="fr_base_link"/>
    <origin rpy="0 0 0" xyz="0.1651 -0.1651 0.00635"/>
  </joint>
  <link name="fr_base_link">
    <visual>
      <origin rpy="0 0 0" xyz="0 0 0"/>
      <geometry>
        <box size=".0201 .0201 .0001"/>
      </geometry>
      <material name="Grey1">
        <color rgba="0 0.9 0.9 1.0"/>
      </material>
    </visual>
  </link>
  <link name="fr_anchor_rod_link">
    <visual>
      <axis xyz="0 0 1"/>
      <origin rpy="0 0 0" xyz="-0.0508 0.05715 0"/>
      <geometry>
        <box size="0.01905 0.1143 0.00127"/>
      </geometry>
      <material name="Silver1">
        <color rgba="0 0.9 0.9 1.0"/>
      </material>
    </visual>
  </link>
  <joint name="fr_anchor_rod_joint" type="revolute">
    <axis xyz="0 0 1"/>
    <limit effort="10" lower="-3.1416" upper="3.1416" velocity="3"/>
    <parent link="fr_anchor_rod_link"/>
    <child link="fr_push_rod_link"/>
    <origin rpy="0 0 0" xyz="-0.0508 -0.2159 0"/>
  </joint>
  <link name="fr_push_rod_link">
    <visual>
      <axis xyz="0 0 1"/>
      <origin rpy="0 0 0" xyz="-0.0889 0 0"/>
      <geometry>
        <box size="0.1778 0.01905 0.00127"/>
      </geometry>
      <material name="Silver1">
        <color rgba="0 0.9 0.9 1.0"/>
      </material>
    </visual>
  </link>
  <joint name="fr_caster_rotation_joint" type="revolute">
    <axis xyz="0 0 1"/>
    <limit effort="10" lower="-3.1416" upper="3.1416" velocity="3"/>
    <parent link="fr_base_link"/>
    <child link="fr_caster_link"/>
    <origin rpy="0 0 0" xyz="0 0 0"/>
  </joint>
  <link name="fr_caster_link">
    <visual>
      <origin rpy="0 0 0" xyz="0 0 0"/>
      <geometry>
        <box size="0.1016 0.1016 0.00635"/>
      </geometry>
      <material name="Grey1">
        <color rgba="0 0.9 0.9 1.0"/>
      </material>
    </visual>
  </link>
  <joint name="fr_caster_motor_joint" type="fixed">
    <axis xyz="0 0 1"/>
    <parent link="fr_caster_link"/>
    <child link="fr_wheel_motor_block_link"/>
    <origin rpy="0 0 0" xyz="0 0 0"/>
  </joint>
  <link name="fr_wheel_motor_block_link">
    <visual>
      <origin rpy="0 0 0" xyz="0 0 -0.0508"/>
      <geometry>
        <box size="0.1016 0.0254 0.1016"/>
      </geometry>
      <material name="Blue1">
        <color rgba="0 0.9 0.9 1.0"/>
      </material>
    </visual>
  </link>
  <joint name="fr_wheel_joint" type="continuous">
    <axis xyz="0 1 0"/>
    <limit effort="100" velocity="100"/>
    <safety_controller k_velocity="10"/>
    <dynamics damping="0.0" friction="0.0"/>
    <origin rpy="0 0 0" xyz="0 -0.0254 -0.0889"/>
    <parent link="fr_wheel_motor_block_link"/>
    <child link="fr_wheel_link"/>
  </joint>
  <link name="fr_wheel_link">
    <inertial>
      <mass value="0.1"/>
      <origin xyz=" 0 0 0 "/>
      <inertia ixx="0.012411765597" ixy="0.0" ixz="0.0" iyy="0.015218160428" iyz="0.0" izz="0.011763977943"/>
    </inertial>
    <visual>
      <origin rpy="0 1.570795 1.570795" xyz="0 -0.00635 0"/>
      <geometry>
        <cylinder length="0.0127" radius="0.0762"/>
      </geometry>
      <material name="Grey"/>
    </visual>
    <collision>
      <origin rpy="0 1.570795 1.570795" xyz="0 0 0"/>
      <geometry>
        <cylinder length="0.0127" radius="0.0762"/>
      </geometry>
    </collision>
    <gazebo reference="base_link_fr_wheel_link">
      <mu1 value="100.0"/>
      <mu2 value="100.0"/>
      <kp value="1000000.0"/>
      <kd value="1.0"/>
      <material>Erratic/Grey</material>
    </gazebo>
    <gazebo reference="base_link_fr_motor_link">
      <material>Erratic/White</material>
    </gazebo>
    <transmission name="base_link_fr_wheel_trans" type="pr2_mechanism_model/SimpleTransmission">
      <actuator name="base_link_fr_wheel_motor"/>
      <joint name="base_link_fr_wheel_joint"/>
      <mechanicalReduction>1.0</mechanicalReduction>
    </transmission>
  </link>
  <joint name="bl_base_joint" type="fixed">
    <axis xyz="0 0 1"/>
    <parent link="base_link"/>
    <child link="bl_base_link"/>
    <origin rpy="0 0 0" xyz="-0.1651 0.1651 0.00635"/>
  </joint>
  <link name="bl_base_link">
    <visual>
      <origin rpy="0 0 0" xyz="0 0 0"/>
      <geometry>
        <box size=".0201 .0201 .0001"/>
      </geometry>
      <material name="Grey1">
        <color rgba="0 0.9 0.9 1.0"/>
      </material>
    </visual>
  </link>
  <link name="bl_anchor_rod_link">
    <visual>
      <axis xyz="0 0 1"/>
      <origin rpy="0 0 0" xyz="-0.0508 -0.05715 0"/>
      <geometry>
        <box size="0.01905 0.1143 0.00127"/>
      </geometry>
      <material name="Silver1">
        <color rgba="0 0.9 0.9 1.0"/>
      </material>
    </visual>
  </link>
  <joint name="bl_anchor_rod_joint" type="revolute">
    <axis xyz="0 0 1"/>
    <limit effort="10" lower="-3.1416" upper="3.1416" velocity="3"/>
    <parent link="bl_anchor_rod_link"/>
    <child link="bl_push_rod_link"/>
    <origin rpy="0 0 0" xyz="-0.0508 0.1143 0"/>
  </joint>
  <link name="bl_push_rod_link">
    <visual>
      <axis xyz="0 0 1"/>
      <origin rpy="0 0 0" xyz="0.0889 0 0"/>
      <geometry>
        <box size="0.1778 0.01905 0.00127"/>
      </geometry>
      <material name="Silver1">
        <color rgba="0 0.9 0.9 1.0"/>
      </material>
    </visual>
  </link>
  <joint name="bl_caster_rotation_joint" type="revolute">
    <axis xyz="0 0 1"/>
    <limit effort="10" lower="-3.1416" upper="3.1416" velocity="3"/>
    <parent link="bl_base_link"/>
    <child link="bl_caster_link"/>
    <origin rpy="0 0 0" xyz="0 0 0"/>
  </joint>
  <link name="bl_caster_link">
    <visual>
      <origin rpy="0 0 0" xyz="0 0 0"/>
      <geometry>
        <box size="0.1016 0.1016 0.00635"/>
      </geometry>
      <material name="Grey1">
        <color rgba="0 0.9 0.9 1.0"/>
      </material>
    </visual>
  </link>
  <joint name="bl_caster_motor_joint" type="fixed">
    <axis xyz="0 0 1"/>
    <parent link="bl_caster_link"/>
    <child link="bl_wheel_motor_block_link"/>
    <origin rpy="0 0 0" xyz="0 0 0"/>
  </joint>
  <link name="bl_wheel_motor_block_link">
    <visual>
      <origin rpy="0 0 0" xyz="0 0 -0.0508"/>
      <geometry>
        <box size="0.1016 0.0254 0.1016"/>
      </geometry>
      <material name="Blue1">
        <color rgba="0 0.9 0.9 1.0"/>
      </material>
    </visual>
  </link>
  <joint name="bl_wheel_joint" type="continuous">
    <axis xyz="0 1 0"/>
    <limit effort="100" velocity="100"/>
    <safety_controller k_velocity="10"/>
    <dynamics damping="0.0" friction="0.0"/>
    <origin rpy="0 0 0" xyz="0 0.0254 -0.0889"/>
    <parent link="bl_wheel_motor_block_link"/>
    <child link="bl_wheel_link"/>
  </joint>
  <link name="bl_wheel_link">
    <inertial>
      <mass value="0.1"/>
      <origin xyz=" 0 0 0 "/>
      <inertia ixx="0.012411765597" ixy="0.0" ixz="0.0" iyy="0.015218160428" iyz="0.0" izz="0.011763977943"/>
    </inertial>
    <visual>
      <origin rpy="0 1.570795 1.570795" xyz="0 0.00635 0"/>
      <geometry>
        <cylinder length="0.0127" radius="0.0762"/>
      </geometry>
      <material name="Grey"/>
    </visual>
    <collision>
      <origin rpy="0 1.570795 1.570795" xyz="0 0 0"/>
      <geometry>
        <cylinder length="0.0127" radius="0.0762"/>
      </geometry>
    </collision>
    <gazebo reference="base_link_bl_wheel_link">
      <mu1 value="100.0"/>
      <mu2 value="100.0"/>
      <kp value="1000000.0"/>
      <kd value="1.0"/>
      <material>Erratic/Grey</material>
    </gazebo>
    <gazebo reference="base_link_bl_motor_link">
      <material>Erratic/White</material>
    </gazebo>
    <transmission name="base_link_bl_wheel_trans" type="pr2_mechanism_model/SimpleTransmission">
      <actuator name="base_link_bl_wheel_motor"/>
      <joint name="base_link_bl_wheel_joint"/>
      <mechanicalReduction>1.0</mechanicalReduction>
    </transmission>
  </link>
  <joint name="br_base_joint" type="fixed">
    <axis xyz="0 0 1"/>
    <parent link="base_link"/>
    <child link="br_base_link"/>
    <origin rpy="0 0 0" xyz="-0.1651 -0.1651 0.00635"/>
  </joint>
  <link name="br_base_link">
    <visual>
      <origin rpy="0 0 0" xyz="0 0 0"/>
      <geometry>
        <box size=".0201 .0201 .0001"/>
      </geometry>
      <material name="Grey1">
        <color rgba="0 0.9 0.9 1.0"/>
      </material>
    </visual>
  </link>
  <link name="br_anchor_rod_link">
    <visual>
      <axis xyz="0 0 1"/>
      <origin rpy="0 0 0" xyz="-0.0508 0.10795 0"/>
      <geometry>
        <box size="0.01905 0.2159 0.00127"/>
      </geometry>
      <material name="Silver1">
        <color rgba="0 0.9 0.9 1.0"/>
      </material>
    </visual>
  </link>
  <joint name="br_anchor_rod_joint" type="revolute">
    <axis xyz="0 0 1"/>
    <limit effort="10" lower="-3.1416" upper="3.1416" velocity="3"/>
    <parent link="br_anchor_rod_link"/>
    <child link="br_push_rod_link"/>
    <origin rpy="0 0 0" xyz="-0.0508 -0.1143 0"/>
  </joint>
  <link name="br_push_rod_link">
    <visual>
      <axis xyz="0 0 1"/>
      <origin rpy="0 0 0" xyz="0.0889 0 0"/>
      <geometry>
        <box size="0.1778 0.01905 0.00127"/>
      </geometry>
      <material name="Silver1">
        <color rgba="0 0.9 0.9 1.0"/>
      </material>
    </visual>
  </link>
  <joint name="br_caster_rotation_joint" type="revolute">
    <axis xyz="0 0 1"/>
    <limit effort="10" lower="-3.1416" upper="3.1416" velocity="3"/>
    <parent link="br_base_link"/>
    <child link="br_caster_link"/>
    <origin rpy="0 0 0" xyz="0 0 0"/>
  </joint>
  <link name="br_caster_link">
    <visual>
      <origin rpy="0 0 0" xyz="0 0 0"/>
      <geometry>
        <box size="0.1016 0.1016 0.00635"/>
      </geometry>
      <material name="Grey1">
        <color rgba="0 0.9 0.9 1.0"/>
      </material>
    </visual>
  </link>
  <joint name="br_caster_motor_joint" type="fixed">
    <axis xyz="0 0 1"/>
    <parent link="br_caster_link"/>
    <child link="br_wheel_motor_block_link"/>
    <origin rpy="0 0 0" xyz="0 0 0"/>
  </joint>
  <link name="br_wheel_motor_block_link">
    <visual>
      <origin rpy="0 0 0" xyz="0 0 -0.0508"/>
      <geometry>
        <box size="0.1016 0.0254 0.1016"/>
      </geometry>
      <material name="Blue1">
        <color rgba="0 0.9 0.9 1.0"/>
      </material>
    </visual>
  </link>
  <joint name="br_wheel_joint" type="continuous">
    <axis xyz="0 1 0"/>
    <limit effort="100" velocity="100"/>
    <safety_controller k_velocity="10"/>
    <dynamics damping="0.0" friction="0.0"/>
    <origin rpy="0 0 0" xyz="0 -0.0254 -0.0889"/>
    <parent link="br_wheel_motor_block_link"/>
    <child link="br_wheel_link"/>
  </joint>
  <link name="br_wheel_link">
    <inertial>
      <mass value="0.1"/>
      <origin xyz=" 0 0 0 "/>
      <inertia ixx="0.012411765597" ixy="0.0" ixz="0.0" iyy="0.015218160428" iyz="0.0" izz="0.011763977943"/>
    </inertial>
    <visual>
      <origin rpy="0 1.570795 1.570795" xyz="0 -0.00635 0"/>
      <geometry>
        <cylinder length="0.0127" radius="0.0762"/>
      </geometry>
      <material name="Grey"/>
    </visual>
    <collision>
      <origin rpy="0 1.570795 1.570795" xyz="0 0 0"/>
      <geometry>
        <cylinder length="0.0127" radius="0.0762"/>
      </geometry>
    </collision>
    <gazebo reference="base_link_br_wheel_link">
      <mu1 value="100.0"/>
      <mu2 value="100.0"/>
      <kp value="1000000.0"/>
      <kd value="1.0"/>
      <material>Erratic/Grey</material>
    </gazebo>
    <gazebo reference="base_link_br_motor_link">
      <material>Erratic/White</material>
    </gazebo>
    <transmission name="base_link_br_wheel_trans" type="pr2_mechanism_model/SimpleTransmission">
      <actuator name="base_link_br_wheel_motor"/>
      <joint name="base_link_br_wheel_joint"/>
      <mechanicalReduction>1.0</mechanicalReduction>
    </transmission>
  </link>
  <joint name="torso_body_joint" type="fixed">
    <parent link="base_link"/>
    <child link="torso_lift_link"/>
    <origin rpy="0 0 0" xyz="0.254 0 0.1651"/>
  </joint>
  <link name="torso_lift_link">
    <visual>
      <axis xyz="0 0 0"/>
      <origin rpy="0 0 0" xyz="0.0 0.0 -0.0381"/>
      <geometry>
        <box size="0.0254 0.0254 0.4318"/>
      </geometry>
      <material name="Silver1">
        <color rgba="0 0.9 0.9 1.0"/>
      </material>
    </visual>
  </link>
  <joint name="torso_lift_joint" type="prismatic">
    <axis xyz="0 0 1"/>
    <limit effort="10000" lower="0.0" upper="0.3048" velocity=".05"/>
    <origin rpy="0 0 0" xyz="-0 0 0"/>
    <parent link="torso_lift_link"/>
    <child link="torso_link"/>
    <origin rpy="0 0 0" xyz="0 0.0127 0"/>
  </joint>
  <link name="torso_link">
    <visual>
      <axis xyz="0 0 0"/>
      <origin rpy="0 0 0" xyz="0.0127 0.0 0.0"/>
      <geometry>
        <box size="0.00635 0.508 0.508"/>
      </geometry>
      <material name="Silver1">
        <color rgba="0 0.9 0.9 1.0"/>
      </material>
    </visual>
  </link>
  <joint name="front_shelf_joint" type="fixed">
    <parent link="torso_lift_link"/>
    <child link="front_shelf_link"/>
    <origin rpy="0 0 0" xyz="0 0.00635 0"/>
  </joint>
  <link name="front_shelf_link">
    <visual>
      <origin rpy="0 0 0" xyz="0.0762 0.0 -0.254"/>
      <geometry>
        <box size="0.1524 0.508 0.00635"/>
      </geometry>
      <material name="Grey1">
        <color rgba="0 0.9 0.9 1.0"/>
      </material>
    </visual>
  </link>
  <joint name="left_arm_shelf_joint" type="fixed">
    <parent link="torso_link"/>
    <child link="left_arm_shelf_link"/>
    <origin rpy="0 0 0" xyz="0.0 0.1778 -0.24765"/>
  </joint>
  <link name="left_arm_shelf_link">
    <visual>
      <origin rpy="0 0 0" xyz="0.0762 0.0 0.0"/>
      <geometry>
        <box size="0.1524 0.1524 0.00635"/>
      </geometry>
      <material name="Silver1">
        <color rgba="0 0.9 0.9 1.0"/>
      </material>
    </visual>
  </link>
  <joint name="left_arm_base_link" type="fixed">
    <axis xyz="0 0 1"/>
    <parent link="left_arm_shelf_link"/>
    <child link="left_shoulder_pan_link"/>
    <origin rpy="0 0 0" xyz="0.1016 0.0 0.0254"/>
  </joint>
  <joint name="right_arm_shelf_joint" type="fixed">
    <parent link="torso_link"/>
    <child link="right_arm_shelf_link"/>
    <origin rpy="0 0 0" xyz="0.0 -0.1778 -0.24765"/>
  </joint>
  <link name="right_arm_shelf_link">
    <visual>
      <axis xyz="0 0 1"/>
      <origin rpy="0 0 0" xyz="0.0762 0.0 0.0"/>
      <geometry>
        <box size="0.1524 0.1524 0.00635"/>
      </geometry>
      <material name="Silver1">
        <color rgba="0 0.9 0.9 1.0"/>
      </material>
    </visual>
  </link>
  <joint name="right_arm_base_link" type="fixed">
    <parent link="right_arm_shelf_link"/>
    <child link="right_shoulder_pan_link"/>
    <origin rpy="0 0 0" xyz="0.1016 0.0 0.0254"/>
  </joint>
  <joint name="hokuyo_torso_joint" type="fixed">
    <parent link="torso_link"/>
    <child link="hokuyo_torso_link"/>
    <origin rpy="0 0 0" xyz="0.0508 0 0.0508"/>
  </joint>
  <link name="hokuyo_torso_link">
    <origin rpy="0 0 0" xyz="0.0 0.0 0.0"/>
  </link>
  <joint name="left_shoulder_pan_joint" type="revolute">
    <origin rpy="0 0 0" xyz="-0.0075 0 0.025"/>
    <!-- parent link="${side}_arm_base_link" /-->
    <parent link="left_shoulder_pan_link"/>
    <child link="left_elbow_flex_link"/>
    <axis xyz="0 0 1"/>
    <limit effort="300" lower="-1.22" upper="1.22" velocity="1.17"/>
    <safety_controller k_position="100" k_velocity="15.0" soft_lower_limit="-1.12" soft_upper_limit="1.12"/>
    <dynamics damping="50" friction="1"/>
  </joint>
  <joint name="left_elbow_flex_joint" type="revolute">
    <origin rpy="0 0 0" xyz="0.079575 0 0.0445"/>
    <parent link="left_elbow_flex_link"/>
    <child link="left_forearm_link"/>
    <axis xyz="0 -1 0"/>
    <limit effort="300" lower="-1.04719755" upper="1.972222" velocity="1.17"/>
    <safety_controller k_position="100" k_velocity="15.0" soft_lower_limit="-0.94719755" soft_upper_limit="1.872222"/>
    <dynamics damping="50" friction="1"/>
  </joint>
  <joint name="left_wrist_flex_joint" type="revolute">
    <origin rpy="0 0 0" xyz="0.1815 0 0"/>
    <parent link="left_forearm_link"/>
    <child link="left_wrist_flex_link"/>
    <axis xyz="0 -1 0"/>
    <!-- From -113 to 108 degrees -->
    <limit effort="300" lower="-1.972222" upper="1.8849556" velocity="1.17"/>
    <dynamics damping="50" friction="1"/>
    <safety_controller k_position="100" k_velocity="15.0" soft_lower_limit="-1.872222" soft_upper_limit="1.7849556"/>
  </joint>
  <joint name="left_wrist_roll_joint" type="revolute">
    <origin rpy="0 0 0" xyz="0.07 0 0.023"/>
    <parent link="left_wrist_flex_link"/>
    <child link="left_wrist_roll_link"/>
    <axis xyz="-1 0 0"/>
    <!-- From -150 to 150 degrees -->
    <limit effort="300" lower="-2.6179939" upper="2.6179939" velocity="1.17"/>
    <dynamics damping="50" friction="1"/>
    <safety_controller k_position="100" k_velocity="15.0" soft_lower_limit="-2.5179939" soft_upper_limit="2.5179939"/>
  </joint>
  <joint name="left_gripper_right_joint" type="revolute">
    <origin rpy="0 0 0" xyz="0.0415 -0.0175 0"/>
    <parent link="left_wrist_roll_link"/>
    <child link="left_gripper_right_link"/>
    <axis xyz="0 0 1"/>
    <!-- From 14 to -45 degrees -->
    <limit effort="300" lower="-0.838576116" upper="0.245436912" velocity="1.17"/>
    <dynamics damping="50" friction="1"/>
    <safety_controller k_position="100" k_velocity="15.0" soft_lower_limit="-0.738576116" soft_upper_limit="0.145436912"/>
  </joint>
  <joint name="left_gripper_left_joint" type="revolute">
    <origin rpy="0 0 0" xyz="0.0415 0.0175 0"/>
    <parent link="left_wrist_roll_link"/>
    <child link="left_gripper_left_link"/>
    <axis xyz="0 0 1"/>
    <!-- From -14 to 45 degrees -->
    <limit effort="300" lower="-0.240323643" upper="0.843689385" velocity="1.17"/>
    <dynamics damping="50" friction="1"/>
    <safety_controller k_position="100" k_velocity="15.0" soft_lower_limit="-0.140323643" soft_upper_limit="0.743689385"/>
  </joint>
  <link name="left_shoulder_pan_link">
    <inertial>
      <mass value="0.125"/>
      <origin rpy="0 0 0" xyz="0 0 0.00893364"/>
      <inertia ixx="1.0" ixy="0.0" ixz="0.0" iyy="1.0" iyz="0.0" izz="1.0"/>
    </inertial>
    <visual>
      <origin rpy="0 0 0" xyz="0.0 0.0 0.0"/>
      <geometry>
        <mesh filename="package://smart_arm_description/meshes/arm_base.stl"/>
      </geometry>
    </visual>
    <!--
            <collision>
                <origin xyz="0.0 0.0 0.0" rpy="0 0 0" />
                <geometry>
                    <mesh filename="package://smart_arm_description/meshes/convex/arm_base_convex.stlb"/>
                </geometry>
            </collision>
-->
  </link>
  <link name="left_elbow_flex_link">
    <inertial>
      <mass value="0.405"/>
      <origin rpy="0 0 0" xyz="0.02988871 0 0.02056699"/>
      <inertia ixx="1.0" ixy="0.0" ixz="0.0" iyy="1.0" iyz="0.0" izz="1.0"/>
    </inertial>
    <visual>
      <origin rpy="0 0 0" xyz="0.0 0.0 0.005"/>
      <geometry>
        <mesh filename="package://smart_arm_description/meshes/arm_shoulder_pan.stl"/>
      </geometry>
    </visual>
    <!--
            <collision>
                <origin xyz="0.0 0.0 0.0" rpy="0 0 0" />
                <geometry>
                    <mesh filename="package://smart_arm_description/meshes/convex/arm_shoulder_pan_convex.stlb"/>
                </geometry>
            </collision>
-->
  </link>
  <link name="left_forearm_link">
    <inertial>
      <mass value="0.18"/>
      <origin rpy="0 0 0" xyz="0.13999458 0 0.00064711"/>
      <inertia ixx="1.0" ixy="0.0" ixz="0.0" iyy="1.0" iyz="0.0" izz="1.0"/>
    </inertial>
    <visual>
      <origin rpy="0 0 0" xyz="0.0 0.0 0.0"/>
      <geometry>
        <mesh filename="package://smart_arm_description/meshes/arm_shoulder_tilt.stl"/>
      </geometry>
    </visual>
    <!--
            <collision>
                <origin xyz="0.0 0.0 0.0" rpy="0 0 0" />
                <geometry>
                    <mesh filename="package://smart_arm_description/meshes/convex/arm_shoulder_tilt_convex.stlb"/>
                </geometry>
            </collision>
-->
  </link>
  <link name="left_wrist_flex_link">
    <inertial>
      <mass value="0.12"/>
      <origin rpy="0 0 0" xyz="0.04463361 0 0.00720194"/>
      <inertia ixx="1.0" ixy="0.0" ixz="0.0" iyy="1.0" iyz="0.0" izz="1.0"/>
    </inertial>
    <visual>
      <origin rpy="0 0 0" xyz="0.0 0.0 0.0"/>
      <geometry>
        <mesh filename="package://smart_arm_description/meshes/arm_elbow_tilt.stl"/>
      </geometry>
    </visual>
    <!--
            <collision>
                <origin xyz="0.0 0.0 0.0" rpy="0 0 0" />
                <geometry>
                    <mesh filename="package://smart_arm_description/meshes/convex/arm_elbow_tilt_convex.stlb"/>
                </geometry>
            </collision>
-->
  </link>
  <link name="left_wrist_roll_link">
    <inertial>
      <mass value="0.13"/>
      <origin rpy="0 0 0" xyz="0.02539960 0 0"/>
      <inertia ixx="1.0" ixy="0.0" ixz="0.0" iyy="1.0" iyz="0.0" izz="1.0"/>
    </inertial>
    <visual>
      <origin rpy="0 0 0" xyz="0.0 0.0 0.0"/>
      <geometry>
        <mesh filename="package://smart_arm_description/meshes/arm_wrist_rotate.stl"/>
      </geometry>
    </visual>
    <!--
            <collision>
                <origin xyz="0.0 0.0 0.0" rpy="0 0 0" />
                <geometry>
                    <mesh filename="package://smart_arm_description/meshes/convex/arm_wrist_rotate_convex.stlb"/>
                </geometry>
            </collision>
-->
  </link>
  <link name="left_gripper_right_link">
    <inertial>
      <mass value="0.0225"/>
      <origin rpy="0 0 0" xyz="0.03058625 -0.01804371 -0.00941599"/>
      <inertia ixx="1.0" ixy="0.0" ixz="0.0" iyy="1.0" iyz="0.0" izz="1.0"/>
    </inertial>
    <visual>
      <origin rpy="0 0 0" xyz="0.0 0.0 0.0"/>
      <geometry>
        <mesh filename="package://smart_arm_description/meshes/arm_right_finger.stl"/>
      </geometry>
    </visual>
    <!--
            <collision>
                <origin xyz="0.0 0.0 0.0" rpy="0 0 0" />
                <geometry>
                    <mesh filename="package://smart_arm_description/meshes/convex/arm_right_finger_convex.stlb"/>
                </geometry>
            </collision>
-->
  </link>
  <link name="left_gripper_left_link">
    <inertial>
      <mass value="0.0225"/>
      <origin rpy="0 0 0" xyz="0.03058625 0.01804371 -0.00941599"/>
      <inertia ixx="1.0" ixy="0.0" ixz="0.0" iyy="1.0" iyz="0.0" izz="1.0"/>
    </inertial>
    <visual>
      <origin rpy="0 0 0" xyz="0.0 0.0 0.0"/>
      <geometry>
        <mesh filename="package://smart_arm_description/meshes/arm_left_finger.stl"/>
      </geometry>
    </visual>
    <!--
            <collision>
                <origin xyz="0.0 0.0 0.0" rpy="0 0 0" />
                <geometry>
                    <mesh filename="package://smart_arm_description/meshes/convex/arm_left_finger_convex.stlb"/>
                </geometry>
            </collision>
-->
  </link>
  <transmission name="left_shoulder_pan_trans" type="pr2_mechanism_model/SimpleTransmission">
    <actuator name="left_shoulder_pan_motor"/>
    <joint name="left_shoulder_pan_joint"/>
    <mechanicalReduction>1.0</mechanicalReduction>
  </transmission>
  <transmission name="left_elbow_flex_trans" type="pr2_mechanism_model/SimpleTransmission">
    <actuator name="left_elbow_flex_motor"/>
    <joint name="left_elbow_flex_joint"/>
    <mechanicalReduction>1.0</mechanicalReduction>
  </transmission>
  <transmission name="left_wrist_flex_trans" type="pr2_mechanism_model/SimpleTransmission">
    <actuator name="left_wrist_flex_motor"/>
    <joint name="left_wrist_flex_joint"/>
    <mechanicalReduction>1.0</mechanicalReduction>
  </transmission>
  <transmission name="left_wrist_roll_trans" type="pr2_mechanism_model/SimpleTransmission">
    <actuator name="left_wrist_roll_motor"/>
    <joint name="left_wrist_roll_joint"/>
    <mechanicalReduction>1.0</mechanicalReduction>
  </transmission>
  <transmission name="left_gripper_right_trans" type="pr2_mechanism_model/SimpleTransmission">
    <actuator name="left_gripper_right_motor"/>
    <joint name="left_gripper_right_joint"/>
    <mechanicalReduction>1.0</mechanicalReduction>
  </transmission>
  <transmission name="left_gripper_left_trans" type="pr2_mechanism_model/SimpleTransmission">
    <actuator name="left_gripper_left_motor"/>
    <joint name="left_gripper_left_joint"/>
    <mechanicalReduction>1.0</mechanicalReduction>
  </transmission>
  <gazebo reference="left_arm_base_link">
    <material>SmartArm/GunMetalBrushedAluminum</material>
    <turnGravityOff>true</turnGravityOff>
  </gazebo>
  <gazebo reference="left_arm_shoulder_pan_link">
    <material>SmartArm/GunMetalBrushedAluminum</material>
    <turnGravityOff>true</turnGravityOff>
  </gazebo>
  <gazebo reference="left_elbow_flex_link">
    <material>SmartArm/GunMetalBrushedAluminum</material>
    <turnGravityOff>true</turnGravityOff>
  </gazebo>
  <gazebo reference="left_wrist_flex_link">
    <material>SmartArm/GunMetalBrushedAluminum</material>
    <turnGravityOff>true</turnGravityOff>
  </gazebo>
  <gazebo reference="left_wrist_roll_link">
    <material>SmartArm/GunMetalBrushedAluminum</material>
    <turnGravityOff>true</turnGravityOff>
  </gazebo>
  <gazebo reference="left_gripper_right_link">
    <material>SmartArm/GunMetalBrushedAluminum</material>
    <turnGravityOff>true</turnGravityOff>
    <mu1 value="500.0"/>
    <mu2 value="500.0"/>
    <kp value="1000000.0"/>
    <kd value="1.0"/>
  </gazebo>
  <gazebo reference="left_gripper_left_link">
    <material>SmartArm/GunMetalBrushedAluminum</material>
    <turnGravityOff>true</turnGravityOff>
    <mu1 value="500.0"/>
    <mu2 value="500.0"/>
    <kp value="1000000.0"/>
    <kd value="1.0"/>
  </gazebo>
  <gazebo reference="left_shoulder_pan_joint">
    <stopKd value="1.0"/>
    <stopKp value="1000000.0"/>
    <fudgeFactor value="0.5"/>
  </gazebo>
  <gazebo reference="left_elbow_flex_joint">
    <stopKd value="1.0"/>
    <stopKp value="1000000.0"/>
    <fudgeFactor value="0.5"/>
  </gazebo>
  <gazebo reference="left_wrist_flex_joint">
    <stopKd value="1.0"/>
    <stopKp value="1000000.0"/>
    <fudgeFactor value="0.5"/>
  </gazebo>
  <gazebo reference="left_wrist_roll_joint">
    <stopKd value="1.0"/>
    <stopKp value="1000000.0"/>
    <fudgeFactor value="0.5"/>
  </gazebo>
  <gazebo reference="left_gripper_right_joint">
    <stopKd value="1.0"/>
    <stopKp value="1000000.0"/>
    <fudgeFactor value="1.0"/>
  </gazebo>
  <gazebo reference="left_gripper_left_joint">
    <stopKd value="1.0"/>
    <stopKp value="1000000.0"/>
    <fudgeFactor value="1.0"/>
  </gazebo>
  <joint name="right_shoulder_pan_joint" type="revolute">
    <origin rpy="0 0 0" xyz="-0.0075 0 0.025"/>
    <!-- parent link="${side}_arm_base_link" /-->
    <parent link="right_shoulder_pan_link"/>
    <child link="right_elbow_flex_link"/>
    <axis xyz="0 0 1"/>
    <limit effort="300" lower="-1.22" upper="1.22" velocity="1.17"/>
    <safety_controller k_position="100" k_velocity="15.0" soft_lower_limit="-1.12" soft_upper_limit="1.12"/>
    <dynamics damping="50" friction="1"/>
  </joint>
  <joint name="right_elbow_flex_joint" type="revolute">
    <origin rpy="0 0 0" xyz="0.079575 0 0.0445"/>
    <parent link="right_elbow_flex_link"/>
    <child link="right_forearm_link"/>
    <axis xyz="0 -1 0"/>
    <limit effort="300" lower="-1.04719755" upper="1.972222" velocity="1.17"/>
    <safety_controller k_position="100" k_velocity="15.0" soft_lower_limit="-0.94719755" soft_upper_limit="1.872222"/>
    <dynamics damping="50" friction="1"/>
  </joint>
  <joint name="right_wrist_flex_joint" type="revolute">
    <origin rpy="0 0 0" xyz="0.1815 0 0"/>
    <parent link="right_forearm_link"/>
    <child link="right_wrist_flex_link"/>
    <axis xyz="0 -1 0"/>
    <!-- From -113 to 108 degrees -->
    <limit effort="300" lower="-1.972222" upper="1.8849556" velocity="1.17"/>
    <dynamics damping="50" friction="1"/>
    <safety_controller k_position="100" k_velocity="15.0" soft_lower_limit="-1.872222" soft_upper_limit="1.7849556"/>
  </joint>
  <joint name="right_wrist_roll_joint" type="revolute">
    <origin rpy="0 0 0" xyz="0.07 0 0.023"/>
    <parent link="right_wrist_flex_link"/>
    <child link="right_wrist_roll_link"/>
    <axis xyz="-1 0 0"/>
    <!-- From -150 to 150 degrees -->
    <limit effort="300" lower="-2.6179939" upper="2.6179939" velocity="1.17"/>
    <dynamics damping="50" friction="1"/>
    <safety_controller k_position="100" k_velocity="15.0" soft_lower_limit="-2.5179939" soft_upper_limit="2.5179939"/>
  </joint>
  <joint name="right_gripper_right_joint" type="revolute">
    <origin rpy="0 0 0" xyz="0.0415 -0.0175 0"/>
    <parent link="right_wrist_roll_link"/>
    <child link="right_gripper_right_link"/>
    <axis xyz="0 0 1"/>
    <!-- From 14 to -45 degrees -->
    <limit effort="300" lower="-0.838576116" upper="0.245436912" velocity="1.17"/>
    <dynamics damping="50" friction="1"/>
    <safety_controller k_position="100" k_velocity="15.0" soft_lower_limit="-0.738576116" soft_upper_limit="0.145436912"/>
  </joint>
  <joint name="right_gripper_left_joint" type="revolute">
    <origin rpy="0 0 0" xyz="0.0415 0.0175 0"/>
    <parent link="right_wrist_roll_link"/>
    <child link="right_gripper_left_link"/>
    <axis xyz="0 0 1"/>
    <!-- From -14 to 45 degrees -->
    <limit effort="300" lower="-0.240323643" upper="0.843689385" velocity="1.17"/>
    <dynamics damping="50" friction="1"/>
    <safety_controller k_position="100" k_velocity="15.0" soft_lower_limit="-0.140323643" soft_upper_limit="0.743689385"/>
  </joint>
  <link name="right_shoulder_pan_link">
    <inertial>
      <mass value="0.125"/>
      <origin rpy="0 0 0" xyz="0 0 0.00893364"/>
      <inertia ixx="1.0" ixy="0.0" ixz="0.0" iyy="1.0" iyz="0.0" izz="1.0"/>
    </inertial>
    <visual>
      <origin rpy="0 0 0" xyz="0.0 0.0 0.0"/>
      <geometry>
        <mesh filename="package://smart_arm_description/meshes/arm_base.stl"/>
      </geometry>
    </visual>
    <!--
            <collision>
                <origin xyz="0.0 0.0 0.0" rpy="0 0 0" />
                <geometry>
                    <mesh filename="package://smart_arm_description/meshes/convex/arm_base_convex.stlb"/>
                </geometry>
            </collision>
-->
  </link>
  <link name="right_elbow_flex_link">
    <inertial>
      <mass value="0.405"/>
      <origin rpy="0 0 0" xyz="0.02988871 0 0.02056699"/>
      <inertia ixx="1.0" ixy="0.0" ixz="0.0" iyy="1.0" iyz="0.0" izz="1.0"/>
    </inertial>
    <visual>
      <origin rpy="0 0 0" xyz="0.0 0.0 0.005"/>
      <geometry>
        <mesh filename="package://smart_arm_description/meshes/arm_shoulder_pan.stl"/>
      </geometry>
    </visual>
    <!--
            <collision>
                <origin xyz="0.0 0.0 0.0" rpy="0 0 0" />
                <geometry>
                    <mesh filename="package://smart_arm_description/meshes/convex/arm_shoulder_pan_convex.stlb"/>
                </geometry>
            </collision>
-->
  </link>
  <link name="right_forearm_link">
    <inertial>
      <mass value="0.18"/>
      <origin rpy="0 0 0" xyz="0.13999458 0 0.00064711"/>
      <inertia ixx="1.0" ixy="0.0" ixz="0.0" iyy="1.0" iyz="0.0" izz="1.0"/>
    </inertial>
    <visual>
      <origin rpy="0 0 0" xyz="0.0 0.0 0.0"/>
      <geometry>
        <mesh filename="package://smart_arm_description/meshes/arm_shoulder_tilt.stl"/>
      </geometry>
    </visual>
    <!--
            <collision>
                <origin xyz="0.0 0.0 0.0" rpy="0 0 0" />
                <geometry>
                    <mesh filename="package://smart_arm_description/meshes/convex/arm_shoulder_tilt_convex.stlb"/>
                </geometry>
            </collision>
-->
  </link>
  <link name="right_wrist_flex_link">
    <inertial>
      <mass value="0.12"/>
      <origin rpy="0 0 0" xyz="0.04463361 0 0.00720194"/>
      <inertia ixx="1.0" ixy="0.0" ixz="0.0" iyy="1.0" iyz="0.0" izz="1.0"/>
    </inertial>
    <visual>
      <origin rpy="0 0 0" xyz="0.0 0.0 0.0"/>
      <geometry>
        <mesh filename="package://smart_arm_description/meshes/arm_elbow_tilt.stl"/>
      </geometry>
    </visual>
    <!--
            <collision>
                <origin xyz="0.0 0.0 0.0" rpy="0 0 0" />
                <geometry>
                    <mesh filename="package://smart_arm_description/meshes/convex/arm_elbow_tilt_convex.stlb"/>
                </geometry>
            </collision>
-->
  </link>
  <link name="right_wrist_roll_link">
    <inertial>
      <mass value="0.13"/>
      <origin rpy="0 0 0" xyz="0.02539960 0 0"/>
      <inertia ixx="1.0" ixy="0.0" ixz="0.0" iyy="1.0" iyz="0.0" izz="1.0"/>
    </inertial>
    <visual>
      <origin rpy="0 0 0" xyz="0.0 0.0 0.0"/>
      <geometry>
        <mesh filename="package://smart_arm_description/meshes/arm_wrist_rotate.stl"/>
      </geometry>
    </visual>
    <!--
            <collision>
                <origin xyz="0.0 0.0 0.0" rpy="0 0 0" />
                <geometry>
                    <mesh filename="package://smart_arm_description/meshes/convex/arm_wrist_rotate_convex.stlb"/>
                </geometry>
            </collision>
-->
  </link>
  <link name="right_gripper_right_link">
    <inertial>
      <mass value="0.0225"/>
      <origin rpy="0 0 0" xyz="0.03058625 -0.01804371 -0.00941599"/>
      <inertia ixx="1.0" ixy="0.0" ixz="0.0" iyy="1.0" iyz="0.0" izz="1.0"/>
    </inertial>
    <visual>
      <origin rpy="0 0 0" xyz="0.0 0.0 0.0"/>
      <geometry>
        <mesh filename="package://smart_arm_description/meshes/arm_right_finger.stl"/>
      </geometry>
    </visual>
    <!--
            <collision>
                <origin xyz="0.0 0.0 0.0" rpy="0 0 0" />
                <geometry>
                    <mesh filename="package://smart_arm_description/meshes/convex/arm_right_finger_convex.stlb"/>
                </geometry>
            </collision>
-->
  </link>
  <link name="right_gripper_left_link">
    <inertial>
      <mass value="0.0225"/>
      <origin rpy="0 0 0" xyz="0.03058625 0.01804371 -0.00941599"/>
      <inertia ixx="1.0" ixy="0.0" ixz="0.0" iyy="1.0" iyz="0.0" izz="1.0"/>
    </inertial>
    <visual>
      <origin rpy="0 0 0" xyz="0.0 0.0 0.0"/>
      <geometry>
        <mesh filename="package://smart_arm_description/meshes/arm_left_finger.stl"/>
      </geometry>
    </visual>
    <!--
            <collision>
                <origin xyz="0.0 0.0 0.0" rpy="0 0 0" />
                <geometry>
                    <mesh filename="package://smart_arm_description/meshes/convex/arm_left_finger_convex.stlb"/>
                </geometry>
            </collision>
-->
  </link>
  <transmission name="right_shoulder_pan_trans" type="pr2_mechanism_model/SimpleTransmission">
    <actuator name="right_shoulder_pan_motor"/>
    <joint name="right_shoulder_pan_joint"/>
    <mechanicalReduction>1.0</mechanicalReduction>
  </transmission>
  <transmission name="right_elbow_flex_trans" type="pr2_mechanism_model/SimpleTransmission">
    <actuator name="right_elbow_flex_motor"/>
    <joint name="right_elbow_flex_joint"/>
    <mechanicalReduction>1.0</mechanicalReduction>
  </transmission>
  <transmission name="right_wrist_flex_trans" type="pr2_mechanism_model/SimpleTransmission">
    <actuator name="right_wrist_flex_motor"/>
    <joint name="right_wrist_flex_joint"/>
    <mechanicalReduction>1.0</mechanicalReduction>
  </transmission>
  <transmission name="right_wrist_roll_trans" type="pr2_mechanism_model/SimpleTransmission">
    <actuator name="right_wrist_roll_motor"/>
    <joint name="right_wrist_roll_joint"/>
    <mechanicalReduction>1.0</mechanicalReduction>
  </transmission>
  <transmission name="right_gripper_right_trans" type="pr2_mechanism_model/SimpleTransmission">
    <actuator name="right_gripper_right_motor"/>
    <joint name="right_gripper_right_joint"/>
    <mechanicalReduction>1.0</mechanicalReduction>
  </transmission>
  <transmission name="right_gripper_left_trans" type="pr2_mechanism_model/SimpleTransmission">
    <actuator name="right_gripper_left_motor"/>
    <joint name="right_gripper_left_joint"/>
    <mechanicalReduction>1.0</mechanicalReduction>
  </transmission>
  <gazebo reference="right_arm_base_link">
    <material>SmartArm/GunMetalBrushedAluminum</material>
    <turnGravityOff>true</turnGravityOff>
  </gazebo>
  <gazebo reference="right_arm_shoulder_pan_link">
    <material>SmartArm/GunMetalBrushedAluminum</material>
    <turnGravityOff>true</turnGravityOff>
  </gazebo>
  <gazebo reference="right_elbow_flex_link">
    <material>SmartArm/GunMetalBrushedAluminum</material>
    <turnGravityOff>true</turnGravityOff>
  </gazebo>
  <gazebo reference="right_wrist_flex_link">
    <material>SmartArm/GunMetalBrushedAluminum</material>
    <turnGravityOff>true</turnGravityOff>
  </gazebo>
  <gazebo reference="right_wrist_roll_link">
    <material>SmartArm/GunMetalBrushedAluminum</material>
    <turnGravityOff>true</turnGravityOff>
  </gazebo>
  <gazebo reference="right_gripper_right_link">
    <material>SmartArm/GunMetalBrushedAluminum</material>
    <turnGravityOff>true</turnGravityOff>
    <mu1 value="500.0"/>
    <mu2 value="500.0"/>
    <kp value="1000000.0"/>
    <kd value="1.0"/>
  </gazebo>
  <gazebo reference="right_gripper_left_link">
    <material>SmartArm/GunMetalBrushedAluminum</material>
    <turnGravityOff>true</turnGravityOff>
    <mu1 value="500.0"/>
    <mu2 value="500.0"/>
    <kp value="1000000.0"/>
    <kd value="1.0"/>
  </gazebo>
  <gazebo reference="right_shoulder_pan_joint">
    <stopKd value="1.0"/>
    <stopKp value="1000000.0"/>
    <fudgeFactor value="0.5"/>
  </gazebo>
  <gazebo reference="right_elbow_flex_joint">
    <stopKd value="1.0"/>
    <stopKp value="1000000.0"/>
    <fudgeFactor value="0.5"/>
  </gazebo>
  <gazebo reference="right_wrist_flex_joint">
    <stopKd value="1.0"/>
    <stopKp value="1000000.0"/>
    <fudgeFactor value="0.5"/>
  </gazebo>
  <gazebo reference="right_wrist_roll_joint">
    <stopKd value="1.0"/>
    <stopKp value="1000000.0"/>
    <fudgeFactor value="0.5"/>
  </gazebo>
  <gazebo reference="right_gripper_right_joint">
    <stopKd value="1.0"/>
    <stopKp value="1000000.0"/>
    <fudgeFactor value="1.0"/>
  </gazebo>
  <gazebo reference="right_gripper_left_joint">
    <stopKd value="1.0"/>
    <stopKp value="1000000.0"/>
    <fudgeFactor value="1.0"/>
  </gazebo>
  <joint name="hokuyo_mount_joint" type="fixed">
    <!-- insert_block name="origin" /-->
    <parent link="hokuyo_torso_link"/>
    <child link="hokuyo_mount_link"/>
  </joint>
  <link name="hokuyo_mount_link">
    <inertial>
      <mass value="0.160"/>
      <origin rpy="0 0 0" xyz="0.0 0.0 0.0"/>
      <inertia ixx="1.0" ixy="0.0" ixz="0.0" iyy="1.0" iyz="0.0" izz="1.0"/>
    </inertial>
    <visual>
      <origin rpy="1.570795 0 1.570795" xyz="0.0 0.0 0.0"/>
      <geometry>
        <mesh filename="package://hokuyo_urg_description/meshes/hokuyo_urg.stl"/>
      </geometry>
    </visual>
    <collision>
      <origin rpy="1.570795 0 1.570795" xyz="0.0 0.0 0.0"/>
      <geometry>
        <mesh filename="package://hokuyo_urg_description/meshes/convex/hokuyo_urg_convex.stlb"/>
      </geometry>
    </collision>
  </link>
  <joint name="hokuyo_joint" type="fixed">
    <origin rpy="0 0 0" xyz="0 0 0.06"/>
    <parent link="hokuyo_mount_link"/>
    <child link="hokuyo_link"/>
  </joint>
  <link name="hokuyo_link" type="laser">
    <inertial>
      <mass value="0.001"/>
      <origin rpy="0 0 0" xyz="0 0 0"/>
      <inertia ixx="0.0001" ixy="0" ixz="0" iyy="0.000001" iyz="0" izz="0.0001"/>
    </inertial>
    <visual name="laser_visual">
      <origin rpy="0 0 0" xyz="0 0 0"/>
      <geometry name="laser_visual_geom">
        <box size="0.001 0.001 0.001"/>
      </geometry>
      <material name="Red"/>
    </visual>
    <collision name="laser_collision">
      <origin rpy="0 0 0" xyz="0 0 0"/>
      <geometry name="laser_collision_geom">
        <box size=".001 .001 .001"/>
      </geometry>
    </collision>
  </link>
  <gazebo reference="hokuyo_mount_link">
    <material value="Erratic/Black"/>
  </gazebo>
  <gazebo reference="hokuyo_link">
    <material value="Erratic/Black"/>
  </gazebo>
  <gazebo reference="hokuyo_link">
    <sensor:ray name="laser">
      <rayCount>683</rayCount>
      <rangeCount>683</rangeCount>
      <laserCount>1</laserCount>
      <origin>0.0 0.0 0.0</origin>
      <displayRays>false</displayRays>
      <minAngle>-90</minAngle>
      <maxAngle> 90</maxAngle>
      <minRange>0.06</minRange>
      <maxRange>4.0</maxRange>
      <resRange>0.001</resRange>
      <updateRate>10.0</updateRate>
      <controller:gazebo_ros_laser name="gazebo_ros_hokuyo_laser_controller" plugin="libgazebo_ros_laser.so">
        <gaussianNoise>0.005</gaussianNoise>
        <alwaysOn>true</alwaysOn>
        <updateRate>10.0</updateRate>
        <topicName>hokuyo/scan</topicName>
        <frameName>hokuyo_link</frameName>
        <interface:laser name="gazebo_ros_hokuyo_laser_iface"/>
      </controller:gazebo_ros_laser>
    </sensor:ray>
  </gazebo>
</robot>

